Here is the list of inputs:
OPTIONS jobs 2
OPTIONS queues 2
OPTIONS allotments for queue  1 is   2
OPTIONS quantum length for queue  1 is  10
OPTIONS allotments for queue  0 is   2
OPTIONS quantum length for queue  0 is  10
OPTIONS boost 0
OPTIONS ioTime 5
OPTIONS stayAfterIO True
OPTIONS iobump False


For each job, three defining characteristics are given:
  startTime : at what time does the job enter the system
  runTime   : the total CPU time needed by the job to finish
  ioFreq    : every ioFreq time units, the job issues an I/O
              (the I/O takes ioTime units to complete)

Job List:
  Job  0: startTime   0 - runTime 500 - ioFreq   1
  Job  1: startTime   0 - runTime 500 - ioFreq 100


Execution Trace:

[ time 0 ] JOB BEGINS by JOB 0
[ time 0 ] JOB BEGINS by JOB 1
[ time 0 ] Run JOB 0 at PRIORITY 1 [ TICKS 9 ALLOT 2 TIME 499 (of 500) ]
[ time 1 ] IO_START by JOB 0
IO DONE
[ time 1 ] Run JOB 1 at PRIORITY 1 [ TICKS 9 ALLOT 2 TIME 499 (of 500) ]
[ time 2 ] Run JOB 1 at PRIORITY 1 [ TICKS 8 ALLOT 2 TIME 498 (of 500) ]
[ time 3 ] Run JOB 1 at PRIORITY 1 [ TICKS 7 ALLOT 2 TIME 497 (of 500) ]
[ time 4 ] Run JOB 1 at PRIORITY 1 [ TICKS 6 ALLOT 2 TIME 496 (of 500) ]
[ time 5 ] Run JOB 1 at PRIORITY 1 [ TICKS 5 ALLOT 2 TIME 495 (of 500) ]
[ time 6 ] IO_DONE by JOB 0
[ time 6 ] Run JOB 1 at PRIORITY 1 [ TICKS 4 ALLOT 2 TIME 494 (of 500) ]
[ time 7 ] Run JOB 1 at PRIORITY 1 [ TICKS 3 ALLOT 2 TIME 493 (of 500) ]
[ time 8 ] Run JOB 1 at PRIORITY 1 [ TICKS 2 ALLOT 2 TIME 492 (of 500) ]
[ time 9 ] Run JOB 1 at PRIORITY 1 [ TICKS 1 ALLOT 2 TIME 491 (of 500) ]
[ time 10 ] Run JOB 1 at PRIORITY 1 [ TICKS 0 ALLOT 2 TIME 490 (of 500) ]
[ time 11 ] Run JOB 0 at PRIORITY 1 [ TICKS 9 ALLOT 2 TIME 498 (of 500) ]
[ time 12 ] IO_START by JOB 0
IO DONE
[ time 12 ] Run JOB 1 at PRIORITY 1 [ TICKS 9 ALLOT 1 TIME 489 (of 500) ]
[ time 13 ] Run JOB 1 at PRIORITY 1 [ TICKS 8 ALLOT 1 TIME 488 (of 500) ]
[ time 14 ] Run JOB 1 at PRIORITY 1 [ TICKS 7 ALLOT 1 TIME 487 (of 500) ]
[ time 15 ] Run JOB 1 at PRIORITY 1 [ TICKS 6 ALLOT 1 TIME 486 (of 500) ]
[ time 16 ] Run JOB 1 at PRIORITY 1 [ TICKS 5 ALLOT 1 TIME 485 (of 500) ]
[ time 17 ] IO_DONE by JOB 0
[ time 17 ] Run JOB 1 at PRIORITY 1 [ TICKS 4 ALLOT 1 TIME 484 (of 500) ]
[ time 18 ] Run JOB 1 at PRIORITY 1 [ TICKS 3 ALLOT 1 TIME 483 (of 500) ]
[ time 19 ] Run JOB 1 at PRIORITY 1 [ TICKS 2 ALLOT 1 TIME 482 (of 500) ]
[ time 20 ] Run JOB 1 at PRIORITY 1 [ TICKS 1 ALLOT 1 TIME 481 (of 500) ]
[ time 21 ] Run JOB 1 at PRIORITY 1 [ TICKS 0 ALLOT 1 TIME 480 (of 500) ]
[ time 22 ] Run JOB 0 at PRIORITY 1 [ TICKS 9 ALLOT 2 TIME 497 (of 500) ]
[ time 23 ] IO_START by JOB 0
IO DONE
[ time 23 ] Run JOB 1 at PRIORITY 0 [ TICKS 9 ALLOT 2 TIME 479 (of 500) ]
[ time 24 ] Run JOB 1 at PRIORITY 0 [ TICKS 8 ALLOT 2 TIME 478 (of 500) ]
[ time 25 ] Run JOB 1 at PRIORITY 0 [ TICKS 7 ALLOT 2 TIME 477 (of 500) ]
[ time 26 ] Run JOB 1 at PRIORITY 0 [ TICKS 6 ALLOT 2 TIME 476 (of 500) ]
[ time 27 ] Run JOB 1 at PRIORITY 0 [ TICKS 5 ALLOT 2 TIME 475 (of 500) ]
[ time 28 ] IO_DONE by JOB 0
[ time 28 ] Run JOB 0 at PRIORITY 1 [ TICKS 9 ALLOT 2 TIME 496 (of 500) ]
[ time 29 ] IO_START by JOB 0
IO DONE
[ time 29 ] Run JOB 1 at PRIORITY 0 [ TICKS 4 ALLOT 2 TIME 474 (of 500) ]
[ time 30 ] Run JOB 1 at PRIORITY 0 [ TICKS 3 ALLOT 2 TIME 473 (of 500) ]
[ time 31 ] Run JOB 1 at PRIORITY 0 [ TICKS 2 ALLOT 2 TIME 472 (of 500) ]
[ time 32 ] Run JOB 1 at PRIORITY 0 [ TICKS 1 ALLOT 2 TIME 471 (of 500) ]
[ time 33 ] Run JOB 1 at PRIORITY 0 [ TICKS 0 ALLOT 2 TIME 470 (of 500) ]
[ time 34 ] IO_DONE by JOB 0
[ time 34 ] Run JOB 0 at PRIORITY 1 [ TICKS 9 ALLOT 2 TIME 495 (of 500) ]
[ time 35 ] IO_START by JOB 0
IO DONE
[ time 35 ] Run JOB 1 at PRIORITY 0 [ TICKS 9 ALLOT 1 TIME 469 (of 500) ]
[ time 36 ] Run JOB 1 at PRIORITY 0 [ TICKS 8 ALLOT 1 TIME 468 (of 500) ]
[ time 37 ] Run JOB 1 at PRIORITY 0 [ TICKS 7 ALLOT 1 TIME 467 (of 500) ]
[ time 38 ] Run JOB 1 at PRIORITY 0 [ TICKS 6 ALLOT 1 TIME 466 (of 500) ]
[ time 39 ] Run JOB 1 at PRIORITY 0 [ TICKS 5 ALLOT 1 TIME 465 (of 500) ]
[ time 40 ] IO_DONE by JOB 0
[ time 40 ] Run JOB 0 at PRIORITY 1 [ TICKS 9 ALLOT 2 TIME 494 (of 500) ]
[ time 41 ] IO_START by JOB 0
IO DONE
[ time 41 ] Run JOB 1 at PRIORITY 0 [ TICKS 4 ALLOT 1 TIME 464 (of 500) ]
[ time 42 ] Run JOB 1 at PRIORITY 0 [ TICKS 3 ALLOT 1 TIME 463 (of 500) ]
[ time 43 ] Run JOB 1 at PRIORITY 0 [ TICKS 2 ALLOT 1 TIME 462 (of 500) ]
[ time 44 ] Run JOB 1 at PRIORITY 0 [ TICKS 1 ALLOT 1 TIME 461 (of 500) ]
[ time 45 ] Run JOB 1 at PRIORITY 0 [ TICKS 0 ALLOT 1 TIME 460 (of 500) ]
[ time 46 ] IO_DONE by JOB 0
[ time 46 ] Run JOB 0 at PRIORITY 1 [ TICKS 9 ALLOT 2 TIME 493 (of 500) ]
[ time 47 ] IO_START by JOB 0
IO DONE
[ time 47 ] Run JOB 1 at PRIORITY 0 [ TICKS 9 ALLOT 2 TIME 459 (of 500) ]
[ time 48 ] Run JOB 1 at PRIORITY 0 [ TICKS 8 ALLOT 2 TIME 458 (of 500) ]
[ time 49 ] Run JOB 1 at PRIORITY 0 [ TICKS 7 ALLOT 2 TIME 457 (of 500) ]
[ time 50 ] Run JOB 1 at PRIORITY 0 [ TICKS 6 ALLOT 2 TIME 456 (of 500) ]
[ time 51 ] Run JOB 1 at PRIORITY 0 [ TICKS 5 ALLOT 2 TIME 455 (of 500) ]
[ time 52 ] IO_DONE by JOB 0
[ time 52 ] Run JOB 0 at PRIORITY 1 [ TICKS 9 ALLOT 2 TIME 492 (of 500) ]
[ time 53 ] IO_START by JOB 0
IO DONE
[ time 53 ] Run JOB 1 at PRIORITY 0 [ TICKS 4 ALLOT 2 TIME 454 (of 500) ]
[ time 54 ] Run JOB 1 at PRIORITY 0 [ TICKS 3 ALLOT 2 TIME 453 (of 500) ]
[ time 55 ] Run JOB 1 at PRIORITY 0 [ TICKS 2 ALLOT 2 TIME 452 (of 500) ]
[ time 56 ] Run JOB 1 at PRIORITY 0 [ TICKS 1 ALLOT 2 TIME 451 (of 500) ]
[ time 57 ] Run JOB 1 at PRIORITY 0 [ TICKS 0 ALLOT 2 TIME 450 (of 500) ]
[ time 58 ] IO_DONE by JOB 0
[ time 58 ] Run JOB 0 at PRIORITY 1 [ TICKS 9 ALLOT 2 TIME 491 (of 500) ]
[ time 59 ] IO_START by JOB 0
IO DONE
[ time 59 ] Run JOB 1 at PRIORITY 0 [ TICKS 9 ALLOT 1 TIME 449 (of 500) ]
[ time 60 ] Run JOB 1 at PRIORITY 0 [ TICKS 8 ALLOT 1 TIME 448 (of 500) ]
[ time 61 ] Run JOB 1 at PRIORITY 0 [ TICKS 7 ALLOT 1 TIME 447 (of 500) ]
[ time 62 ] Run JOB 1 at PRIORITY 0 [ TICKS 6 ALLOT 1 TIME 446 (of 500) ]
[ time 63 ] Run JOB 1 at PRIORITY 0 [ TICKS 5 ALLOT 1 TIME 445 (of 500) ]
[ time 64 ] IO_DONE by JOB 0
[ time 64 ] Run JOB 0 at PRIORITY 1 [ TICKS 9 ALLOT 2 TIME 490 (of 500) ]
[ time 65 ] IO_START by JOB 0
IO DONE
[ time 65 ] Run JOB 1 at PRIORITY 0 [ TICKS 4 ALLOT 1 TIME 444 (of 500) ]
[ time 66 ] Run JOB 1 at PRIORITY 0 [ TICKS 3 ALLOT 1 TIME 443 (of 500) ]
[ time 67 ] Run JOB 1 at PRIORITY 0 [ TICKS 2 ALLOT 1 TIME 442 (of 500) ]
[ time 68 ] Run JOB 1 at PRIORITY 0 [ TICKS 1 ALLOT 1 TIME 441 (of 500) ]
[ time 69 ] Run JOB 1 at PRIORITY 0 [ TICKS 0 ALLOT 1 TIME 440 (of 500) ]
[ time 70 ] IO_DONE by JOB 0
[ time 70 ] Run JOB 0 at PRIORITY 1 [ TICKS 9 ALLOT 2 TIME 489 (of 500) ]
[ time 71 ] IO_START by JOB 0
IO DONE
[ time 71 ] Run JOB 1 at PRIORITY 0 [ TICKS 9 ALLOT 2 TIME 439 (of 500) ]
[ time 72 ] Run JOB 1 at PRIORITY 0 [ TICKS 8 ALLOT 2 TIME 438 (of 500) ]
[ time 73 ] Run JOB 1 at PRIORITY 0 [ TICKS 7 ALLOT 2 TIME 437 (of 500) ]
[ time 74 ] Run JOB 1 at PRIORITY 0 [ TICKS 6 ALLOT 2 TIME 436 (of 500) ]
[ time 75 ] Run JOB 1 at PRIORITY 0 [ TICKS 5 ALLOT 2 TIME 435 (of 500) ]
[ time 76 ] IO_DONE by JOB 0
[ time 76 ] Run JOB 0 at PRIORITY 1 [ TICKS 9 ALLOT 2 TIME 488 (of 500) ]
[ time 77 ] IO_START by JOB 0
IO DONE
[ time 77 ] Run JOB 1 at PRIORITY 0 [ TICKS 4 ALLOT 2 TIME 434 (of 500) ]
[ time 78 ] Run JOB 1 at PRIORITY 0 [ TICKS 3 ALLOT 2 TIME 433 (of 500) ]
[ time 79 ] Run JOB 1 at PRIORITY 0 [ TICKS 2 ALLOT 2 TIME 432 (of 500) ]
[ time 80 ] Run JOB 1 at PRIORITY 0 [ TICKS 1 ALLOT 2 TIME 431 (of 500) ]
[ time 81 ] Run JOB 1 at PRIORITY 0 [ TICKS 0 ALLOT 2 TIME 430 (of 500) ]
[ time 82 ] IO_DONE by JOB 0
[ time 82 ] Run JOB 0 at PRIORITY 1 [ TICKS 9 ALLOT 2 TIME 487 (of 500) ]
[ time 83 ] IO_START by JOB 0
IO DONE
[ time 83 ] Run JOB 1 at PRIORITY 0 [ TICKS 9 ALLOT 1 TIME 429 (of 500) ]
[ time 84 ] Run JOB 1 at PRIORITY 0 [ TICKS 8 ALLOT 1 TIME 428 (of 500) ]
[ time 85 ] Run JOB 1 at PRIORITY 0 [ TICKS 7 ALLOT 1 TIME 427 (of 500) ]
[ time 86 ] Run JOB 1 at PRIORITY 0 [ TICKS 6 ALLOT 1 TIME 426 (of 500) ]
[ time 87 ] Run JOB 1 at PRIORITY 0 [ TICKS 5 ALLOT 1 TIME 425 (of 500) ]
[ time 88 ] IO_DONE by JOB 0
[ time 88 ] Run JOB 0 at PRIORITY 1 [ TICKS 9 ALLOT 2 TIME 486 (of 500) ]
[ time 89 ] IO_START by JOB 0
IO DONE
[ time 89 ] Run JOB 1 at PRIORITY 0 [ TICKS 4 ALLOT 1 TIME 424 (of 500) ]
[ time 90 ] Run JOB 1 at PRIORITY 0 [ TICKS 3 ALLOT 1 TIME 423 (of 500) ]
[ time 91 ] Run JOB 1 at PRIORITY 0 [ TICKS 2 ALLOT 1 TIME 422 (of 500) ]
[ time 92 ] Run JOB 1 at PRIORITY 0 [ TICKS 1 ALLOT 1 TIME 421 (of 500) ]
[ time 93 ] Run JOB 1 at PRIORITY 0 [ TICKS 0 ALLOT 1 TIME 420 (of 500) ]
[ time 94 ] IO_DONE by JOB 0
[ time 94 ] Run JOB 0 at PRIORITY 1 [ TICKS 9 ALLOT 2 TIME 485 (of 500) ]
[ time 95 ] IO_START by JOB 0
IO DONE
[ time 95 ] Run JOB 1 at PRIORITY 0 [ TICKS 9 ALLOT 2 TIME 419 (of 500) ]
[ time 96 ] Run JOB 1 at PRIORITY 0 [ TICKS 8 ALLOT 2 TIME 418 (of 500) ]
[ time 97 ] Run JOB 1 at PRIORITY 0 [ TICKS 7 ALLOT 2 TIME 417 (of 500) ]
[ time 98 ] Run JOB 1 at PRIORITY 0 [ TICKS 6 ALLOT 2 TIME 416 (of 500) ]
[ time 99 ] Run JOB 1 at PRIORITY 0 [ TICKS 5 ALLOT 2 TIME 415 (of 500) ]
[ time 100 ] IO_DONE by JOB 0
[ time 100 ] Run JOB 0 at PRIORITY 1 [ TICKS 9 ALLOT 2 TIME 484 (of 500) ]
[ time 101 ] IO_START by JOB 0
IO DONE
[ time 101 ] Run JOB 1 at PRIORITY 0 [ TICKS 4 ALLOT 2 TIME 414 (of 500) ]
[ time 102 ] Run JOB 1 at PRIORITY 0 [ TICKS 3 ALLOT 2 TIME 413 (of 500) ]
[ time 103 ] Run JOB 1 at PRIORITY 0 [ TICKS 2 ALLOT 2 TIME 412 (of 500) ]
[ time 104 ] Run JOB 1 at PRIORITY 0 [ TICKS 1 ALLOT 2 TIME 411 (of 500) ]
[ time 105 ] Run JOB 1 at PRIORITY 0 [ TICKS 0 ALLOT 2 TIME 410 (of 500) ]
[ time 106 ] IO_DONE by JOB 0
[ time 106 ] Run JOB 0 at PRIORITY 1 [ TICKS 9 ALLOT 2 TIME 483 (of 500) ]
[ time 107 ] IO_START by JOB 0
IO DONE
[ time 107 ] Run JOB 1 at PRIORITY 0 [ TICKS 9 ALLOT 1 TIME 409 (of 500) ]
[ time 108 ] Run JOB 1 at PRIORITY 0 [ TICKS 8 ALLOT 1 TIME 408 (of 500) ]
[ time 109 ] Run JOB 1 at PRIORITY 0 [ TICKS 7 ALLOT 1 TIME 407 (of 500) ]
[ time 110 ] Run JOB 1 at PRIORITY 0 [ TICKS 6 ALLOT 1 TIME 406 (of 500) ]
[ time 111 ] Run JOB 1 at PRIORITY 0 [ TICKS 5 ALLOT 1 TIME 405 (of 500) ]
[ time 112 ] IO_DONE by JOB 0
[ time 112 ] Run JOB 0 at PRIORITY 1 [ TICKS 9 ALLOT 2 TIME 482 (of 500) ]
[ time 113 ] IO_START by JOB 0
IO DONE
[ time 113 ] Run JOB 1 at PRIORITY 0 [ TICKS 4 ALLOT 1 TIME 404 (of 500) ]
[ time 114 ] Run JOB 1 at PRIORITY 0 [ TICKS 3 ALLOT 1 TIME 403 (of 500) ]
[ time 115 ] Run JOB 1 at PRIORITY 0 [ TICKS 2 ALLOT 1 TIME 402 (of 500) ]
[ time 116 ] Run JOB 1 at PRIORITY 0 [ TICKS 1 ALLOT 1 TIME 401 (of 500) ]
[ time 117 ] Run JOB 1 at PRIORITY 0 [ TICKS 0 ALLOT 1 TIME 400 (of 500) ]
[ time 118 ] IO_START by JOB 1
IO DONE
[ time 118 ] IO_DONE by JOB 0
[ time 118 ] Run JOB 0 at PRIORITY 1 [ TICKS 9 ALLOT 2 TIME 481 (of 500) ]
[ time 119 ] IO_START by JOB 0
IO DONE
[ time 119 ] IDLE
[ time 120 ] IDLE
[ time 121 ] IDLE
[ time 122 ] IDLE
[ time 123 ] IO_DONE by JOB 1
[ time 123 ] Run JOB 1 at PRIORITY 0 [ TICKS 9 ALLOT 1 TIME 399 (of 500) ]
[ time 124 ] IO_DONE by JOB 0
[ time 124 ] Run JOB 0 at PRIORITY 1 [ TICKS 9 ALLOT 2 TIME 480 (of 500) ]
[ time 125 ] IO_START by JOB 0
IO DONE
[ time 125 ] Run JOB 1 at PRIORITY 0 [ TICKS 8 ALLOT 1 TIME 398 (of 500) ]
[ time 126 ] Run JOB 1 at PRIORITY 0 [ TICKS 7 ALLOT 1 TIME 397 (of 500) ]
[ time 127 ] Run JOB 1 at PRIORITY 0 [ TICKS 6 ALLOT 1 TIME 396 (of 500) ]
[ time 128 ] Run JOB 1 at PRIORITY 0 [ TICKS 5 ALLOT 1 TIME 395 (of 500) ]
[ time 129 ] Run JOB 1 at PRIORITY 0 [ TICKS 4 ALLOT 1 TIME 394 (of 500) ]
[ time 130 ] IO_DONE by JOB 0
[ time 130 ] Run JOB 0 at PRIORITY 1 [ TICKS 9 ALLOT 2 TIME 479 (of 500) ]
[ time 131 ] IO_START by JOB 0
IO DONE
[ time 131 ] Run JOB 1 at PRIORITY 0 [ TICKS 3 ALLOT 1 TIME 393 (of 500) ]
[ time 132 ] Run JOB 1 at PRIORITY 0 [ TICKS 2 ALLOT 1 TIME 392 (of 500) ]
[ time 133 ] Run JOB 1 at PRIORITY 0 [ TICKS 1 ALLOT 1 TIME 391 (of 500) ]
[ time 134 ] Run JOB 1 at PRIORITY 0 [ TICKS 0 ALLOT 1 TIME 390 (of 500) ]
[ time 135 ] Run JOB 1 at PRIORITY 0 [ TICKS 9 ALLOT 2 TIME 389 (of 500) ]
[ time 136 ] IO_DONE by JOB 0
[ time 136 ] Run JOB 0 at PRIORITY 1 [ TICKS 9 ALLOT 2 TIME 478 (of 500) ]
[ time 137 ] IO_START by JOB 0
IO DONE
[ time 137 ] Run JOB 1 at PRIORITY 0 [ TICKS 8 ALLOT 2 TIME 388 (of 500) ]
[ time 138 ] Run JOB 1 at PRIORITY 0 [ TICKS 7 ALLOT 2 TIME 387 (of 500) ]
[ time 139 ] Run JOB 1 at PRIORITY 0 [ TICKS 6 ALLOT 2 TIME 386 (of 500) ]
[ time 140 ] Run JOB 1 at PRIORITY 0 [ TICKS 5 ALLOT 2 TIME 385 (of 500) ]
[ time 141 ] Run JOB 1 at PRIORITY 0 [ TICKS 4 ALLOT 2 TIME 384 (of 500) ]
[ time 142 ] IO_DONE by JOB 0
[ time 142 ] Run JOB 0 at PRIORITY 1 [ TICKS 9 ALLOT 2 TIME 477 (of 500) ]
[ time 143 ] IO_START by JOB 0
IO DONE
[ time 143 ] Run JOB 1 at PRIORITY 0 [ TICKS 3 ALLOT 2 TIME 383 (of 500) ]
[ time 144 ] Run JOB 1 at PRIORITY 0 [ TICKS 2 ALLOT 2 TIME 382 (of 500) ]
[ time 145 ] Run JOB 1 at PRIORITY 0 [ TICKS 1 ALLOT 2 TIME 381 (of 500) ]
[ time 146 ] Run JOB 1 at PRIORITY 0 [ TICKS 0 ALLOT 2 TIME 380 (of 500) ]
[ time 147 ] Run JOB 1 at PRIORITY 0 [ TICKS 9 ALLOT 1 TIME 379 (of 500) ]
[ time 148 ] IO_DONE by JOB 0
[ time 148 ] Run JOB 0 at PRIORITY 1 [ TICKS 9 ALLOT 2 TIME 476 (of 500) ]
[ time 149 ] IO_START by JOB 0
IO DONE
[ time 149 ] Run JOB 1 at PRIORITY 0 [ TICKS 8 ALLOT 1 TIME 378 (of 500) ]
[ time 150 ] Run JOB 1 at PRIORITY 0 [ TICKS 7 ALLOT 1 TIME 377 (of 500) ]
[ time 151 ] Run JOB 1 at PRIORITY 0 [ TICKS 6 ALLOT 1 TIME 376 (of 500) ]
[ time 152 ] Run JOB 1 at PRIORITY 0 [ TICKS 5 ALLOT 1 TIME 375 (of 500) ]
[ time 153 ] Run JOB 1 at PRIORITY 0 [ TICKS 4 ALLOT 1 TIME 374 (of 500) ]
[ time 154 ] IO_DONE by JOB 0
[ time 154 ] Run JOB 0 at PRIORITY 1 [ TICKS 9 ALLOT 2 TIME 475 (of 500) ]
[ time 155 ] IO_START by JOB 0
IO DONE
[ time 155 ] Run JOB 1 at PRIORITY 0 [ TICKS 3 ALLOT 1 TIME 373 (of 500) ]
[ time 156 ] Run JOB 1 at PRIORITY 0 [ TICKS 2 ALLOT 1 TIME 372 (of 500) ]
[ time 157 ] Run JOB 1 at PRIORITY 0 [ TICKS 1 ALLOT 1 TIME 371 (of 500) ]
[ time 158 ] Run JOB 1 at PRIORITY 0 [ TICKS 0 ALLOT 1 TIME 370 (of 500) ]
[ time 159 ] Run JOB 1 at PRIORITY 0 [ TICKS 9 ALLOT 2 TIME 369 (of 500) ]
[ time 160 ] IO_DONE by JOB 0
[ time 160 ] Run JOB 0 at PRIORITY 1 [ TICKS 9 ALLOT 2 TIME 474 (of 500) ]
[ time 161 ] IO_START by JOB 0
IO DONE
[ time 161 ] Run JOB 1 at PRIORITY 0 [ TICKS 8 ALLOT 2 TIME 368 (of 500) ]
[ time 162 ] Run JOB 1 at PRIORITY 0 [ TICKS 7 ALLOT 2 TIME 367 (of 500) ]
[ time 163 ] Run JOB 1 at PRIORITY 0 [ TICKS 6 ALLOT 2 TIME 366 (of 500) ]
[ time 164 ] Run JOB 1 at PRIORITY 0 [ TICKS 5 ALLOT 2 TIME 365 (of 500) ]
[ time 165 ] Run JOB 1 at PRIORITY 0 [ TICKS 4 ALLOT 2 TIME 364 (of 500) ]
[ time 166 ] IO_DONE by JOB 0
[ time 166 ] Run JOB 0 at PRIORITY 1 [ TICKS 9 ALLOT 2 TIME 473 (of 500) ]
[ time 167 ] IO_START by JOB 0
IO DONE
[ time 167 ] Run JOB 1 at PRIORITY 0 [ TICKS 3 ALLOT 2 TIME 363 (of 500) ]
[ time 168 ] Run JOB 1 at PRIORITY 0 [ TICKS 2 ALLOT 2 TIME 362 (of 500) ]
[ time 169 ] Run JOB 1 at PRIORITY 0 [ TICKS 1 ALLOT 2 TIME 361 (of 500) ]
[ time 170 ] Run JOB 1 at PRIORITY 0 [ TICKS 0 ALLOT 2 TIME 360 (of 500) ]
[ time 171 ] Run JOB 1 at PRIORITY 0 [ TICKS 9 ALLOT 1 TIME 359 (of 500) ]
[ time 172 ] IO_DONE by JOB 0
[ time 172 ] Run JOB 0 at PRIORITY 1 [ TICKS 9 ALLOT 2 TIME 472 (of 500) ]
[ time 173 ] IO_START by JOB 0
IO DONE
[ time 173 ] Run JOB 1 at PRIORITY 0 [ TICKS 8 ALLOT 1 TIME 358 (of 500) ]
[ time 174 ] Run JOB 1 at PRIORITY 0 [ TICKS 7 ALLOT 1 TIME 357 (of 500) ]
[ time 175 ] Run JOB 1 at PRIORITY 0 [ TICKS 6 ALLOT 1 TIME 356 (of 500) ]
[ time 176 ] Run JOB 1 at PRIORITY 0 [ TICKS 5 ALLOT 1 TIME 355 (of 500) ]
[ time 177 ] Run JOB 1 at PRIORITY 0 [ TICKS 4 ALLOT 1 TIME 354 (of 500) ]
[ time 178 ] IO_DONE by JOB 0
[ time 178 ] Run JOB 0 at PRIORITY 1 [ TICKS 9 ALLOT 2 TIME 471 (of 500) ]
[ time 179 ] IO_START by JOB 0
IO DONE
[ time 179 ] Run JOB 1 at PRIORITY 0 [ TICKS 3 ALLOT 1 TIME 353 (of 500) ]
[ time 180 ] Run JOB 1 at PRIORITY 0 [ TICKS 2 ALLOT 1 TIME 352 (of 500) ]
[ time 181 ] Run JOB 1 at PRIORITY 0 [ TICKS 1 ALLOT 1 TIME 351 (of 500) ]
[ time 182 ] Run JOB 1 at PRIORITY 0 [ TICKS 0 ALLOT 1 TIME 350 (of 500) ]
[ time 183 ] Run JOB 1 at PRIORITY 0 [ TICKS 9 ALLOT 2 TIME 349 (of 500) ]
[ time 184 ] IO_DONE by JOB 0
[ time 184 ] Run JOB 0 at PRIORITY 1 [ TICKS 9 ALLOT 2 TIME 470 (of 500) ]
[ time 185 ] IO_START by JOB 0
IO DONE
[ time 185 ] Run JOB 1 at PRIORITY 0 [ TICKS 8 ALLOT 2 TIME 348 (of 500) ]
[ time 186 ] Run JOB 1 at PRIORITY 0 [ TICKS 7 ALLOT 2 TIME 347 (of 500) ]
[ time 187 ] Run JOB 1 at PRIORITY 0 [ TICKS 6 ALLOT 2 TIME 346 (of 500) ]
[ time 188 ] Run JOB 1 at PRIORITY 0 [ TICKS 5 ALLOT 2 TIME 345 (of 500) ]
[ time 189 ] Run JOB 1 at PRIORITY 0 [ TICKS 4 ALLOT 2 TIME 344 (of 500) ]
[ time 190 ] IO_DONE by JOB 0
[ time 190 ] Run JOB 0 at PRIORITY 1 [ TICKS 9 ALLOT 2 TIME 469 (of 500) ]
[ time 191 ] IO_START by JOB 0
IO DONE
[ time 191 ] Run JOB 1 at PRIORITY 0 [ TICKS 3 ALLOT 2 TIME 343 (of 500) ]
[ time 192 ] Run JOB 1 at PRIORITY 0 [ TICKS 2 ALLOT 2 TIME 342 (of 500) ]
[ time 193 ] Run JOB 1 at PRIORITY 0 [ TICKS 1 ALLOT 2 TIME 341 (of 500) ]
[ time 194 ] Run JOB 1 at PRIORITY 0 [ TICKS 0 ALLOT 2 TIME 340 (of 500) ]
[ time 195 ] Run JOB 1 at PRIORITY 0 [ TICKS 9 ALLOT 1 TIME 339 (of 500) ]
[ time 196 ] IO_DONE by JOB 0
[ time 196 ] Run JOB 0 at PRIORITY 1 [ TICKS 9 ALLOT 2 TIME 468 (of 500) ]
[ time 197 ] IO_START by JOB 0
IO DONE
[ time 197 ] Run JOB 1 at PRIORITY 0 [ TICKS 8 ALLOT 1 TIME 338 (of 500) ]
[ time 198 ] Run JOB 1 at PRIORITY 0 [ TICKS 7 ALLOT 1 TIME 337 (of 500) ]
[ time 199 ] Run JOB 1 at PRIORITY 0 [ TICKS 6 ALLOT 1 TIME 336 (of 500) ]
[ time 200 ] Run JOB 1 at PRIORITY 0 [ TICKS 5 ALLOT 1 TIME 335 (of 500) ]
[ time 201 ] Run JOB 1 at PRIORITY 0 [ TICKS 4 ALLOT 1 TIME 334 (of 500) ]
[ time 202 ] IO_DONE by JOB 0
[ time 202 ] Run JOB 0 at PRIORITY 1 [ TICKS 9 ALLOT 2 TIME 467 (of 500) ]
[ time 203 ] IO_START by JOB 0
IO DONE
[ time 203 ] Run JOB 1 at PRIORITY 0 [ TICKS 3 ALLOT 1 TIME 333 (of 500) ]
[ time 204 ] Run JOB 1 at PRIORITY 0 [ TICKS 2 ALLOT 1 TIME 332 (of 500) ]
[ time 205 ] Run JOB 1 at PRIORITY 0 [ TICKS 1 ALLOT 1 TIME 331 (of 500) ]
[ time 206 ] Run JOB 1 at PRIORITY 0 [ TICKS 0 ALLOT 1 TIME 330 (of 500) ]
[ time 207 ] Run JOB 1 at PRIORITY 0 [ TICKS 9 ALLOT 2 TIME 329 (of 500) ]
[ time 208 ] IO_DONE by JOB 0
[ time 208 ] Run JOB 0 at PRIORITY 1 [ TICKS 9 ALLOT 2 TIME 466 (of 500) ]
[ time 209 ] IO_START by JOB 0
IO DONE
[ time 209 ] Run JOB 1 at PRIORITY 0 [ TICKS 8 ALLOT 2 TIME 328 (of 500) ]
[ time 210 ] Run JOB 1 at PRIORITY 0 [ TICKS 7 ALLOT 2 TIME 327 (of 500) ]
[ time 211 ] Run JOB 1 at PRIORITY 0 [ TICKS 6 ALLOT 2 TIME 326 (of 500) ]
[ time 212 ] Run JOB 1 at PRIORITY 0 [ TICKS 5 ALLOT 2 TIME 325 (of 500) ]
[ time 213 ] Run JOB 1 at PRIORITY 0 [ TICKS 4 ALLOT 2 TIME 324 (of 500) ]
[ time 214 ] IO_DONE by JOB 0
[ time 214 ] Run JOB 0 at PRIORITY 1 [ TICKS 9 ALLOT 2 TIME 465 (of 500) ]
[ time 215 ] IO_START by JOB 0
IO DONE
[ time 215 ] Run JOB 1 at PRIORITY 0 [ TICKS 3 ALLOT 2 TIME 323 (of 500) ]
[ time 216 ] Run JOB 1 at PRIORITY 0 [ TICKS 2 ALLOT 2 TIME 322 (of 500) ]
[ time 217 ] Run JOB 1 at PRIORITY 0 [ TICKS 1 ALLOT 2 TIME 321 (of 500) ]
[ time 218 ] Run JOB 1 at PRIORITY 0 [ TICKS 0 ALLOT 2 TIME 320 (of 500) ]
[ time 219 ] Run JOB 1 at PRIORITY 0 [ TICKS 9 ALLOT 1 TIME 319 (of 500) ]
[ time 220 ] IO_DONE by JOB 0
[ time 220 ] Run JOB 0 at PRIORITY 1 [ TICKS 9 ALLOT 2 TIME 464 (of 500) ]
[ time 221 ] IO_START by JOB 0
IO DONE
[ time 221 ] Run JOB 1 at PRIORITY 0 [ TICKS 8 ALLOT 1 TIME 318 (of 500) ]
[ time 222 ] Run JOB 1 at PRIORITY 0 [ TICKS 7 ALLOT 1 TIME 317 (of 500) ]
[ time 223 ] Run JOB 1 at PRIORITY 0 [ TICKS 6 ALLOT 1 TIME 316 (of 500) ]
[ time 224 ] Run JOB 1 at PRIORITY 0 [ TICKS 5 ALLOT 1 TIME 315 (of 500) ]
[ time 225 ] Run JOB 1 at PRIORITY 0 [ TICKS 4 ALLOT 1 TIME 314 (of 500) ]
[ time 226 ] IO_DONE by JOB 0
[ time 226 ] Run JOB 0 at PRIORITY 1 [ TICKS 9 ALLOT 2 TIME 463 (of 500) ]
[ time 227 ] IO_START by JOB 0
IO DONE
[ time 227 ] Run JOB 1 at PRIORITY 0 [ TICKS 3 ALLOT 1 TIME 313 (of 500) ]
[ time 228 ] Run JOB 1 at PRIORITY 0 [ TICKS 2 ALLOT 1 TIME 312 (of 500) ]
[ time 229 ] Run JOB 1 at PRIORITY 0 [ TICKS 1 ALLOT 1 TIME 311 (of 500) ]
[ time 230 ] Run JOB 1 at PRIORITY 0 [ TICKS 0 ALLOT 1 TIME 310 (of 500) ]
[ time 231 ] Run JOB 1 at PRIORITY 0 [ TICKS 9 ALLOT 2 TIME 309 (of 500) ]
[ time 232 ] IO_DONE by JOB 0
[ time 232 ] Run JOB 0 at PRIORITY 1 [ TICKS 9 ALLOT 2 TIME 462 (of 500) ]
[ time 233 ] IO_START by JOB 0
IO DONE
[ time 233 ] Run JOB 1 at PRIORITY 0 [ TICKS 8 ALLOT 2 TIME 308 (of 500) ]
[ time 234 ] Run JOB 1 at PRIORITY 0 [ TICKS 7 ALLOT 2 TIME 307 (of 500) ]
[ time 235 ] Run JOB 1 at PRIORITY 0 [ TICKS 6 ALLOT 2 TIME 306 (of 500) ]
[ time 236 ] Run JOB 1 at PRIORITY 0 [ TICKS 5 ALLOT 2 TIME 305 (of 500) ]
[ time 237 ] Run JOB 1 at PRIORITY 0 [ TICKS 4 ALLOT 2 TIME 304 (of 500) ]
[ time 238 ] IO_DONE by JOB 0
[ time 238 ] Run JOB 0 at PRIORITY 1 [ TICKS 9 ALLOT 2 TIME 461 (of 500) ]
[ time 239 ] IO_START by JOB 0
IO DONE
[ time 239 ] Run JOB 1 at PRIORITY 0 [ TICKS 3 ALLOT 2 TIME 303 (of 500) ]
[ time 240 ] Run JOB 1 at PRIORITY 0 [ TICKS 2 ALLOT 2 TIME 302 (of 500) ]
[ time 241 ] Run JOB 1 at PRIORITY 0 [ TICKS 1 ALLOT 2 TIME 301 (of 500) ]
[ time 242 ] Run JOB 1 at PRIORITY 0 [ TICKS 0 ALLOT 2 TIME 300 (of 500) ]
[ time 243 ] IO_START by JOB 1
IO DONE
[ time 243 ] IDLE
[ time 244 ] IO_DONE by JOB 0
[ time 244 ] Run JOB 0 at PRIORITY 1 [ TICKS 9 ALLOT 2 TIME 460 (of 500) ]
[ time 245 ] IO_START by JOB 0
IO DONE
[ time 245 ] IDLE
[ time 246 ] IDLE
[ time 247 ] IDLE
[ time 248 ] IO_DONE by JOB 1
[ time 248 ] Run JOB 1 at PRIORITY 0 [ TICKS 9 ALLOT 1 TIME 299 (of 500) ]
[ time 249 ] Run JOB 1 at PRIORITY 0 [ TICKS 8 ALLOT 1 TIME 298 (of 500) ]
[ time 250 ] IO_DONE by JOB 0
[ time 250 ] Run JOB 0 at PRIORITY 1 [ TICKS 9 ALLOT 2 TIME 459 (of 500) ]
[ time 251 ] IO_START by JOB 0
IO DONE
[ time 251 ] Run JOB 1 at PRIORITY 0 [ TICKS 7 ALLOT 1 TIME 297 (of 500) ]
[ time 252 ] Run JOB 1 at PRIORITY 0 [ TICKS 6 ALLOT 1 TIME 296 (of 500) ]
[ time 253 ] Run JOB 1 at PRIORITY 0 [ TICKS 5 ALLOT 1 TIME 295 (of 500) ]
[ time 254 ] Run JOB 1 at PRIORITY 0 [ TICKS 4 ALLOT 1 TIME 294 (of 500) ]
[ time 255 ] Run JOB 1 at PRIORITY 0 [ TICKS 3 ALLOT 1 TIME 293 (of 500) ]
[ time 256 ] IO_DONE by JOB 0
[ time 256 ] Run JOB 0 at PRIORITY 1 [ TICKS 9 ALLOT 2 TIME 458 (of 500) ]
[ time 257 ] IO_START by JOB 0
IO DONE
[ time 257 ] Run JOB 1 at PRIORITY 0 [ TICKS 2 ALLOT 1 TIME 292 (of 500) ]
[ time 258 ] Run JOB 1 at PRIORITY 0 [ TICKS 1 ALLOT 1 TIME 291 (of 500) ]
[ time 259 ] Run JOB 1 at PRIORITY 0 [ TICKS 0 ALLOT 1 TIME 290 (of 500) ]
[ time 260 ] Run JOB 1 at PRIORITY 0 [ TICKS 9 ALLOT 2 TIME 289 (of 500) ]
[ time 261 ] Run JOB 1 at PRIORITY 0 [ TICKS 8 ALLOT 2 TIME 288 (of 500) ]
[ time 262 ] IO_DONE by JOB 0
[ time 262 ] Run JOB 0 at PRIORITY 1 [ TICKS 9 ALLOT 2 TIME 457 (of 500) ]
[ time 263 ] IO_START by JOB 0
IO DONE
[ time 263 ] Run JOB 1 at PRIORITY 0 [ TICKS 7 ALLOT 2 TIME 287 (of 500) ]
[ time 264 ] Run JOB 1 at PRIORITY 0 [ TICKS 6 ALLOT 2 TIME 286 (of 500) ]
[ time 265 ] Run JOB 1 at PRIORITY 0 [ TICKS 5 ALLOT 2 TIME 285 (of 500) ]
[ time 266 ] Run JOB 1 at PRIORITY 0 [ TICKS 4 ALLOT 2 TIME 284 (of 500) ]
[ time 267 ] Run JOB 1 at PRIORITY 0 [ TICKS 3 ALLOT 2 TIME 283 (of 500) ]
[ time 268 ] IO_DONE by JOB 0
[ time 268 ] Run JOB 0 at PRIORITY 1 [ TICKS 9 ALLOT 2 TIME 456 (of 500) ]
[ time 269 ] IO_START by JOB 0
IO DONE
[ time 269 ] Run JOB 1 at PRIORITY 0 [ TICKS 2 ALLOT 2 TIME 282 (of 500) ]
[ time 270 ] Run JOB 1 at PRIORITY 0 [ TICKS 1 ALLOT 2 TIME 281 (of 500) ]
[ time 271 ] Run JOB 1 at PRIORITY 0 [ TICKS 0 ALLOT 2 TIME 280 (of 500) ]
[ time 272 ] Run JOB 1 at PRIORITY 0 [ TICKS 9 ALLOT 1 TIME 279 (of 500) ]
[ time 273 ] Run JOB 1 at PRIORITY 0 [ TICKS 8 ALLOT 1 TIME 278 (of 500) ]
[ time 274 ] IO_DONE by JOB 0
[ time 274 ] Run JOB 0 at PRIORITY 1 [ TICKS 9 ALLOT 2 TIME 455 (of 500) ]
[ time 275 ] IO_START by JOB 0
IO DONE
[ time 275 ] Run JOB 1 at PRIORITY 0 [ TICKS 7 ALLOT 1 TIME 277 (of 500) ]
[ time 276 ] Run JOB 1 at PRIORITY 0 [ TICKS 6 ALLOT 1 TIME 276 (of 500) ]
[ time 277 ] Run JOB 1 at PRIORITY 0 [ TICKS 5 ALLOT 1 TIME 275 (of 500) ]
[ time 278 ] Run JOB 1 at PRIORITY 0 [ TICKS 4 ALLOT 1 TIME 274 (of 500) ]
[ time 279 ] Run JOB 1 at PRIORITY 0 [ TICKS 3 ALLOT 1 TIME 273 (of 500) ]
[ time 280 ] IO_DONE by JOB 0
[ time 280 ] Run JOB 0 at PRIORITY 1 [ TICKS 9 ALLOT 2 TIME 454 (of 500) ]
[ time 281 ] IO_START by JOB 0
IO DONE
[ time 281 ] Run JOB 1 at PRIORITY 0 [ TICKS 2 ALLOT 1 TIME 272 (of 500) ]
[ time 282 ] Run JOB 1 at PRIORITY 0 [ TICKS 1 ALLOT 1 TIME 271 (of 500) ]
[ time 283 ] Run JOB 1 at PRIORITY 0 [ TICKS 0 ALLOT 1 TIME 270 (of 500) ]
[ time 284 ] Run JOB 1 at PRIORITY 0 [ TICKS 9 ALLOT 2 TIME 269 (of 500) ]
[ time 285 ] Run JOB 1 at PRIORITY 0 [ TICKS 8 ALLOT 2 TIME 268 (of 500) ]
[ time 286 ] IO_DONE by JOB 0
[ time 286 ] Run JOB 0 at PRIORITY 1 [ TICKS 9 ALLOT 2 TIME 453 (of 500) ]
[ time 287 ] IO_START by JOB 0
IO DONE
[ time 287 ] Run JOB 1 at PRIORITY 0 [ TICKS 7 ALLOT 2 TIME 267 (of 500) ]
[ time 288 ] Run JOB 1 at PRIORITY 0 [ TICKS 6 ALLOT 2 TIME 266 (of 500) ]
[ time 289 ] Run JOB 1 at PRIORITY 0 [ TICKS 5 ALLOT 2 TIME 265 (of 500) ]
[ time 290 ] Run JOB 1 at PRIORITY 0 [ TICKS 4 ALLOT 2 TIME 264 (of 500) ]
[ time 291 ] Run JOB 1 at PRIORITY 0 [ TICKS 3 ALLOT 2 TIME 263 (of 500) ]
[ time 292 ] IO_DONE by JOB 0
[ time 292 ] Run JOB 0 at PRIORITY 1 [ TICKS 9 ALLOT 2 TIME 452 (of 500) ]
[ time 293 ] IO_START by JOB 0
IO DONE
[ time 293 ] Run JOB 1 at PRIORITY 0 [ TICKS 2 ALLOT 2 TIME 262 (of 500) ]
[ time 294 ] Run JOB 1 at PRIORITY 0 [ TICKS 1 ALLOT 2 TIME 261 (of 500) ]
[ time 295 ] Run JOB 1 at PRIORITY 0 [ TICKS 0 ALLOT 2 TIME 260 (of 500) ]
[ time 296 ] Run JOB 1 at PRIORITY 0 [ TICKS 9 ALLOT 1 TIME 259 (of 500) ]
[ time 297 ] Run JOB 1 at PRIORITY 0 [ TICKS 8 ALLOT 1 TIME 258 (of 500) ]
[ time 298 ] IO_DONE by JOB 0
[ time 298 ] Run JOB 0 at PRIORITY 1 [ TICKS 9 ALLOT 2 TIME 451 (of 500) ]
[ time 299 ] IO_START by JOB 0
IO DONE
[ time 299 ] Run JOB 1 at PRIORITY 0 [ TICKS 7 ALLOT 1 TIME 257 (of 500) ]
[ time 300 ] Run JOB 1 at PRIORITY 0 [ TICKS 6 ALLOT 1 TIME 256 (of 500) ]
[ time 301 ] Run JOB 1 at PRIORITY 0 [ TICKS 5 ALLOT 1 TIME 255 (of 500) ]
[ time 302 ] Run JOB 1 at PRIORITY 0 [ TICKS 4 ALLOT 1 TIME 254 (of 500) ]
[ time 303 ] Run JOB 1 at PRIORITY 0 [ TICKS 3 ALLOT 1 TIME 253 (of 500) ]
[ time 304 ] IO_DONE by JOB 0
[ time 304 ] Run JOB 0 at PRIORITY 1 [ TICKS 9 ALLOT 2 TIME 450 (of 500) ]
[ time 305 ] IO_START by JOB 0
IO DONE
[ time 305 ] Run JOB 1 at PRIORITY 0 [ TICKS 2 ALLOT 1 TIME 252 (of 500) ]
[ time 306 ] Run JOB 1 at PRIORITY 0 [ TICKS 1 ALLOT 1 TIME 251 (of 500) ]
[ time 307 ] Run JOB 1 at PRIORITY 0 [ TICKS 0 ALLOT 1 TIME 250 (of 500) ]
[ time 308 ] Run JOB 1 at PRIORITY 0 [ TICKS 9 ALLOT 2 TIME 249 (of 500) ]
[ time 309 ] Run JOB 1 at PRIORITY 0 [ TICKS 8 ALLOT 2 TIME 248 (of 500) ]
[ time 310 ] IO_DONE by JOB 0
[ time 310 ] Run JOB 0 at PRIORITY 1 [ TICKS 9 ALLOT 2 TIME 449 (of 500) ]
[ time 311 ] IO_START by JOB 0
IO DONE
[ time 311 ] Run JOB 1 at PRIORITY 0 [ TICKS 7 ALLOT 2 TIME 247 (of 500) ]
[ time 312 ] Run JOB 1 at PRIORITY 0 [ TICKS 6 ALLOT 2 TIME 246 (of 500) ]
[ time 313 ] Run JOB 1 at PRIORITY 0 [ TICKS 5 ALLOT 2 TIME 245 (of 500) ]
[ time 314 ] Run JOB 1 at PRIORITY 0 [ TICKS 4 ALLOT 2 TIME 244 (of 500) ]
[ time 315 ] Run JOB 1 at PRIORITY 0 [ TICKS 3 ALLOT 2 TIME 243 (of 500) ]
[ time 316 ] IO_DONE by JOB 0
[ time 316 ] Run JOB 0 at PRIORITY 1 [ TICKS 9 ALLOT 2 TIME 448 (of 500) ]
[ time 317 ] IO_START by JOB 0
IO DONE
[ time 317 ] Run JOB 1 at PRIORITY 0 [ TICKS 2 ALLOT 2 TIME 242 (of 500) ]
[ time 318 ] Run JOB 1 at PRIORITY 0 [ TICKS 1 ALLOT 2 TIME 241 (of 500) ]
[ time 319 ] Run JOB 1 at PRIORITY 0 [ TICKS 0 ALLOT 2 TIME 240 (of 500) ]
[ time 320 ] Run JOB 1 at PRIORITY 0 [ TICKS 9 ALLOT 1 TIME 239 (of 500) ]
[ time 321 ] Run JOB 1 at PRIORITY 0 [ TICKS 8 ALLOT 1 TIME 238 (of 500) ]
[ time 322 ] IO_DONE by JOB 0
[ time 322 ] Run JOB 0 at PRIORITY 1 [ TICKS 9 ALLOT 2 TIME 447 (of 500) ]
[ time 323 ] IO_START by JOB 0
IO DONE
[ time 323 ] Run JOB 1 at PRIORITY 0 [ TICKS 7 ALLOT 1 TIME 237 (of 500) ]
[ time 324 ] Run JOB 1 at PRIORITY 0 [ TICKS 6 ALLOT 1 TIME 236 (of 500) ]
[ time 325 ] Run JOB 1 at PRIORITY 0 [ TICKS 5 ALLOT 1 TIME 235 (of 500) ]
[ time 326 ] Run JOB 1 at PRIORITY 0 [ TICKS 4 ALLOT 1 TIME 234 (of 500) ]
[ time 327 ] Run JOB 1 at PRIORITY 0 [ TICKS 3 ALLOT 1 TIME 233 (of 500) ]
[ time 328 ] IO_DONE by JOB 0
[ time 328 ] Run JOB 0 at PRIORITY 1 [ TICKS 9 ALLOT 2 TIME 446 (of 500) ]
[ time 329 ] IO_START by JOB 0
IO DONE
[ time 329 ] Run JOB 1 at PRIORITY 0 [ TICKS 2 ALLOT 1 TIME 232 (of 500) ]
[ time 330 ] Run JOB 1 at PRIORITY 0 [ TICKS 1 ALLOT 1 TIME 231 (of 500) ]
[ time 331 ] Run JOB 1 at PRIORITY 0 [ TICKS 0 ALLOT 1 TIME 230 (of 500) ]
[ time 332 ] Run JOB 1 at PRIORITY 0 [ TICKS 9 ALLOT 2 TIME 229 (of 500) ]
[ time 333 ] Run JOB 1 at PRIORITY 0 [ TICKS 8 ALLOT 2 TIME 228 (of 500) ]
[ time 334 ] IO_DONE by JOB 0
[ time 334 ] Run JOB 0 at PRIORITY 1 [ TICKS 9 ALLOT 2 TIME 445 (of 500) ]
[ time 335 ] IO_START by JOB 0
IO DONE
[ time 335 ] Run JOB 1 at PRIORITY 0 [ TICKS 7 ALLOT 2 TIME 227 (of 500) ]
[ time 336 ] Run JOB 1 at PRIORITY 0 [ TICKS 6 ALLOT 2 TIME 226 (of 500) ]
[ time 337 ] Run JOB 1 at PRIORITY 0 [ TICKS 5 ALLOT 2 TIME 225 (of 500) ]
[ time 338 ] Run JOB 1 at PRIORITY 0 [ TICKS 4 ALLOT 2 TIME 224 (of 500) ]
[ time 339 ] Run JOB 1 at PRIORITY 0 [ TICKS 3 ALLOT 2 TIME 223 (of 500) ]
[ time 340 ] IO_DONE by JOB 0
[ time 340 ] Run JOB 0 at PRIORITY 1 [ TICKS 9 ALLOT 2 TIME 444 (of 500) ]
[ time 341 ] IO_START by JOB 0
IO DONE
[ time 341 ] Run JOB 1 at PRIORITY 0 [ TICKS 2 ALLOT 2 TIME 222 (of 500) ]
[ time 342 ] Run JOB 1 at PRIORITY 0 [ TICKS 1 ALLOT 2 TIME 221 (of 500) ]
[ time 343 ] Run JOB 1 at PRIORITY 0 [ TICKS 0 ALLOT 2 TIME 220 (of 500) ]
[ time 344 ] Run JOB 1 at PRIORITY 0 [ TICKS 9 ALLOT 1 TIME 219 (of 500) ]
[ time 345 ] Run JOB 1 at PRIORITY 0 [ TICKS 8 ALLOT 1 TIME 218 (of 500) ]
[ time 346 ] IO_DONE by JOB 0
[ time 346 ] Run JOB 0 at PRIORITY 1 [ TICKS 9 ALLOT 2 TIME 443 (of 500) ]
[ time 347 ] IO_START by JOB 0
IO DONE
[ time 347 ] Run JOB 1 at PRIORITY 0 [ TICKS 7 ALLOT 1 TIME 217 (of 500) ]
[ time 348 ] Run JOB 1 at PRIORITY 0 [ TICKS 6 ALLOT 1 TIME 216 (of 500) ]
[ time 349 ] Run JOB 1 at PRIORITY 0 [ TICKS 5 ALLOT 1 TIME 215 (of 500) ]
[ time 350 ] Run JOB 1 at PRIORITY 0 [ TICKS 4 ALLOT 1 TIME 214 (of 500) ]
[ time 351 ] Run JOB 1 at PRIORITY 0 [ TICKS 3 ALLOT 1 TIME 213 (of 500) ]
[ time 352 ] IO_DONE by JOB 0
[ time 352 ] Run JOB 0 at PRIORITY 1 [ TICKS 9 ALLOT 2 TIME 442 (of 500) ]
[ time 353 ] IO_START by JOB 0
IO DONE
[ time 353 ] Run JOB 1 at PRIORITY 0 [ TICKS 2 ALLOT 1 TIME 212 (of 500) ]
[ time 354 ] Run JOB 1 at PRIORITY 0 [ TICKS 1 ALLOT 1 TIME 211 (of 500) ]
[ time 355 ] Run JOB 1 at PRIORITY 0 [ TICKS 0 ALLOT 1 TIME 210 (of 500) ]
[ time 356 ] Run JOB 1 at PRIORITY 0 [ TICKS 9 ALLOT 2 TIME 209 (of 500) ]
[ time 357 ] Run JOB 1 at PRIORITY 0 [ TICKS 8 ALLOT 2 TIME 208 (of 500) ]
[ time 358 ] IO_DONE by JOB 0
[ time 358 ] Run JOB 0 at PRIORITY 1 [ TICKS 9 ALLOT 2 TIME 441 (of 500) ]
[ time 359 ] IO_START by JOB 0
IO DONE
[ time 359 ] Run JOB 1 at PRIORITY 0 [ TICKS 7 ALLOT 2 TIME 207 (of 500) ]
[ time 360 ] Run JOB 1 at PRIORITY 0 [ TICKS 6 ALLOT 2 TIME 206 (of 500) ]
[ time 361 ] Run JOB 1 at PRIORITY 0 [ TICKS 5 ALLOT 2 TIME 205 (of 500) ]
[ time 362 ] Run JOB 1 at PRIORITY 0 [ TICKS 4 ALLOT 2 TIME 204 (of 500) ]
[ time 363 ] Run JOB 1 at PRIORITY 0 [ TICKS 3 ALLOT 2 TIME 203 (of 500) ]
[ time 364 ] IO_DONE by JOB 0
[ time 364 ] Run JOB 0 at PRIORITY 1 [ TICKS 9 ALLOT 2 TIME 440 (of 500) ]
[ time 365 ] IO_START by JOB 0
IO DONE
[ time 365 ] Run JOB 1 at PRIORITY 0 [ TICKS 2 ALLOT 2 TIME 202 (of 500) ]
[ time 366 ] Run JOB 1 at PRIORITY 0 [ TICKS 1 ALLOT 2 TIME 201 (of 500) ]
[ time 367 ] Run JOB 1 at PRIORITY 0 [ TICKS 0 ALLOT 2 TIME 200 (of 500) ]
[ time 368 ] IO_START by JOB 1
IO DONE
[ time 368 ] IDLE
[ time 369 ] IDLE
[ time 370 ] IO_DONE by JOB 0
[ time 370 ] Run JOB 0 at PRIORITY 1 [ TICKS 9 ALLOT 2 TIME 439 (of 500) ]
[ time 371 ] IO_START by JOB 0
IO DONE
[ time 371 ] IDLE
[ time 372 ] IDLE
[ time 373 ] IO_DONE by JOB 1
[ time 373 ] Run JOB 1 at PRIORITY 0 [ TICKS 9 ALLOT 1 TIME 199 (of 500) ]
[ time 374 ] Run JOB 1 at PRIORITY 0 [ TICKS 8 ALLOT 1 TIME 198 (of 500) ]
[ time 375 ] Run JOB 1 at PRIORITY 0 [ TICKS 7 ALLOT 1 TIME 197 (of 500) ]
[ time 376 ] IO_DONE by JOB 0
[ time 376 ] Run JOB 0 at PRIORITY 1 [ TICKS 9 ALLOT 2 TIME 438 (of 500) ]
[ time 377 ] IO_START by JOB 0
IO DONE
[ time 377 ] Run JOB 1 at PRIORITY 0 [ TICKS 6 ALLOT 1 TIME 196 (of 500) ]
[ time 378 ] Run JOB 1 at PRIORITY 0 [ TICKS 5 ALLOT 1 TIME 195 (of 500) ]
[ time 379 ] Run JOB 1 at PRIORITY 0 [ TICKS 4 ALLOT 1 TIME 194 (of 500) ]
[ time 380 ] Run JOB 1 at PRIORITY 0 [ TICKS 3 ALLOT 1 TIME 193 (of 500) ]
[ time 381 ] Run JOB 1 at PRIORITY 0 [ TICKS 2 ALLOT 1 TIME 192 (of 500) ]
[ time 382 ] IO_DONE by JOB 0
[ time 382 ] Run JOB 0 at PRIORITY 1 [ TICKS 9 ALLOT 2 TIME 437 (of 500) ]
[ time 383 ] IO_START by JOB 0
IO DONE
[ time 383 ] Run JOB 1 at PRIORITY 0 [ TICKS 1 ALLOT 1 TIME 191 (of 500) ]
[ time 384 ] Run JOB 1 at PRIORITY 0 [ TICKS 0 ALLOT 1 TIME 190 (of 500) ]
[ time 385 ] Run JOB 1 at PRIORITY 0 [ TICKS 9 ALLOT 2 TIME 189 (of 500) ]
[ time 386 ] Run JOB 1 at PRIORITY 0 [ TICKS 8 ALLOT 2 TIME 188 (of 500) ]
[ time 387 ] Run JOB 1 at PRIORITY 0 [ TICKS 7 ALLOT 2 TIME 187 (of 500) ]
[ time 388 ] IO_DONE by JOB 0
[ time 388 ] Run JOB 0 at PRIORITY 1 [ TICKS 9 ALLOT 2 TIME 436 (of 500) ]
[ time 389 ] IO_START by JOB 0
IO DONE
[ time 389 ] Run JOB 1 at PRIORITY 0 [ TICKS 6 ALLOT 2 TIME 186 (of 500) ]
[ time 390 ] Run JOB 1 at PRIORITY 0 [ TICKS 5 ALLOT 2 TIME 185 (of 500) ]
[ time 391 ] Run JOB 1 at PRIORITY 0 [ TICKS 4 ALLOT 2 TIME 184 (of 500) ]
[ time 392 ] Run JOB 1 at PRIORITY 0 [ TICKS 3 ALLOT 2 TIME 183 (of 500) ]
[ time 393 ] Run JOB 1 at PRIORITY 0 [ TICKS 2 ALLOT 2 TIME 182 (of 500) ]
[ time 394 ] IO_DONE by JOB 0
[ time 394 ] Run JOB 0 at PRIORITY 1 [ TICKS 9 ALLOT 2 TIME 435 (of 500) ]
[ time 395 ] IO_START by JOB 0
IO DONE
[ time 395 ] Run JOB 1 at PRIORITY 0 [ TICKS 1 ALLOT 2 TIME 181 (of 500) ]
[ time 396 ] Run JOB 1 at PRIORITY 0 [ TICKS 0 ALLOT 2 TIME 180 (of 500) ]
[ time 397 ] Run JOB 1 at PRIORITY 0 [ TICKS 9 ALLOT 1 TIME 179 (of 500) ]
[ time 398 ] Run JOB 1 at PRIORITY 0 [ TICKS 8 ALLOT 1 TIME 178 (of 500) ]
[ time 399 ] Run JOB 1 at PRIORITY 0 [ TICKS 7 ALLOT 1 TIME 177 (of 500) ]
[ time 400 ] IO_DONE by JOB 0
[ time 400 ] Run JOB 0 at PRIORITY 1 [ TICKS 9 ALLOT 2 TIME 434 (of 500) ]
[ time 401 ] IO_START by JOB 0
IO DONE
[ time 401 ] Run JOB 1 at PRIORITY 0 [ TICKS 6 ALLOT 1 TIME 176 (of 500) ]
[ time 402 ] Run JOB 1 at PRIORITY 0 [ TICKS 5 ALLOT 1 TIME 175 (of 500) ]
[ time 403 ] Run JOB 1 at PRIORITY 0 [ TICKS 4 ALLOT 1 TIME 174 (of 500) ]
[ time 404 ] Run JOB 1 at PRIORITY 0 [ TICKS 3 ALLOT 1 TIME 173 (of 500) ]
[ time 405 ] Run JOB 1 at PRIORITY 0 [ TICKS 2 ALLOT 1 TIME 172 (of 500) ]
[ time 406 ] IO_DONE by JOB 0
[ time 406 ] Run JOB 0 at PRIORITY 1 [ TICKS 9 ALLOT 2 TIME 433 (of 500) ]
[ time 407 ] IO_START by JOB 0
IO DONE
[ time 407 ] Run JOB 1 at PRIORITY 0 [ TICKS 1 ALLOT 1 TIME 171 (of 500) ]
[ time 408 ] Run JOB 1 at PRIORITY 0 [ TICKS 0 ALLOT 1 TIME 170 (of 500) ]
[ time 409 ] Run JOB 1 at PRIORITY 0 [ TICKS 9 ALLOT 2 TIME 169 (of 500) ]
[ time 410 ] Run JOB 1 at PRIORITY 0 [ TICKS 8 ALLOT 2 TIME 168 (of 500) ]
[ time 411 ] Run JOB 1 at PRIORITY 0 [ TICKS 7 ALLOT 2 TIME 167 (of 500) ]
[ time 412 ] IO_DONE by JOB 0
[ time 412 ] Run JOB 0 at PRIORITY 1 [ TICKS 9 ALLOT 2 TIME 432 (of 500) ]
[ time 413 ] IO_START by JOB 0
IO DONE
[ time 413 ] Run JOB 1 at PRIORITY 0 [ TICKS 6 ALLOT 2 TIME 166 (of 500) ]
[ time 414 ] Run JOB 1 at PRIORITY 0 [ TICKS 5 ALLOT 2 TIME 165 (of 500) ]
[ time 415 ] Run JOB 1 at PRIORITY 0 [ TICKS 4 ALLOT 2 TIME 164 (of 500) ]
[ time 416 ] Run JOB 1 at PRIORITY 0 [ TICKS 3 ALLOT 2 TIME 163 (of 500) ]
[ time 417 ] Run JOB 1 at PRIORITY 0 [ TICKS 2 ALLOT 2 TIME 162 (of 500) ]
[ time 418 ] IO_DONE by JOB 0
[ time 418 ] Run JOB 0 at PRIORITY 1 [ TICKS 9 ALLOT 2 TIME 431 (of 500) ]
[ time 419 ] IO_START by JOB 0
IO DONE
[ time 419 ] Run JOB 1 at PRIORITY 0 [ TICKS 1 ALLOT 2 TIME 161 (of 500) ]
[ time 420 ] Run JOB 1 at PRIORITY 0 [ TICKS 0 ALLOT 2 TIME 160 (of 500) ]
[ time 421 ] Run JOB 1 at PRIORITY 0 [ TICKS 9 ALLOT 1 TIME 159 (of 500) ]
[ time 422 ] Run JOB 1 at PRIORITY 0 [ TICKS 8 ALLOT 1 TIME 158 (of 500) ]
[ time 423 ] Run JOB 1 at PRIORITY 0 [ TICKS 7 ALLOT 1 TIME 157 (of 500) ]
[ time 424 ] IO_DONE by JOB 0
[ time 424 ] Run JOB 0 at PRIORITY 1 [ TICKS 9 ALLOT 2 TIME 430 (of 500) ]
[ time 425 ] IO_START by JOB 0
IO DONE
[ time 425 ] Run JOB 1 at PRIORITY 0 [ TICKS 6 ALLOT 1 TIME 156 (of 500) ]
[ time 426 ] Run JOB 1 at PRIORITY 0 [ TICKS 5 ALLOT 1 TIME 155 (of 500) ]
[ time 427 ] Run JOB 1 at PRIORITY 0 [ TICKS 4 ALLOT 1 TIME 154 (of 500) ]
[ time 428 ] Run JOB 1 at PRIORITY 0 [ TICKS 3 ALLOT 1 TIME 153 (of 500) ]
[ time 429 ] Run JOB 1 at PRIORITY 0 [ TICKS 2 ALLOT 1 TIME 152 (of 500) ]
[ time 430 ] IO_DONE by JOB 0
[ time 430 ] Run JOB 0 at PRIORITY 1 [ TICKS 9 ALLOT 2 TIME 429 (of 500) ]
[ time 431 ] IO_START by JOB 0
IO DONE
[ time 431 ] Run JOB 1 at PRIORITY 0 [ TICKS 1 ALLOT 1 TIME 151 (of 500) ]
[ time 432 ] Run JOB 1 at PRIORITY 0 [ TICKS 0 ALLOT 1 TIME 150 (of 500) ]
[ time 433 ] Run JOB 1 at PRIORITY 0 [ TICKS 9 ALLOT 2 TIME 149 (of 500) ]
[ time 434 ] Run JOB 1 at PRIORITY 0 [ TICKS 8 ALLOT 2 TIME 148 (of 500) ]
[ time 435 ] Run JOB 1 at PRIORITY 0 [ TICKS 7 ALLOT 2 TIME 147 (of 500) ]
[ time 436 ] IO_DONE by JOB 0
[ time 436 ] Run JOB 0 at PRIORITY 1 [ TICKS 9 ALLOT 2 TIME 428 (of 500) ]
[ time 437 ] IO_START by JOB 0
IO DONE
[ time 437 ] Run JOB 1 at PRIORITY 0 [ TICKS 6 ALLOT 2 TIME 146 (of 500) ]
[ time 438 ] Run JOB 1 at PRIORITY 0 [ TICKS 5 ALLOT 2 TIME 145 (of 500) ]
[ time 439 ] Run JOB 1 at PRIORITY 0 [ TICKS 4 ALLOT 2 TIME 144 (of 500) ]
[ time 440 ] Run JOB 1 at PRIORITY 0 [ TICKS 3 ALLOT 2 TIME 143 (of 500) ]
[ time 441 ] Run JOB 1 at PRIORITY 0 [ TICKS 2 ALLOT 2 TIME 142 (of 500) ]
[ time 442 ] IO_DONE by JOB 0
[ time 442 ] Run JOB 0 at PRIORITY 1 [ TICKS 9 ALLOT 2 TIME 427 (of 500) ]
[ time 443 ] IO_START by JOB 0
IO DONE
[ time 443 ] Run JOB 1 at PRIORITY 0 [ TICKS 1 ALLOT 2 TIME 141 (of 500) ]
[ time 444 ] Run JOB 1 at PRIORITY 0 [ TICKS 0 ALLOT 2 TIME 140 (of 500) ]
[ time 445 ] Run JOB 1 at PRIORITY 0 [ TICKS 9 ALLOT 1 TIME 139 (of 500) ]
[ time 446 ] Run JOB 1 at PRIORITY 0 [ TICKS 8 ALLOT 1 TIME 138 (of 500) ]
[ time 447 ] Run JOB 1 at PRIORITY 0 [ TICKS 7 ALLOT 1 TIME 137 (of 500) ]
[ time 448 ] IO_DONE by JOB 0
[ time 448 ] Run JOB 0 at PRIORITY 1 [ TICKS 9 ALLOT 2 TIME 426 (of 500) ]
[ time 449 ] IO_START by JOB 0
IO DONE
[ time 449 ] Run JOB 1 at PRIORITY 0 [ TICKS 6 ALLOT 1 TIME 136 (of 500) ]
[ time 450 ] Run JOB 1 at PRIORITY 0 [ TICKS 5 ALLOT 1 TIME 135 (of 500) ]
[ time 451 ] Run JOB 1 at PRIORITY 0 [ TICKS 4 ALLOT 1 TIME 134 (of 500) ]
[ time 452 ] Run JOB 1 at PRIORITY 0 [ TICKS 3 ALLOT 1 TIME 133 (of 500) ]
[ time 453 ] Run JOB 1 at PRIORITY 0 [ TICKS 2 ALLOT 1 TIME 132 (of 500) ]
[ time 454 ] IO_DONE by JOB 0
[ time 454 ] Run JOB 0 at PRIORITY 1 [ TICKS 9 ALLOT 2 TIME 425 (of 500) ]
[ time 455 ] IO_START by JOB 0
IO DONE
[ time 455 ] Run JOB 1 at PRIORITY 0 [ TICKS 1 ALLOT 1 TIME 131 (of 500) ]
[ time 456 ] Run JOB 1 at PRIORITY 0 [ TICKS 0 ALLOT 1 TIME 130 (of 500) ]
[ time 457 ] Run JOB 1 at PRIORITY 0 [ TICKS 9 ALLOT 2 TIME 129 (of 500) ]
[ time 458 ] Run JOB 1 at PRIORITY 0 [ TICKS 8 ALLOT 2 TIME 128 (of 500) ]
[ time 459 ] Run JOB 1 at PRIORITY 0 [ TICKS 7 ALLOT 2 TIME 127 (of 500) ]
[ time 460 ] IO_DONE by JOB 0
[ time 460 ] Run JOB 0 at PRIORITY 1 [ TICKS 9 ALLOT 2 TIME 424 (of 500) ]
[ time 461 ] IO_START by JOB 0
IO DONE
[ time 461 ] Run JOB 1 at PRIORITY 0 [ TICKS 6 ALLOT 2 TIME 126 (of 500) ]
[ time 462 ] Run JOB 1 at PRIORITY 0 [ TICKS 5 ALLOT 2 TIME 125 (of 500) ]
[ time 463 ] Run JOB 1 at PRIORITY 0 [ TICKS 4 ALLOT 2 TIME 124 (of 500) ]
[ time 464 ] Run JOB 1 at PRIORITY 0 [ TICKS 3 ALLOT 2 TIME 123 (of 500) ]
[ time 465 ] Run JOB 1 at PRIORITY 0 [ TICKS 2 ALLOT 2 TIME 122 (of 500) ]
[ time 466 ] IO_DONE by JOB 0
[ time 466 ] Run JOB 0 at PRIORITY 1 [ TICKS 9 ALLOT 2 TIME 423 (of 500) ]
[ time 467 ] IO_START by JOB 0
IO DONE
[ time 467 ] Run JOB 1 at PRIORITY 0 [ TICKS 1 ALLOT 2 TIME 121 (of 500) ]
[ time 468 ] Run JOB 1 at PRIORITY 0 [ TICKS 0 ALLOT 2 TIME 120 (of 500) ]
[ time 469 ] Run JOB 1 at PRIORITY 0 [ TICKS 9 ALLOT 1 TIME 119 (of 500) ]
[ time 470 ] Run JOB 1 at PRIORITY 0 [ TICKS 8 ALLOT 1 TIME 118 (of 500) ]
[ time 471 ] Run JOB 1 at PRIORITY 0 [ TICKS 7 ALLOT 1 TIME 117 (of 500) ]
[ time 472 ] IO_DONE by JOB 0
[ time 472 ] Run JOB 0 at PRIORITY 1 [ TICKS 9 ALLOT 2 TIME 422 (of 500) ]
[ time 473 ] IO_START by JOB 0
IO DONE
[ time 473 ] Run JOB 1 at PRIORITY 0 [ TICKS 6 ALLOT 1 TIME 116 (of 500) ]
[ time 474 ] Run JOB 1 at PRIORITY 0 [ TICKS 5 ALLOT 1 TIME 115 (of 500) ]
[ time 475 ] Run JOB 1 at PRIORITY 0 [ TICKS 4 ALLOT 1 TIME 114 (of 500) ]
[ time 476 ] Run JOB 1 at PRIORITY 0 [ TICKS 3 ALLOT 1 TIME 113 (of 500) ]
[ time 477 ] Run JOB 1 at PRIORITY 0 [ TICKS 2 ALLOT 1 TIME 112 (of 500) ]
[ time 478 ] IO_DONE by JOB 0
[ time 478 ] Run JOB 0 at PRIORITY 1 [ TICKS 9 ALLOT 2 TIME 421 (of 500) ]
[ time 479 ] IO_START by JOB 0
IO DONE
[ time 479 ] Run JOB 1 at PRIORITY 0 [ TICKS 1 ALLOT 1 TIME 111 (of 500) ]
[ time 480 ] Run JOB 1 at PRIORITY 0 [ TICKS 0 ALLOT 1 TIME 110 (of 500) ]
[ time 481 ] Run JOB 1 at PRIORITY 0 [ TICKS 9 ALLOT 2 TIME 109 (of 500) ]
[ time 482 ] Run JOB 1 at PRIORITY 0 [ TICKS 8 ALLOT 2 TIME 108 (of 500) ]
[ time 483 ] Run JOB 1 at PRIORITY 0 [ TICKS 7 ALLOT 2 TIME 107 (of 500) ]
[ time 484 ] IO_DONE by JOB 0
[ time 484 ] Run JOB 0 at PRIORITY 1 [ TICKS 9 ALLOT 2 TIME 420 (of 500) ]
[ time 485 ] IO_START by JOB 0
IO DONE
[ time 485 ] Run JOB 1 at PRIORITY 0 [ TICKS 6 ALLOT 2 TIME 106 (of 500) ]
[ time 486 ] Run JOB 1 at PRIORITY 0 [ TICKS 5 ALLOT 2 TIME 105 (of 500) ]
[ time 487 ] Run JOB 1 at PRIORITY 0 [ TICKS 4 ALLOT 2 TIME 104 (of 500) ]
[ time 488 ] Run JOB 1 at PRIORITY 0 [ TICKS 3 ALLOT 2 TIME 103 (of 500) ]
[ time 489 ] Run JOB 1 at PRIORITY 0 [ TICKS 2 ALLOT 2 TIME 102 (of 500) ]
[ time 490 ] IO_DONE by JOB 0
[ time 490 ] Run JOB 0 at PRIORITY 1 [ TICKS 9 ALLOT 2 TIME 419 (of 500) ]
[ time 491 ] IO_START by JOB 0
IO DONE
[ time 491 ] Run JOB 1 at PRIORITY 0 [ TICKS 1 ALLOT 2 TIME 101 (of 500) ]
[ time 492 ] Run JOB 1 at PRIORITY 0 [ TICKS 0 ALLOT 2 TIME 100 (of 500) ]
[ time 493 ] IO_START by JOB 1
IO DONE
[ time 493 ] IDLE
[ time 494 ] IDLE
[ time 495 ] IDLE
[ time 496 ] IO_DONE by JOB 0
[ time 496 ] Run JOB 0 at PRIORITY 1 [ TICKS 9 ALLOT 2 TIME 418 (of 500) ]
[ time 497 ] IO_START by JOB 0
IO DONE
[ time 497 ] IDLE
[ time 498 ] IO_DONE by JOB 1
[ time 498 ] Run JOB 1 at PRIORITY 0 [ TICKS 9 ALLOT 1 TIME 99 (of 500) ]
[ time 499 ] Run JOB 1 at PRIORITY 0 [ TICKS 8 ALLOT 1 TIME 98 (of 500) ]
[ time 500 ] Run JOB 1 at PRIORITY 0 [ TICKS 7 ALLOT 1 TIME 97 (of 500) ]
[ time 501 ] Run JOB 1 at PRIORITY 0 [ TICKS 6 ALLOT 1 TIME 96 (of 500) ]
[ time 502 ] IO_DONE by JOB 0
[ time 502 ] Run JOB 0 at PRIORITY 1 [ TICKS 9 ALLOT 2 TIME 417 (of 500) ]
[ time 503 ] IO_START by JOB 0
IO DONE
[ time 503 ] Run JOB 1 at PRIORITY 0 [ TICKS 5 ALLOT 1 TIME 95 (of 500) ]
[ time 504 ] Run JOB 1 at PRIORITY 0 [ TICKS 4 ALLOT 1 TIME 94 (of 500) ]
[ time 505 ] Run JOB 1 at PRIORITY 0 [ TICKS 3 ALLOT 1 TIME 93 (of 500) ]
[ time 506 ] Run JOB 1 at PRIORITY 0 [ TICKS 2 ALLOT 1 TIME 92 (of 500) ]
[ time 507 ] Run JOB 1 at PRIORITY 0 [ TICKS 1 ALLOT 1 TIME 91 (of 500) ]
[ time 508 ] IO_DONE by JOB 0
[ time 508 ] Run JOB 0 at PRIORITY 1 [ TICKS 9 ALLOT 2 TIME 416 (of 500) ]
[ time 509 ] IO_START by JOB 0
IO DONE
[ time 509 ] Run JOB 1 at PRIORITY 0 [ TICKS 0 ALLOT 1 TIME 90 (of 500) ]
[ time 510 ] Run JOB 1 at PRIORITY 0 [ TICKS 9 ALLOT 2 TIME 89 (of 500) ]
[ time 511 ] Run JOB 1 at PRIORITY 0 [ TICKS 8 ALLOT 2 TIME 88 (of 500) ]
[ time 512 ] Run JOB 1 at PRIORITY 0 [ TICKS 7 ALLOT 2 TIME 87 (of 500) ]
[ time 513 ] Run JOB 1 at PRIORITY 0 [ TICKS 6 ALLOT 2 TIME 86 (of 500) ]
[ time 514 ] IO_DONE by JOB 0
[ time 514 ] Run JOB 0 at PRIORITY 1 [ TICKS 9 ALLOT 2 TIME 415 (of 500) ]
[ time 515 ] IO_START by JOB 0
IO DONE
[ time 515 ] Run JOB 1 at PRIORITY 0 [ TICKS 5 ALLOT 2 TIME 85 (of 500) ]
[ time 516 ] Run JOB 1 at PRIORITY 0 [ TICKS 4 ALLOT 2 TIME 84 (of 500) ]
[ time 517 ] Run JOB 1 at PRIORITY 0 [ TICKS 3 ALLOT 2 TIME 83 (of 500) ]
[ time 518 ] Run JOB 1 at PRIORITY 0 [ TICKS 2 ALLOT 2 TIME 82 (of 500) ]
[ time 519 ] Run JOB 1 at PRIORITY 0 [ TICKS 1 ALLOT 2 TIME 81 (of 500) ]
[ time 520 ] IO_DONE by JOB 0
[ time 520 ] Run JOB 0 at PRIORITY 1 [ TICKS 9 ALLOT 2 TIME 414 (of 500) ]
[ time 521 ] IO_START by JOB 0
IO DONE
[ time 521 ] Run JOB 1 at PRIORITY 0 [ TICKS 0 ALLOT 2 TIME 80 (of 500) ]
[ time 522 ] Run JOB 1 at PRIORITY 0 [ TICKS 9 ALLOT 1 TIME 79 (of 500) ]
[ time 523 ] Run JOB 1 at PRIORITY 0 [ TICKS 8 ALLOT 1 TIME 78 (of 500) ]
[ time 524 ] Run JOB 1 at PRIORITY 0 [ TICKS 7 ALLOT 1 TIME 77 (of 500) ]
[ time 525 ] Run JOB 1 at PRIORITY 0 [ TICKS 6 ALLOT 1 TIME 76 (of 500) ]
[ time 526 ] IO_DONE by JOB 0
[ time 526 ] Run JOB 0 at PRIORITY 1 [ TICKS 9 ALLOT 2 TIME 413 (of 500) ]
[ time 527 ] IO_START by JOB 0
IO DONE
[ time 527 ] Run JOB 1 at PRIORITY 0 [ TICKS 5 ALLOT 1 TIME 75 (of 500) ]
[ time 528 ] Run JOB 1 at PRIORITY 0 [ TICKS 4 ALLOT 1 TIME 74 (of 500) ]
[ time 529 ] Run JOB 1 at PRIORITY 0 [ TICKS 3 ALLOT 1 TIME 73 (of 500) ]
[ time 530 ] Run JOB 1 at PRIORITY 0 [ TICKS 2 ALLOT 1 TIME 72 (of 500) ]
[ time 531 ] Run JOB 1 at PRIORITY 0 [ TICKS 1 ALLOT 1 TIME 71 (of 500) ]
[ time 532 ] IO_DONE by JOB 0
[ time 532 ] Run JOB 0 at PRIORITY 1 [ TICKS 9 ALLOT 2 TIME 412 (of 500) ]
[ time 533 ] IO_START by JOB 0
IO DONE
[ time 533 ] Run JOB 1 at PRIORITY 0 [ TICKS 0 ALLOT 1 TIME 70 (of 500) ]
[ time 534 ] Run JOB 1 at PRIORITY 0 [ TICKS 9 ALLOT 2 TIME 69 (of 500) ]
[ time 535 ] Run JOB 1 at PRIORITY 0 [ TICKS 8 ALLOT 2 TIME 68 (of 500) ]
[ time 536 ] Run JOB 1 at PRIORITY 0 [ TICKS 7 ALLOT 2 TIME 67 (of 500) ]
[ time 537 ] Run JOB 1 at PRIORITY 0 [ TICKS 6 ALLOT 2 TIME 66 (of 500) ]
[ time 538 ] IO_DONE by JOB 0
[ time 538 ] Run JOB 0 at PRIORITY 1 [ TICKS 9 ALLOT 2 TIME 411 (of 500) ]
[ time 539 ] IO_START by JOB 0
IO DONE
[ time 539 ] Run JOB 1 at PRIORITY 0 [ TICKS 5 ALLOT 2 TIME 65 (of 500) ]
[ time 540 ] Run JOB 1 at PRIORITY 0 [ TICKS 4 ALLOT 2 TIME 64 (of 500) ]
[ time 541 ] Run JOB 1 at PRIORITY 0 [ TICKS 3 ALLOT 2 TIME 63 (of 500) ]
[ time 542 ] Run JOB 1 at PRIORITY 0 [ TICKS 2 ALLOT 2 TIME 62 (of 500) ]
[ time 543 ] Run JOB 1 at PRIORITY 0 [ TICKS 1 ALLOT 2 TIME 61 (of 500) ]
[ time 544 ] IO_DONE by JOB 0
[ time 544 ] Run JOB 0 at PRIORITY 1 [ TICKS 9 ALLOT 2 TIME 410 (of 500) ]
[ time 545 ] IO_START by JOB 0
IO DONE
[ time 545 ] Run JOB 1 at PRIORITY 0 [ TICKS 0 ALLOT 2 TIME 60 (of 500) ]
[ time 546 ] Run JOB 1 at PRIORITY 0 [ TICKS 9 ALLOT 1 TIME 59 (of 500) ]
[ time 547 ] Run JOB 1 at PRIORITY 0 [ TICKS 8 ALLOT 1 TIME 58 (of 500) ]
[ time 548 ] Run JOB 1 at PRIORITY 0 [ TICKS 7 ALLOT 1 TIME 57 (of 500) ]
[ time 549 ] Run JOB 1 at PRIORITY 0 [ TICKS 6 ALLOT 1 TIME 56 (of 500) ]
[ time 550 ] IO_DONE by JOB 0
[ time 550 ] Run JOB 0 at PRIORITY 1 [ TICKS 9 ALLOT 2 TIME 409 (of 500) ]
[ time 551 ] IO_START by JOB 0
IO DONE
[ time 551 ] Run JOB 1 at PRIORITY 0 [ TICKS 5 ALLOT 1 TIME 55 (of 500) ]
[ time 552 ] Run JOB 1 at PRIORITY 0 [ TICKS 4 ALLOT 1 TIME 54 (of 500) ]
[ time 553 ] Run JOB 1 at PRIORITY 0 [ TICKS 3 ALLOT 1 TIME 53 (of 500) ]
[ time 554 ] Run JOB 1 at PRIORITY 0 [ TICKS 2 ALLOT 1 TIME 52 (of 500) ]
[ time 555 ] Run JOB 1 at PRIORITY 0 [ TICKS 1 ALLOT 1 TIME 51 (of 500) ]
[ time 556 ] IO_DONE by JOB 0
[ time 556 ] Run JOB 0 at PRIORITY 1 [ TICKS 9 ALLOT 2 TIME 408 (of 500) ]
[ time 557 ] IO_START by JOB 0
IO DONE
[ time 557 ] Run JOB 1 at PRIORITY 0 [ TICKS 0 ALLOT 1 TIME 50 (of 500) ]
[ time 558 ] Run JOB 1 at PRIORITY 0 [ TICKS 9 ALLOT 2 TIME 49 (of 500) ]
[ time 559 ] Run JOB 1 at PRIORITY 0 [ TICKS 8 ALLOT 2 TIME 48 (of 500) ]
[ time 560 ] Run JOB 1 at PRIORITY 0 [ TICKS 7 ALLOT 2 TIME 47 (of 500) ]
[ time 561 ] Run JOB 1 at PRIORITY 0 [ TICKS 6 ALLOT 2 TIME 46 (of 500) ]
[ time 562 ] IO_DONE by JOB 0
[ time 562 ] Run JOB 0 at PRIORITY 1 [ TICKS 9 ALLOT 2 TIME 407 (of 500) ]
[ time 563 ] IO_START by JOB 0
IO DONE
[ time 563 ] Run JOB 1 at PRIORITY 0 [ TICKS 5 ALLOT 2 TIME 45 (of 500) ]
[ time 564 ] Run JOB 1 at PRIORITY 0 [ TICKS 4 ALLOT 2 TIME 44 (of 500) ]
[ time 565 ] Run JOB 1 at PRIORITY 0 [ TICKS 3 ALLOT 2 TIME 43 (of 500) ]
[ time 566 ] Run JOB 1 at PRIORITY 0 [ TICKS 2 ALLOT 2 TIME 42 (of 500) ]
[ time 567 ] Run JOB 1 at PRIORITY 0 [ TICKS 1 ALLOT 2 TIME 41 (of 500) ]
[ time 568 ] IO_DONE by JOB 0
[ time 568 ] Run JOB 0 at PRIORITY 1 [ TICKS 9 ALLOT 2 TIME 406 (of 500) ]
[ time 569 ] IO_START by JOB 0
IO DONE
[ time 569 ] Run JOB 1 at PRIORITY 0 [ TICKS 0 ALLOT 2 TIME 40 (of 500) ]
[ time 570 ] Run JOB 1 at PRIORITY 0 [ TICKS 9 ALLOT 1 TIME 39 (of 500) ]
[ time 571 ] Run JOB 1 at PRIORITY 0 [ TICKS 8 ALLOT 1 TIME 38 (of 500) ]
[ time 572 ] Run JOB 1 at PRIORITY 0 [ TICKS 7 ALLOT 1 TIME 37 (of 500) ]
[ time 573 ] Run JOB 1 at PRIORITY 0 [ TICKS 6 ALLOT 1 TIME 36 (of 500) ]
[ time 574 ] IO_DONE by JOB 0
[ time 574 ] Run JOB 0 at PRIORITY 1 [ TICKS 9 ALLOT 2 TIME 405 (of 500) ]
[ time 575 ] IO_START by JOB 0
IO DONE
[ time 575 ] Run JOB 1 at PRIORITY 0 [ TICKS 5 ALLOT 1 TIME 35 (of 500) ]
[ time 576 ] Run JOB 1 at PRIORITY 0 [ TICKS 4 ALLOT 1 TIME 34 (of 500) ]
[ time 577 ] Run JOB 1 at PRIORITY 0 [ TICKS 3 ALLOT 1 TIME 33 (of 500) ]
[ time 578 ] Run JOB 1 at PRIORITY 0 [ TICKS 2 ALLOT 1 TIME 32 (of 500) ]
[ time 579 ] Run JOB 1 at PRIORITY 0 [ TICKS 1 ALLOT 1 TIME 31 (of 500) ]
[ time 580 ] IO_DONE by JOB 0
[ time 580 ] Run JOB 0 at PRIORITY 1 [ TICKS 9 ALLOT 2 TIME 404 (of 500) ]
[ time 581 ] IO_START by JOB 0
IO DONE
[ time 581 ] Run JOB 1 at PRIORITY 0 [ TICKS 0 ALLOT 1 TIME 30 (of 500) ]
[ time 582 ] Run JOB 1 at PRIORITY 0 [ TICKS 9 ALLOT 2 TIME 29 (of 500) ]
[ time 583 ] Run JOB 1 at PRIORITY 0 [ TICKS 8 ALLOT 2 TIME 28 (of 500) ]
[ time 584 ] Run JOB 1 at PRIORITY 0 [ TICKS 7 ALLOT 2 TIME 27 (of 500) ]
[ time 585 ] Run JOB 1 at PRIORITY 0 [ TICKS 6 ALLOT 2 TIME 26 (of 500) ]
[ time 586 ] IO_DONE by JOB 0
[ time 586 ] Run JOB 0 at PRIORITY 1 [ TICKS 9 ALLOT 2 TIME 403 (of 500) ]
[ time 587 ] IO_START by JOB 0
IO DONE
[ time 587 ] Run JOB 1 at PRIORITY 0 [ TICKS 5 ALLOT 2 TIME 25 (of 500) ]
[ time 588 ] Run JOB 1 at PRIORITY 0 [ TICKS 4 ALLOT 2 TIME 24 (of 500) ]
[ time 589 ] Run JOB 1 at PRIORITY 0 [ TICKS 3 ALLOT 2 TIME 23 (of 500) ]
[ time 590 ] Run JOB 1 at PRIORITY 0 [ TICKS 2 ALLOT 2 TIME 22 (of 500) ]
[ time 591 ] Run JOB 1 at PRIORITY 0 [ TICKS 1 ALLOT 2 TIME 21 (of 500) ]
[ time 592 ] IO_DONE by JOB 0
[ time 592 ] Run JOB 0 at PRIORITY 1 [ TICKS 9 ALLOT 2 TIME 402 (of 500) ]
[ time 593 ] IO_START by JOB 0
IO DONE
[ time 593 ] Run JOB 1 at PRIORITY 0 [ TICKS 0 ALLOT 2 TIME 20 (of 500) ]
[ time 594 ] Run JOB 1 at PRIORITY 0 [ TICKS 9 ALLOT 1 TIME 19 (of 500) ]
[ time 595 ] Run JOB 1 at PRIORITY 0 [ TICKS 8 ALLOT 1 TIME 18 (of 500) ]
[ time 596 ] Run JOB 1 at PRIORITY 0 [ TICKS 7 ALLOT 1 TIME 17 (of 500) ]
[ time 597 ] Run JOB 1 at PRIORITY 0 [ TICKS 6 ALLOT 1 TIME 16 (of 500) ]
[ time 598 ] IO_DONE by JOB 0
[ time 598 ] Run JOB 0 at PRIORITY 1 [ TICKS 9 ALLOT 2 TIME 401 (of 500) ]
[ time 599 ] IO_START by JOB 0
IO DONE
[ time 599 ] Run JOB 1 at PRIORITY 0 [ TICKS 5 ALLOT 1 TIME 15 (of 500) ]
[ time 600 ] Run JOB 1 at PRIORITY 0 [ TICKS 4 ALLOT 1 TIME 14 (of 500) ]
[ time 601 ] Run JOB 1 at PRIORITY 0 [ TICKS 3 ALLOT 1 TIME 13 (of 500) ]
[ time 602 ] Run JOB 1 at PRIORITY 0 [ TICKS 2 ALLOT 1 TIME 12 (of 500) ]
[ time 603 ] Run JOB 1 at PRIORITY 0 [ TICKS 1 ALLOT 1 TIME 11 (of 500) ]
[ time 604 ] IO_DONE by JOB 0
[ time 604 ] Run JOB 0 at PRIORITY 1 [ TICKS 9 ALLOT 2 TIME 400 (of 500) ]
[ time 605 ] IO_START by JOB 0
IO DONE
[ time 605 ] Run JOB 1 at PRIORITY 0 [ TICKS 0 ALLOT 1 TIME 10 (of 500) ]
[ time 606 ] Run JOB 1 at PRIORITY 0 [ TICKS 9 ALLOT 2 TIME 9 (of 500) ]
[ time 607 ] Run JOB 1 at PRIORITY 0 [ TICKS 8 ALLOT 2 TIME 8 (of 500) ]
[ time 608 ] Run JOB 1 at PRIORITY 0 [ TICKS 7 ALLOT 2 TIME 7 (of 500) ]
[ time 609 ] Run JOB 1 at PRIORITY 0 [ TICKS 6 ALLOT 2 TIME 6 (of 500) ]
[ time 610 ] IO_DONE by JOB 0
[ time 610 ] Run JOB 0 at PRIORITY 1 [ TICKS 9 ALLOT 2 TIME 399 (of 500) ]
[ time 611 ] IO_START by JOB 0
IO DONE
[ time 611 ] Run JOB 1 at PRIORITY 0 [ TICKS 5 ALLOT 2 TIME 5 (of 500) ]
[ time 612 ] Run JOB 1 at PRIORITY 0 [ TICKS 4 ALLOT 2 TIME 4 (of 500) ]
[ time 613 ] Run JOB 1 at PRIORITY 0 [ TICKS 3 ALLOT 2 TIME 3 (of 500) ]
[ time 614 ] Run JOB 1 at PRIORITY 0 [ TICKS 2 ALLOT 2 TIME 2 (of 500) ]
[ time 615 ] Run JOB 1 at PRIORITY 0 [ TICKS 1 ALLOT 2 TIME 1 (of 500) ]
[ time 616 ] IO_DONE by JOB 0
[ time 616 ] Run JOB 0 at PRIORITY 1 [ TICKS 9 ALLOT 2 TIME 398 (of 500) ]
[ time 617 ] IO_START by JOB 0
IO DONE
[ time 617 ] Run JOB 1 at PRIORITY 0 [ TICKS 0 ALLOT 2 TIME 0 (of 500) ]
[ time 618 ] FINISHED JOB 1
[ time 618 ] IDLE
[ time 619 ] IDLE
[ time 620 ] IDLE
[ time 621 ] IDLE
[ time 622 ] IO_DONE by JOB 0
[ time 622 ] Run JOB 0 at PRIORITY 1 [ TICKS 9 ALLOT 2 TIME 397 (of 500) ]
[ time 623 ] IO_START by JOB 0
IO DONE
[ time 623 ] IDLE
[ time 624 ] IDLE
[ time 625 ] IDLE
[ time 626 ] IDLE
[ time 627 ] IDLE
[ time 628 ] IO_DONE by JOB 0
[ time 628 ] Run JOB 0 at PRIORITY 1 [ TICKS 9 ALLOT 2 TIME 396 (of 500) ]
[ time 629 ] IO_START by JOB 0
IO DONE
[ time 629 ] IDLE
[ time 630 ] IDLE
[ time 631 ] IDLE
[ time 632 ] IDLE
[ time 633 ] IDLE
[ time 634 ] IO_DONE by JOB 0
[ time 634 ] Run JOB 0 at PRIORITY 1 [ TICKS 9 ALLOT 2 TIME 395 (of 500) ]
[ time 635 ] IO_START by JOB 0
IO DONE
[ time 635 ] IDLE
[ time 636 ] IDLE
[ time 637 ] IDLE
[ time 638 ] IDLE
[ time 639 ] IDLE
[ time 640 ] IO_DONE by JOB 0
[ time 640 ] Run JOB 0 at PRIORITY 1 [ TICKS 9 ALLOT 2 TIME 394 (of 500) ]
[ time 641 ] IO_START by JOB 0
IO DONE
[ time 641 ] IDLE
[ time 642 ] IDLE
[ time 643 ] IDLE
[ time 644 ] IDLE
[ time 645 ] IDLE
[ time 646 ] IO_DONE by JOB 0
[ time 646 ] Run JOB 0 at PRIORITY 1 [ TICKS 9 ALLOT 2 TIME 393 (of 500) ]
[ time 647 ] IO_START by JOB 0
IO DONE
[ time 647 ] IDLE
[ time 648 ] IDLE
[ time 649 ] IDLE
[ time 650 ] IDLE
[ time 651 ] IDLE
[ time 652 ] IO_DONE by JOB 0
[ time 652 ] Run JOB 0 at PRIORITY 1 [ TICKS 9 ALLOT 2 TIME 392 (of 500) ]
[ time 653 ] IO_START by JOB 0
IO DONE
[ time 653 ] IDLE
[ time 654 ] IDLE
[ time 655 ] IDLE
[ time 656 ] IDLE
[ time 657 ] IDLE
[ time 658 ] IO_DONE by JOB 0
[ time 658 ] Run JOB 0 at PRIORITY 1 [ TICKS 9 ALLOT 2 TIME 391 (of 500) ]
[ time 659 ] IO_START by JOB 0
IO DONE
[ time 659 ] IDLE
[ time 660 ] IDLE
[ time 661 ] IDLE
[ time 662 ] IDLE
[ time 663 ] IDLE
[ time 664 ] IO_DONE by JOB 0
[ time 664 ] Run JOB 0 at PRIORITY 1 [ TICKS 9 ALLOT 2 TIME 390 (of 500) ]
[ time 665 ] IO_START by JOB 0
IO DONE
[ time 665 ] IDLE
[ time 666 ] IDLE
[ time 667 ] IDLE
[ time 668 ] IDLE
[ time 669 ] IDLE
[ time 670 ] IO_DONE by JOB 0
[ time 670 ] Run JOB 0 at PRIORITY 1 [ TICKS 9 ALLOT 2 TIME 389 (of 500) ]
[ time 671 ] IO_START by JOB 0
IO DONE
[ time 671 ] IDLE
[ time 672 ] IDLE
[ time 673 ] IDLE
[ time 674 ] IDLE
[ time 675 ] IDLE
[ time 676 ] IO_DONE by JOB 0
[ time 676 ] Run JOB 0 at PRIORITY 1 [ TICKS 9 ALLOT 2 TIME 388 (of 500) ]
[ time 677 ] IO_START by JOB 0
IO DONE
[ time 677 ] IDLE
[ time 678 ] IDLE
[ time 679 ] IDLE
[ time 680 ] IDLE
[ time 681 ] IDLE
[ time 682 ] IO_DONE by JOB 0
[ time 682 ] Run JOB 0 at PRIORITY 1 [ TICKS 9 ALLOT 2 TIME 387 (of 500) ]
[ time 683 ] IO_START by JOB 0
IO DONE
[ time 683 ] IDLE
[ time 684 ] IDLE
[ time 685 ] IDLE
[ time 686 ] IDLE
[ time 687 ] IDLE
[ time 688 ] IO_DONE by JOB 0
[ time 688 ] Run JOB 0 at PRIORITY 1 [ TICKS 9 ALLOT 2 TIME 386 (of 500) ]
[ time 689 ] IO_START by JOB 0
IO DONE
[ time 689 ] IDLE
[ time 690 ] IDLE
[ time 691 ] IDLE
[ time 692 ] IDLE
[ time 693 ] IDLE
[ time 694 ] IO_DONE by JOB 0
[ time 694 ] Run JOB 0 at PRIORITY 1 [ TICKS 9 ALLOT 2 TIME 385 (of 500) ]
[ time 695 ] IO_START by JOB 0
IO DONE
[ time 695 ] IDLE
[ time 696 ] IDLE
[ time 697 ] IDLE
[ time 698 ] IDLE
[ time 699 ] IDLE
[ time 700 ] IO_DONE by JOB 0
[ time 700 ] Run JOB 0 at PRIORITY 1 [ TICKS 9 ALLOT 2 TIME 384 (of 500) ]
[ time 701 ] IO_START by JOB 0
IO DONE
[ time 701 ] IDLE
[ time 702 ] IDLE
[ time 703 ] IDLE
[ time 704 ] IDLE
[ time 705 ] IDLE
[ time 706 ] IO_DONE by JOB 0
[ time 706 ] Run JOB 0 at PRIORITY 1 [ TICKS 9 ALLOT 2 TIME 383 (of 500) ]
[ time 707 ] IO_START by JOB 0
IO DONE
[ time 707 ] IDLE
[ time 708 ] IDLE
[ time 709 ] IDLE
[ time 710 ] IDLE
[ time 711 ] IDLE
[ time 712 ] IO_DONE by JOB 0
[ time 712 ] Run JOB 0 at PRIORITY 1 [ TICKS 9 ALLOT 2 TIME 382 (of 500) ]
[ time 713 ] IO_START by JOB 0
IO DONE
[ time 713 ] IDLE
[ time 714 ] IDLE
[ time 715 ] IDLE
[ time 716 ] IDLE
[ time 717 ] IDLE
[ time 718 ] IO_DONE by JOB 0
[ time 718 ] Run JOB 0 at PRIORITY 1 [ TICKS 9 ALLOT 2 TIME 381 (of 500) ]
[ time 719 ] IO_START by JOB 0
IO DONE
[ time 719 ] IDLE
[ time 720 ] IDLE
[ time 721 ] IDLE
[ time 722 ] IDLE
[ time 723 ] IDLE
[ time 724 ] IO_DONE by JOB 0
[ time 724 ] Run JOB 0 at PRIORITY 1 [ TICKS 9 ALLOT 2 TIME 380 (of 500) ]
[ time 725 ] IO_START by JOB 0
IO DONE
[ time 725 ] IDLE
[ time 726 ] IDLE
[ time 727 ] IDLE
[ time 728 ] IDLE
[ time 729 ] IDLE
[ time 730 ] IO_DONE by JOB 0
[ time 730 ] Run JOB 0 at PRIORITY 1 [ TICKS 9 ALLOT 2 TIME 379 (of 500) ]
[ time 731 ] IO_START by JOB 0
IO DONE
[ time 731 ] IDLE
[ time 732 ] IDLE
[ time 733 ] IDLE
[ time 734 ] IDLE
[ time 735 ] IDLE
[ time 736 ] IO_DONE by JOB 0
[ time 736 ] Run JOB 0 at PRIORITY 1 [ TICKS 9 ALLOT 2 TIME 378 (of 500) ]
[ time 737 ] IO_START by JOB 0
IO DONE
[ time 737 ] IDLE
[ time 738 ] IDLE
[ time 739 ] IDLE
[ time 740 ] IDLE
[ time 741 ] IDLE
[ time 742 ] IO_DONE by JOB 0
[ time 742 ] Run JOB 0 at PRIORITY 1 [ TICKS 9 ALLOT 2 TIME 377 (of 500) ]
[ time 743 ] IO_START by JOB 0
IO DONE
[ time 743 ] IDLE
[ time 744 ] IDLE
[ time 745 ] IDLE
[ time 746 ] IDLE
[ time 747 ] IDLE
[ time 748 ] IO_DONE by JOB 0
[ time 748 ] Run JOB 0 at PRIORITY 1 [ TICKS 9 ALLOT 2 TIME 376 (of 500) ]
[ time 749 ] IO_START by JOB 0
IO DONE
[ time 749 ] IDLE
[ time 750 ] IDLE
[ time 751 ] IDLE
[ time 752 ] IDLE
[ time 753 ] IDLE
[ time 754 ] IO_DONE by JOB 0
[ time 754 ] Run JOB 0 at PRIORITY 1 [ TICKS 9 ALLOT 2 TIME 375 (of 500) ]
[ time 755 ] IO_START by JOB 0
IO DONE
[ time 755 ] IDLE
[ time 756 ] IDLE
[ time 757 ] IDLE
[ time 758 ] IDLE
[ time 759 ] IDLE
[ time 760 ] IO_DONE by JOB 0
[ time 760 ] Run JOB 0 at PRIORITY 1 [ TICKS 9 ALLOT 2 TIME 374 (of 500) ]
[ time 761 ] IO_START by JOB 0
IO DONE
[ time 761 ] IDLE
[ time 762 ] IDLE
[ time 763 ] IDLE
[ time 764 ] IDLE
[ time 765 ] IDLE
[ time 766 ] IO_DONE by JOB 0
[ time 766 ] Run JOB 0 at PRIORITY 1 [ TICKS 9 ALLOT 2 TIME 373 (of 500) ]
[ time 767 ] IO_START by JOB 0
IO DONE
[ time 767 ] IDLE
[ time 768 ] IDLE
[ time 769 ] IDLE
[ time 770 ] IDLE
[ time 771 ] IDLE
[ time 772 ] IO_DONE by JOB 0
[ time 772 ] Run JOB 0 at PRIORITY 1 [ TICKS 9 ALLOT 2 TIME 372 (of 500) ]
[ time 773 ] IO_START by JOB 0
IO DONE
[ time 773 ] IDLE
[ time 774 ] IDLE
[ time 775 ] IDLE
[ time 776 ] IDLE
[ time 777 ] IDLE
[ time 778 ] IO_DONE by JOB 0
[ time 778 ] Run JOB 0 at PRIORITY 1 [ TICKS 9 ALLOT 2 TIME 371 (of 500) ]
[ time 779 ] IO_START by JOB 0
IO DONE
[ time 779 ] IDLE
[ time 780 ] IDLE
[ time 781 ] IDLE
[ time 782 ] IDLE
[ time 783 ] IDLE
[ time 784 ] IO_DONE by JOB 0
[ time 784 ] Run JOB 0 at PRIORITY 1 [ TICKS 9 ALLOT 2 TIME 370 (of 500) ]
[ time 785 ] IO_START by JOB 0
IO DONE
[ time 785 ] IDLE
[ time 786 ] IDLE
[ time 787 ] IDLE
[ time 788 ] IDLE
[ time 789 ] IDLE
[ time 790 ] IO_DONE by JOB 0
[ time 790 ] Run JOB 0 at PRIORITY 1 [ TICKS 9 ALLOT 2 TIME 369 (of 500) ]
[ time 791 ] IO_START by JOB 0
IO DONE
[ time 791 ] IDLE
[ time 792 ] IDLE
[ time 793 ] IDLE
[ time 794 ] IDLE
[ time 795 ] IDLE
[ time 796 ] IO_DONE by JOB 0
[ time 796 ] Run JOB 0 at PRIORITY 1 [ TICKS 9 ALLOT 2 TIME 368 (of 500) ]
[ time 797 ] IO_START by JOB 0
IO DONE
[ time 797 ] IDLE
[ time 798 ] IDLE
[ time 799 ] IDLE
[ time 800 ] IDLE
[ time 801 ] IDLE
[ time 802 ] IO_DONE by JOB 0
[ time 802 ] Run JOB 0 at PRIORITY 1 [ TICKS 9 ALLOT 2 TIME 367 (of 500) ]
[ time 803 ] IO_START by JOB 0
IO DONE
[ time 803 ] IDLE
[ time 804 ] IDLE
[ time 805 ] IDLE
[ time 806 ] IDLE
[ time 807 ] IDLE
[ time 808 ] IO_DONE by JOB 0
[ time 808 ] Run JOB 0 at PRIORITY 1 [ TICKS 9 ALLOT 2 TIME 366 (of 500) ]
[ time 809 ] IO_START by JOB 0
IO DONE
[ time 809 ] IDLE
[ time 810 ] IDLE
[ time 811 ] IDLE
[ time 812 ] IDLE
[ time 813 ] IDLE
[ time 814 ] IO_DONE by JOB 0
[ time 814 ] Run JOB 0 at PRIORITY 1 [ TICKS 9 ALLOT 2 TIME 365 (of 500) ]
[ time 815 ] IO_START by JOB 0
IO DONE
[ time 815 ] IDLE
[ time 816 ] IDLE
[ time 817 ] IDLE
[ time 818 ] IDLE
[ time 819 ] IDLE
[ time 820 ] IO_DONE by JOB 0
[ time 820 ] Run JOB 0 at PRIORITY 1 [ TICKS 9 ALLOT 2 TIME 364 (of 500) ]
[ time 821 ] IO_START by JOB 0
IO DONE
[ time 821 ] IDLE
[ time 822 ] IDLE
[ time 823 ] IDLE
[ time 824 ] IDLE
[ time 825 ] IDLE
[ time 826 ] IO_DONE by JOB 0
[ time 826 ] Run JOB 0 at PRIORITY 1 [ TICKS 9 ALLOT 2 TIME 363 (of 500) ]
[ time 827 ] IO_START by JOB 0
IO DONE
[ time 827 ] IDLE
[ time 828 ] IDLE
[ time 829 ] IDLE
[ time 830 ] IDLE
[ time 831 ] IDLE
[ time 832 ] IO_DONE by JOB 0
[ time 832 ] Run JOB 0 at PRIORITY 1 [ TICKS 9 ALLOT 2 TIME 362 (of 500) ]
[ time 833 ] IO_START by JOB 0
IO DONE
[ time 833 ] IDLE
[ time 834 ] IDLE
[ time 835 ] IDLE
[ time 836 ] IDLE
[ time 837 ] IDLE
[ time 838 ] IO_DONE by JOB 0
[ time 838 ] Run JOB 0 at PRIORITY 1 [ TICKS 9 ALLOT 2 TIME 361 (of 500) ]
[ time 839 ] IO_START by JOB 0
IO DONE
[ time 839 ] IDLE
[ time 840 ] IDLE
[ time 841 ] IDLE
[ time 842 ] IDLE
[ time 843 ] IDLE
[ time 844 ] IO_DONE by JOB 0
[ time 844 ] Run JOB 0 at PRIORITY 1 [ TICKS 9 ALLOT 2 TIME 360 (of 500) ]
[ time 845 ] IO_START by JOB 0
IO DONE
[ time 845 ] IDLE
[ time 846 ] IDLE
[ time 847 ] IDLE
[ time 848 ] IDLE
[ time 849 ] IDLE
[ time 850 ] IO_DONE by JOB 0
[ time 850 ] Run JOB 0 at PRIORITY 1 [ TICKS 9 ALLOT 2 TIME 359 (of 500) ]
[ time 851 ] IO_START by JOB 0
IO DONE
[ time 851 ] IDLE
[ time 852 ] IDLE
[ time 853 ] IDLE
[ time 854 ] IDLE
[ time 855 ] IDLE
[ time 856 ] IO_DONE by JOB 0
[ time 856 ] Run JOB 0 at PRIORITY 1 [ TICKS 9 ALLOT 2 TIME 358 (of 500) ]
[ time 857 ] IO_START by JOB 0
IO DONE
[ time 857 ] IDLE
[ time 858 ] IDLE
[ time 859 ] IDLE
[ time 860 ] IDLE
[ time 861 ] IDLE
[ time 862 ] IO_DONE by JOB 0
[ time 862 ] Run JOB 0 at PRIORITY 1 [ TICKS 9 ALLOT 2 TIME 357 (of 500) ]
[ time 863 ] IO_START by JOB 0
IO DONE
[ time 863 ] IDLE
[ time 864 ] IDLE
[ time 865 ] IDLE
[ time 866 ] IDLE
[ time 867 ] IDLE
[ time 868 ] IO_DONE by JOB 0
[ time 868 ] Run JOB 0 at PRIORITY 1 [ TICKS 9 ALLOT 2 TIME 356 (of 500) ]
[ time 869 ] IO_START by JOB 0
IO DONE
[ time 869 ] IDLE
[ time 870 ] IDLE
[ time 871 ] IDLE
[ time 872 ] IDLE
[ time 873 ] IDLE
[ time 874 ] IO_DONE by JOB 0
[ time 874 ] Run JOB 0 at PRIORITY 1 [ TICKS 9 ALLOT 2 TIME 355 (of 500) ]
[ time 875 ] IO_START by JOB 0
IO DONE
[ time 875 ] IDLE
[ time 876 ] IDLE
[ time 877 ] IDLE
[ time 878 ] IDLE
[ time 879 ] IDLE
[ time 880 ] IO_DONE by JOB 0
[ time 880 ] Run JOB 0 at PRIORITY 1 [ TICKS 9 ALLOT 2 TIME 354 (of 500) ]
[ time 881 ] IO_START by JOB 0
IO DONE
[ time 881 ] IDLE
[ time 882 ] IDLE
[ time 883 ] IDLE
[ time 884 ] IDLE
[ time 885 ] IDLE
[ time 886 ] IO_DONE by JOB 0
[ time 886 ] Run JOB 0 at PRIORITY 1 [ TICKS 9 ALLOT 2 TIME 353 (of 500) ]
[ time 887 ] IO_START by JOB 0
IO DONE
[ time 887 ] IDLE
[ time 888 ] IDLE
[ time 889 ] IDLE
[ time 890 ] IDLE
[ time 891 ] IDLE
[ time 892 ] IO_DONE by JOB 0
[ time 892 ] Run JOB 0 at PRIORITY 1 [ TICKS 9 ALLOT 2 TIME 352 (of 500) ]
[ time 893 ] IO_START by JOB 0
IO DONE
[ time 893 ] IDLE
[ time 894 ] IDLE
[ time 895 ] IDLE
[ time 896 ] IDLE
[ time 897 ] IDLE
[ time 898 ] IO_DONE by JOB 0
[ time 898 ] Run JOB 0 at PRIORITY 1 [ TICKS 9 ALLOT 2 TIME 351 (of 500) ]
[ time 899 ] IO_START by JOB 0
IO DONE
[ time 899 ] IDLE
[ time 900 ] IDLE
[ time 901 ] IDLE
[ time 902 ] IDLE
[ time 903 ] IDLE
[ time 904 ] IO_DONE by JOB 0
[ time 904 ] Run JOB 0 at PRIORITY 1 [ TICKS 9 ALLOT 2 TIME 350 (of 500) ]
[ time 905 ] IO_START by JOB 0
IO DONE
[ time 905 ] IDLE
[ time 906 ] IDLE
[ time 907 ] IDLE
[ time 908 ] IDLE
[ time 909 ] IDLE
[ time 910 ] IO_DONE by JOB 0
[ time 910 ] Run JOB 0 at PRIORITY 1 [ TICKS 9 ALLOT 2 TIME 349 (of 500) ]
[ time 911 ] IO_START by JOB 0
IO DONE
[ time 911 ] IDLE
[ time 912 ] IDLE
[ time 913 ] IDLE
[ time 914 ] IDLE
[ time 915 ] IDLE
[ time 916 ] IO_DONE by JOB 0
[ time 916 ] Run JOB 0 at PRIORITY 1 [ TICKS 9 ALLOT 2 TIME 348 (of 500) ]
[ time 917 ] IO_START by JOB 0
IO DONE
[ time 917 ] IDLE
[ time 918 ] IDLE
[ time 919 ] IDLE
[ time 920 ] IDLE
[ time 921 ] IDLE
[ time 922 ] IO_DONE by JOB 0
[ time 922 ] Run JOB 0 at PRIORITY 1 [ TICKS 9 ALLOT 2 TIME 347 (of 500) ]
[ time 923 ] IO_START by JOB 0
IO DONE
[ time 923 ] IDLE
[ time 924 ] IDLE
[ time 925 ] IDLE
[ time 926 ] IDLE
[ time 927 ] IDLE
[ time 928 ] IO_DONE by JOB 0
[ time 928 ] Run JOB 0 at PRIORITY 1 [ TICKS 9 ALLOT 2 TIME 346 (of 500) ]
[ time 929 ] IO_START by JOB 0
IO DONE
[ time 929 ] IDLE
[ time 930 ] IDLE
[ time 931 ] IDLE
[ time 932 ] IDLE
[ time 933 ] IDLE
[ time 934 ] IO_DONE by JOB 0
[ time 934 ] Run JOB 0 at PRIORITY 1 [ TICKS 9 ALLOT 2 TIME 345 (of 500) ]
[ time 935 ] IO_START by JOB 0
IO DONE
[ time 935 ] IDLE
[ time 936 ] IDLE
[ time 937 ] IDLE
[ time 938 ] IDLE
[ time 939 ] IDLE
[ time 940 ] IO_DONE by JOB 0
[ time 940 ] Run JOB 0 at PRIORITY 1 [ TICKS 9 ALLOT 2 TIME 344 (of 500) ]
[ time 941 ] IO_START by JOB 0
IO DONE
[ time 941 ] IDLE
[ time 942 ] IDLE
[ time 943 ] IDLE
[ time 944 ] IDLE
[ time 945 ] IDLE
[ time 946 ] IO_DONE by JOB 0
[ time 946 ] Run JOB 0 at PRIORITY 1 [ TICKS 9 ALLOT 2 TIME 343 (of 500) ]
[ time 947 ] IO_START by JOB 0
IO DONE
[ time 947 ] IDLE
[ time 948 ] IDLE
[ time 949 ] IDLE
[ time 950 ] IDLE
[ time 951 ] IDLE
[ time 952 ] IO_DONE by JOB 0
[ time 952 ] Run JOB 0 at PRIORITY 1 [ TICKS 9 ALLOT 2 TIME 342 (of 500) ]
[ time 953 ] IO_START by JOB 0
IO DONE
[ time 953 ] IDLE
[ time 954 ] IDLE
[ time 955 ] IDLE
[ time 956 ] IDLE
[ time 957 ] IDLE
[ time 958 ] IO_DONE by JOB 0
[ time 958 ] Run JOB 0 at PRIORITY 1 [ TICKS 9 ALLOT 2 TIME 341 (of 500) ]
[ time 959 ] IO_START by JOB 0
IO DONE
[ time 959 ] IDLE
[ time 960 ] IDLE
[ time 961 ] IDLE
[ time 962 ] IDLE
[ time 963 ] IDLE
[ time 964 ] IO_DONE by JOB 0
[ time 964 ] Run JOB 0 at PRIORITY 1 [ TICKS 9 ALLOT 2 TIME 340 (of 500) ]
[ time 965 ] IO_START by JOB 0
IO DONE
[ time 965 ] IDLE
[ time 966 ] IDLE
[ time 967 ] IDLE
[ time 968 ] IDLE
[ time 969 ] IDLE
[ time 970 ] IO_DONE by JOB 0
[ time 970 ] Run JOB 0 at PRIORITY 1 [ TICKS 9 ALLOT 2 TIME 339 (of 500) ]
[ time 971 ] IO_START by JOB 0
IO DONE
[ time 971 ] IDLE
[ time 972 ] IDLE
[ time 973 ] IDLE
[ time 974 ] IDLE
[ time 975 ] IDLE
[ time 976 ] IO_DONE by JOB 0
[ time 976 ] Run JOB 0 at PRIORITY 1 [ TICKS 9 ALLOT 2 TIME 338 (of 500) ]
[ time 977 ] IO_START by JOB 0
IO DONE
[ time 977 ] IDLE
[ time 978 ] IDLE
[ time 979 ] IDLE
[ time 980 ] IDLE
[ time 981 ] IDLE
[ time 982 ] IO_DONE by JOB 0
[ time 982 ] Run JOB 0 at PRIORITY 1 [ TICKS 9 ALLOT 2 TIME 337 (of 500) ]
[ time 983 ] IO_START by JOB 0
IO DONE
[ time 983 ] IDLE
[ time 984 ] IDLE
[ time 985 ] IDLE
[ time 986 ] IDLE
[ time 987 ] IDLE
[ time 988 ] IO_DONE by JOB 0
[ time 988 ] Run JOB 0 at PRIORITY 1 [ TICKS 9 ALLOT 2 TIME 336 (of 500) ]
[ time 989 ] IO_START by JOB 0
IO DONE
[ time 989 ] IDLE
[ time 990 ] IDLE
[ time 991 ] IDLE
[ time 992 ] IDLE
[ time 993 ] IDLE
[ time 994 ] IO_DONE by JOB 0
[ time 994 ] Run JOB 0 at PRIORITY 1 [ TICKS 9 ALLOT 2 TIME 335 (of 500) ]
[ time 995 ] IO_START by JOB 0
IO DONE
[ time 995 ] IDLE
[ time 996 ] IDLE
[ time 997 ] IDLE
[ time 998 ] IDLE
[ time 999 ] IDLE
[ time 1000 ] IO_DONE by JOB 0
[ time 1000 ] Run JOB 0 at PRIORITY 1 [ TICKS 9 ALLOT 2 TIME 334 (of 500) ]
[ time 1001 ] IO_START by JOB 0
IO DONE
[ time 1001 ] IDLE
[ time 1002 ] IDLE
[ time 1003 ] IDLE
[ time 1004 ] IDLE
[ time 1005 ] IDLE
[ time 1006 ] IO_DONE by JOB 0
[ time 1006 ] Run JOB 0 at PRIORITY 1 [ TICKS 9 ALLOT 2 TIME 333 (of 500) ]
[ time 1007 ] IO_START by JOB 0
IO DONE
[ time 1007 ] IDLE
[ time 1008 ] IDLE
[ time 1009 ] IDLE
[ time 1010 ] IDLE
[ time 1011 ] IDLE
[ time 1012 ] IO_DONE by JOB 0
[ time 1012 ] Run JOB 0 at PRIORITY 1 [ TICKS 9 ALLOT 2 TIME 332 (of 500) ]
[ time 1013 ] IO_START by JOB 0
IO DONE
[ time 1013 ] IDLE
[ time 1014 ] IDLE
[ time 1015 ] IDLE
[ time 1016 ] IDLE
[ time 1017 ] IDLE
[ time 1018 ] IO_DONE by JOB 0
[ time 1018 ] Run JOB 0 at PRIORITY 1 [ TICKS 9 ALLOT 2 TIME 331 (of 500) ]
[ time 1019 ] IO_START by JOB 0
IO DONE
[ time 1019 ] IDLE
[ time 1020 ] IDLE
[ time 1021 ] IDLE
[ time 1022 ] IDLE
[ time 1023 ] IDLE
[ time 1024 ] IO_DONE by JOB 0
[ time 1024 ] Run JOB 0 at PRIORITY 1 [ TICKS 9 ALLOT 2 TIME 330 (of 500) ]
[ time 1025 ] IO_START by JOB 0
IO DONE
[ time 1025 ] IDLE
[ time 1026 ] IDLE
[ time 1027 ] IDLE
[ time 1028 ] IDLE
[ time 1029 ] IDLE
[ time 1030 ] IO_DONE by JOB 0
[ time 1030 ] Run JOB 0 at PRIORITY 1 [ TICKS 9 ALLOT 2 TIME 329 (of 500) ]
[ time 1031 ] IO_START by JOB 0
IO DONE
[ time 1031 ] IDLE
[ time 1032 ] IDLE
[ time 1033 ] IDLE
[ time 1034 ] IDLE
[ time 1035 ] IDLE
[ time 1036 ] IO_DONE by JOB 0
[ time 1036 ] Run JOB 0 at PRIORITY 1 [ TICKS 9 ALLOT 2 TIME 328 (of 500) ]
[ time 1037 ] IO_START by JOB 0
IO DONE
[ time 1037 ] IDLE
[ time 1038 ] IDLE
[ time 1039 ] IDLE
[ time 1040 ] IDLE
[ time 1041 ] IDLE
[ time 1042 ] IO_DONE by JOB 0
[ time 1042 ] Run JOB 0 at PRIORITY 1 [ TICKS 9 ALLOT 2 TIME 327 (of 500) ]
[ time 1043 ] IO_START by JOB 0
IO DONE
[ time 1043 ] IDLE
[ time 1044 ] IDLE
[ time 1045 ] IDLE
[ time 1046 ] IDLE
[ time 1047 ] IDLE
[ time 1048 ] IO_DONE by JOB 0
[ time 1048 ] Run JOB 0 at PRIORITY 1 [ TICKS 9 ALLOT 2 TIME 326 (of 500) ]
[ time 1049 ] IO_START by JOB 0
IO DONE
[ time 1049 ] IDLE
[ time 1050 ] IDLE
[ time 1051 ] IDLE
[ time 1052 ] IDLE
[ time 1053 ] IDLE
[ time 1054 ] IO_DONE by JOB 0
[ time 1054 ] Run JOB 0 at PRIORITY 1 [ TICKS 9 ALLOT 2 TIME 325 (of 500) ]
[ time 1055 ] IO_START by JOB 0
IO DONE
[ time 1055 ] IDLE
[ time 1056 ] IDLE
[ time 1057 ] IDLE
[ time 1058 ] IDLE
[ time 1059 ] IDLE
[ time 1060 ] IO_DONE by JOB 0
[ time 1060 ] Run JOB 0 at PRIORITY 1 [ TICKS 9 ALLOT 2 TIME 324 (of 500) ]
[ time 1061 ] IO_START by JOB 0
IO DONE
[ time 1061 ] IDLE
[ time 1062 ] IDLE
[ time 1063 ] IDLE
[ time 1064 ] IDLE
[ time 1065 ] IDLE
[ time 1066 ] IO_DONE by JOB 0
[ time 1066 ] Run JOB 0 at PRIORITY 1 [ TICKS 9 ALLOT 2 TIME 323 (of 500) ]
[ time 1067 ] IO_START by JOB 0
IO DONE
[ time 1067 ] IDLE
[ time 1068 ] IDLE
[ time 1069 ] IDLE
[ time 1070 ] IDLE
[ time 1071 ] IDLE
[ time 1072 ] IO_DONE by JOB 0
[ time 1072 ] Run JOB 0 at PRIORITY 1 [ TICKS 9 ALLOT 2 TIME 322 (of 500) ]
[ time 1073 ] IO_START by JOB 0
IO DONE
[ time 1073 ] IDLE
[ time 1074 ] IDLE
[ time 1075 ] IDLE
[ time 1076 ] IDLE
[ time 1077 ] IDLE
[ time 1078 ] IO_DONE by JOB 0
[ time 1078 ] Run JOB 0 at PRIORITY 1 [ TICKS 9 ALLOT 2 TIME 321 (of 500) ]
[ time 1079 ] IO_START by JOB 0
IO DONE
[ time 1079 ] IDLE
[ time 1080 ] IDLE
[ time 1081 ] IDLE
[ time 1082 ] IDLE
[ time 1083 ] IDLE
[ time 1084 ] IO_DONE by JOB 0
[ time 1084 ] Run JOB 0 at PRIORITY 1 [ TICKS 9 ALLOT 2 TIME 320 (of 500) ]
[ time 1085 ] IO_START by JOB 0
IO DONE
[ time 1085 ] IDLE
[ time 1086 ] IDLE
[ time 1087 ] IDLE
[ time 1088 ] IDLE
[ time 1089 ] IDLE
[ time 1090 ] IO_DONE by JOB 0
[ time 1090 ] Run JOB 0 at PRIORITY 1 [ TICKS 9 ALLOT 2 TIME 319 (of 500) ]
[ time 1091 ] IO_START by JOB 0
IO DONE
[ time 1091 ] IDLE
[ time 1092 ] IDLE
[ time 1093 ] IDLE
[ time 1094 ] IDLE
[ time 1095 ] IDLE
[ time 1096 ] IO_DONE by JOB 0
[ time 1096 ] Run JOB 0 at PRIORITY 1 [ TICKS 9 ALLOT 2 TIME 318 (of 500) ]
[ time 1097 ] IO_START by JOB 0
IO DONE
[ time 1097 ] IDLE
[ time 1098 ] IDLE
[ time 1099 ] IDLE
[ time 1100 ] IDLE
[ time 1101 ] IDLE
[ time 1102 ] IO_DONE by JOB 0
[ time 1102 ] Run JOB 0 at PRIORITY 1 [ TICKS 9 ALLOT 2 TIME 317 (of 500) ]
[ time 1103 ] IO_START by JOB 0
IO DONE
[ time 1103 ] IDLE
[ time 1104 ] IDLE
[ time 1105 ] IDLE
[ time 1106 ] IDLE
[ time 1107 ] IDLE
[ time 1108 ] IO_DONE by JOB 0
[ time 1108 ] Run JOB 0 at PRIORITY 1 [ TICKS 9 ALLOT 2 TIME 316 (of 500) ]
[ time 1109 ] IO_START by JOB 0
IO DONE
[ time 1109 ] IDLE
[ time 1110 ] IDLE
[ time 1111 ] IDLE
[ time 1112 ] IDLE
[ time 1113 ] IDLE
[ time 1114 ] IO_DONE by JOB 0
[ time 1114 ] Run JOB 0 at PRIORITY 1 [ TICKS 9 ALLOT 2 TIME 315 (of 500) ]
[ time 1115 ] IO_START by JOB 0
IO DONE
[ time 1115 ] IDLE
[ time 1116 ] IDLE
[ time 1117 ] IDLE
[ time 1118 ] IDLE
[ time 1119 ] IDLE
[ time 1120 ] IO_DONE by JOB 0
[ time 1120 ] Run JOB 0 at PRIORITY 1 [ TICKS 9 ALLOT 2 TIME 314 (of 500) ]
[ time 1121 ] IO_START by JOB 0
IO DONE
[ time 1121 ] IDLE
[ time 1122 ] IDLE
[ time 1123 ] IDLE
[ time 1124 ] IDLE
[ time 1125 ] IDLE
[ time 1126 ] IO_DONE by JOB 0
[ time 1126 ] Run JOB 0 at PRIORITY 1 [ TICKS 9 ALLOT 2 TIME 313 (of 500) ]
[ time 1127 ] IO_START by JOB 0
IO DONE
[ time 1127 ] IDLE
[ time 1128 ] IDLE
[ time 1129 ] IDLE
[ time 1130 ] IDLE
[ time 1131 ] IDLE
[ time 1132 ] IO_DONE by JOB 0
[ time 1132 ] Run JOB 0 at PRIORITY 1 [ TICKS 9 ALLOT 2 TIME 312 (of 500) ]
[ time 1133 ] IO_START by JOB 0
IO DONE
[ time 1133 ] IDLE
[ time 1134 ] IDLE
[ time 1135 ] IDLE
[ time 1136 ] IDLE
[ time 1137 ] IDLE
[ time 1138 ] IO_DONE by JOB 0
[ time 1138 ] Run JOB 0 at PRIORITY 1 [ TICKS 9 ALLOT 2 TIME 311 (of 500) ]
[ time 1139 ] IO_START by JOB 0
IO DONE
[ time 1139 ] IDLE
[ time 1140 ] IDLE
[ time 1141 ] IDLE
[ time 1142 ] IDLE
[ time 1143 ] IDLE
[ time 1144 ] IO_DONE by JOB 0
[ time 1144 ] Run JOB 0 at PRIORITY 1 [ TICKS 9 ALLOT 2 TIME 310 (of 500) ]
[ time 1145 ] IO_START by JOB 0
IO DONE
[ time 1145 ] IDLE
[ time 1146 ] IDLE
[ time 1147 ] IDLE
[ time 1148 ] IDLE
[ time 1149 ] IDLE
[ time 1150 ] IO_DONE by JOB 0
[ time 1150 ] Run JOB 0 at PRIORITY 1 [ TICKS 9 ALLOT 2 TIME 309 (of 500) ]
[ time 1151 ] IO_START by JOB 0
IO DONE
[ time 1151 ] IDLE
[ time 1152 ] IDLE
[ time 1153 ] IDLE
[ time 1154 ] IDLE
[ time 1155 ] IDLE
[ time 1156 ] IO_DONE by JOB 0
[ time 1156 ] Run JOB 0 at PRIORITY 1 [ TICKS 9 ALLOT 2 TIME 308 (of 500) ]
[ time 1157 ] IO_START by JOB 0
IO DONE
[ time 1157 ] IDLE
[ time 1158 ] IDLE
[ time 1159 ] IDLE
[ time 1160 ] IDLE
[ time 1161 ] IDLE
[ time 1162 ] IO_DONE by JOB 0
[ time 1162 ] Run JOB 0 at PRIORITY 1 [ TICKS 9 ALLOT 2 TIME 307 (of 500) ]
[ time 1163 ] IO_START by JOB 0
IO DONE
[ time 1163 ] IDLE
[ time 1164 ] IDLE
[ time 1165 ] IDLE
[ time 1166 ] IDLE
[ time 1167 ] IDLE
[ time 1168 ] IO_DONE by JOB 0
[ time 1168 ] Run JOB 0 at PRIORITY 1 [ TICKS 9 ALLOT 2 TIME 306 (of 500) ]
[ time 1169 ] IO_START by JOB 0
IO DONE
[ time 1169 ] IDLE
[ time 1170 ] IDLE
[ time 1171 ] IDLE
[ time 1172 ] IDLE
[ time 1173 ] IDLE
[ time 1174 ] IO_DONE by JOB 0
[ time 1174 ] Run JOB 0 at PRIORITY 1 [ TICKS 9 ALLOT 2 TIME 305 (of 500) ]
[ time 1175 ] IO_START by JOB 0
IO DONE
[ time 1175 ] IDLE
[ time 1176 ] IDLE
[ time 1177 ] IDLE
[ time 1178 ] IDLE
[ time 1179 ] IDLE
[ time 1180 ] IO_DONE by JOB 0
[ time 1180 ] Run JOB 0 at PRIORITY 1 [ TICKS 9 ALLOT 2 TIME 304 (of 500) ]
[ time 1181 ] IO_START by JOB 0
IO DONE
[ time 1181 ] IDLE
[ time 1182 ] IDLE
[ time 1183 ] IDLE
[ time 1184 ] IDLE
[ time 1185 ] IDLE
[ time 1186 ] IO_DONE by JOB 0
[ time 1186 ] Run JOB 0 at PRIORITY 1 [ TICKS 9 ALLOT 2 TIME 303 (of 500) ]
[ time 1187 ] IO_START by JOB 0
IO DONE
[ time 1187 ] IDLE
[ time 1188 ] IDLE
[ time 1189 ] IDLE
[ time 1190 ] IDLE
[ time 1191 ] IDLE
[ time 1192 ] IO_DONE by JOB 0
[ time 1192 ] Run JOB 0 at PRIORITY 1 [ TICKS 9 ALLOT 2 TIME 302 (of 500) ]
[ time 1193 ] IO_START by JOB 0
IO DONE
[ time 1193 ] IDLE
[ time 1194 ] IDLE
[ time 1195 ] IDLE
[ time 1196 ] IDLE
[ time 1197 ] IDLE
[ time 1198 ] IO_DONE by JOB 0
[ time 1198 ] Run JOB 0 at PRIORITY 1 [ TICKS 9 ALLOT 2 TIME 301 (of 500) ]
[ time 1199 ] IO_START by JOB 0
IO DONE
[ time 1199 ] IDLE
[ time 1200 ] IDLE
[ time 1201 ] IDLE
[ time 1202 ] IDLE
[ time 1203 ] IDLE
[ time 1204 ] IO_DONE by JOB 0
[ time 1204 ] Run JOB 0 at PRIORITY 1 [ TICKS 9 ALLOT 2 TIME 300 (of 500) ]
[ time 1205 ] IO_START by JOB 0
IO DONE
[ time 1205 ] IDLE
[ time 1206 ] IDLE
[ time 1207 ] IDLE
[ time 1208 ] IDLE
[ time 1209 ] IDLE
[ time 1210 ] IO_DONE by JOB 0
[ time 1210 ] Run JOB 0 at PRIORITY 1 [ TICKS 9 ALLOT 2 TIME 299 (of 500) ]
[ time 1211 ] IO_START by JOB 0
IO DONE
[ time 1211 ] IDLE
[ time 1212 ] IDLE
[ time 1213 ] IDLE
[ time 1214 ] IDLE
[ time 1215 ] IDLE
[ time 1216 ] IO_DONE by JOB 0
[ time 1216 ] Run JOB 0 at PRIORITY 1 [ TICKS 9 ALLOT 2 TIME 298 (of 500) ]
[ time 1217 ] IO_START by JOB 0
IO DONE
[ time 1217 ] IDLE
[ time 1218 ] IDLE
[ time 1219 ] IDLE
[ time 1220 ] IDLE
[ time 1221 ] IDLE
[ time 1222 ] IO_DONE by JOB 0
[ time 1222 ] Run JOB 0 at PRIORITY 1 [ TICKS 9 ALLOT 2 TIME 297 (of 500) ]
[ time 1223 ] IO_START by JOB 0
IO DONE
[ time 1223 ] IDLE
[ time 1224 ] IDLE
[ time 1225 ] IDLE
[ time 1226 ] IDLE
[ time 1227 ] IDLE
[ time 1228 ] IO_DONE by JOB 0
[ time 1228 ] Run JOB 0 at PRIORITY 1 [ TICKS 9 ALLOT 2 TIME 296 (of 500) ]
[ time 1229 ] IO_START by JOB 0
IO DONE
[ time 1229 ] IDLE
[ time 1230 ] IDLE
[ time 1231 ] IDLE
[ time 1232 ] IDLE
[ time 1233 ] IDLE
[ time 1234 ] IO_DONE by JOB 0
[ time 1234 ] Run JOB 0 at PRIORITY 1 [ TICKS 9 ALLOT 2 TIME 295 (of 500) ]
[ time 1235 ] IO_START by JOB 0
IO DONE
[ time 1235 ] IDLE
[ time 1236 ] IDLE
[ time 1237 ] IDLE
[ time 1238 ] IDLE
[ time 1239 ] IDLE
[ time 1240 ] IO_DONE by JOB 0
[ time 1240 ] Run JOB 0 at PRIORITY 1 [ TICKS 9 ALLOT 2 TIME 294 (of 500) ]
[ time 1241 ] IO_START by JOB 0
IO DONE
[ time 1241 ] IDLE
[ time 1242 ] IDLE
[ time 1243 ] IDLE
[ time 1244 ] IDLE
[ time 1245 ] IDLE
[ time 1246 ] IO_DONE by JOB 0
[ time 1246 ] Run JOB 0 at PRIORITY 1 [ TICKS 9 ALLOT 2 TIME 293 (of 500) ]
[ time 1247 ] IO_START by JOB 0
IO DONE
[ time 1247 ] IDLE
[ time 1248 ] IDLE
[ time 1249 ] IDLE
[ time 1250 ] IDLE
[ time 1251 ] IDLE
[ time 1252 ] IO_DONE by JOB 0
[ time 1252 ] Run JOB 0 at PRIORITY 1 [ TICKS 9 ALLOT 2 TIME 292 (of 500) ]
[ time 1253 ] IO_START by JOB 0
IO DONE
[ time 1253 ] IDLE
[ time 1254 ] IDLE
[ time 1255 ] IDLE
[ time 1256 ] IDLE
[ time 1257 ] IDLE
[ time 1258 ] IO_DONE by JOB 0
[ time 1258 ] Run JOB 0 at PRIORITY 1 [ TICKS 9 ALLOT 2 TIME 291 (of 500) ]
[ time 1259 ] IO_START by JOB 0
IO DONE
[ time 1259 ] IDLE
[ time 1260 ] IDLE
[ time 1261 ] IDLE
[ time 1262 ] IDLE
[ time 1263 ] IDLE
[ time 1264 ] IO_DONE by JOB 0
[ time 1264 ] Run JOB 0 at PRIORITY 1 [ TICKS 9 ALLOT 2 TIME 290 (of 500) ]
[ time 1265 ] IO_START by JOB 0
IO DONE
[ time 1265 ] IDLE
[ time 1266 ] IDLE
[ time 1267 ] IDLE
[ time 1268 ] IDLE
[ time 1269 ] IDLE
[ time 1270 ] IO_DONE by JOB 0
[ time 1270 ] Run JOB 0 at PRIORITY 1 [ TICKS 9 ALLOT 2 TIME 289 (of 500) ]
[ time 1271 ] IO_START by JOB 0
IO DONE
[ time 1271 ] IDLE
[ time 1272 ] IDLE
[ time 1273 ] IDLE
[ time 1274 ] IDLE
[ time 1275 ] IDLE
[ time 1276 ] IO_DONE by JOB 0
[ time 1276 ] Run JOB 0 at PRIORITY 1 [ TICKS 9 ALLOT 2 TIME 288 (of 500) ]
[ time 1277 ] IO_START by JOB 0
IO DONE
[ time 1277 ] IDLE
[ time 1278 ] IDLE
[ time 1279 ] IDLE
[ time 1280 ] IDLE
[ time 1281 ] IDLE
[ time 1282 ] IO_DONE by JOB 0
[ time 1282 ] Run JOB 0 at PRIORITY 1 [ TICKS 9 ALLOT 2 TIME 287 (of 500) ]
[ time 1283 ] IO_START by JOB 0
IO DONE
[ time 1283 ] IDLE
[ time 1284 ] IDLE
[ time 1285 ] IDLE
[ time 1286 ] IDLE
[ time 1287 ] IDLE
[ time 1288 ] IO_DONE by JOB 0
[ time 1288 ] Run JOB 0 at PRIORITY 1 [ TICKS 9 ALLOT 2 TIME 286 (of 500) ]
[ time 1289 ] IO_START by JOB 0
IO DONE
[ time 1289 ] IDLE
[ time 1290 ] IDLE
[ time 1291 ] IDLE
[ time 1292 ] IDLE
[ time 1293 ] IDLE
[ time 1294 ] IO_DONE by JOB 0
[ time 1294 ] Run JOB 0 at PRIORITY 1 [ TICKS 9 ALLOT 2 TIME 285 (of 500) ]
[ time 1295 ] IO_START by JOB 0
IO DONE
[ time 1295 ] IDLE
[ time 1296 ] IDLE
[ time 1297 ] IDLE
[ time 1298 ] IDLE
[ time 1299 ] IDLE
[ time 1300 ] IO_DONE by JOB 0
[ time 1300 ] Run JOB 0 at PRIORITY 1 [ TICKS 9 ALLOT 2 TIME 284 (of 500) ]
[ time 1301 ] IO_START by JOB 0
IO DONE
[ time 1301 ] IDLE
[ time 1302 ] IDLE
[ time 1303 ] IDLE
[ time 1304 ] IDLE
[ time 1305 ] IDLE
[ time 1306 ] IO_DONE by JOB 0
[ time 1306 ] Run JOB 0 at PRIORITY 1 [ TICKS 9 ALLOT 2 TIME 283 (of 500) ]
[ time 1307 ] IO_START by JOB 0
IO DONE
[ time 1307 ] IDLE
[ time 1308 ] IDLE
[ time 1309 ] IDLE
[ time 1310 ] IDLE
[ time 1311 ] IDLE
[ time 1312 ] IO_DONE by JOB 0
[ time 1312 ] Run JOB 0 at PRIORITY 1 [ TICKS 9 ALLOT 2 TIME 282 (of 500) ]
[ time 1313 ] IO_START by JOB 0
IO DONE
[ time 1313 ] IDLE
[ time 1314 ] IDLE
[ time 1315 ] IDLE
[ time 1316 ] IDLE
[ time 1317 ] IDLE
[ time 1318 ] IO_DONE by JOB 0
[ time 1318 ] Run JOB 0 at PRIORITY 1 [ TICKS 9 ALLOT 2 TIME 281 (of 500) ]
[ time 1319 ] IO_START by JOB 0
IO DONE
[ time 1319 ] IDLE
[ time 1320 ] IDLE
[ time 1321 ] IDLE
[ time 1322 ] IDLE
[ time 1323 ] IDLE
[ time 1324 ] IO_DONE by JOB 0
[ time 1324 ] Run JOB 0 at PRIORITY 1 [ TICKS 9 ALLOT 2 TIME 280 (of 500) ]
[ time 1325 ] IO_START by JOB 0
IO DONE
[ time 1325 ] IDLE
[ time 1326 ] IDLE
[ time 1327 ] IDLE
[ time 1328 ] IDLE
[ time 1329 ] IDLE
[ time 1330 ] IO_DONE by JOB 0
[ time 1330 ] Run JOB 0 at PRIORITY 1 [ TICKS 9 ALLOT 2 TIME 279 (of 500) ]
[ time 1331 ] IO_START by JOB 0
IO DONE
[ time 1331 ] IDLE
[ time 1332 ] IDLE
[ time 1333 ] IDLE
[ time 1334 ] IDLE
[ time 1335 ] IDLE
[ time 1336 ] IO_DONE by JOB 0
[ time 1336 ] Run JOB 0 at PRIORITY 1 [ TICKS 9 ALLOT 2 TIME 278 (of 500) ]
[ time 1337 ] IO_START by JOB 0
IO DONE
[ time 1337 ] IDLE
[ time 1338 ] IDLE
[ time 1339 ] IDLE
[ time 1340 ] IDLE
[ time 1341 ] IDLE
[ time 1342 ] IO_DONE by JOB 0
[ time 1342 ] Run JOB 0 at PRIORITY 1 [ TICKS 9 ALLOT 2 TIME 277 (of 500) ]
[ time 1343 ] IO_START by JOB 0
IO DONE
[ time 1343 ] IDLE
[ time 1344 ] IDLE
[ time 1345 ] IDLE
[ time 1346 ] IDLE
[ time 1347 ] IDLE
[ time 1348 ] IO_DONE by JOB 0
[ time 1348 ] Run JOB 0 at PRIORITY 1 [ TICKS 9 ALLOT 2 TIME 276 (of 500) ]
[ time 1349 ] IO_START by JOB 0
IO DONE
[ time 1349 ] IDLE
[ time 1350 ] IDLE
[ time 1351 ] IDLE
[ time 1352 ] IDLE
[ time 1353 ] IDLE
[ time 1354 ] IO_DONE by JOB 0
[ time 1354 ] Run JOB 0 at PRIORITY 1 [ TICKS 9 ALLOT 2 TIME 275 (of 500) ]
[ time 1355 ] IO_START by JOB 0
IO DONE
[ time 1355 ] IDLE
[ time 1356 ] IDLE
[ time 1357 ] IDLE
[ time 1358 ] IDLE
[ time 1359 ] IDLE
[ time 1360 ] IO_DONE by JOB 0
[ time 1360 ] Run JOB 0 at PRIORITY 1 [ TICKS 9 ALLOT 2 TIME 274 (of 500) ]
[ time 1361 ] IO_START by JOB 0
IO DONE
[ time 1361 ] IDLE
[ time 1362 ] IDLE
[ time 1363 ] IDLE
[ time 1364 ] IDLE
[ time 1365 ] IDLE
[ time 1366 ] IO_DONE by JOB 0
[ time 1366 ] Run JOB 0 at PRIORITY 1 [ TICKS 9 ALLOT 2 TIME 273 (of 500) ]
[ time 1367 ] IO_START by JOB 0
IO DONE
[ time 1367 ] IDLE
[ time 1368 ] IDLE
[ time 1369 ] IDLE
[ time 1370 ] IDLE
[ time 1371 ] IDLE
[ time 1372 ] IO_DONE by JOB 0
[ time 1372 ] Run JOB 0 at PRIORITY 1 [ TICKS 9 ALLOT 2 TIME 272 (of 500) ]
[ time 1373 ] IO_START by JOB 0
IO DONE
[ time 1373 ] IDLE
[ time 1374 ] IDLE
[ time 1375 ] IDLE
[ time 1376 ] IDLE
[ time 1377 ] IDLE
[ time 1378 ] IO_DONE by JOB 0
[ time 1378 ] Run JOB 0 at PRIORITY 1 [ TICKS 9 ALLOT 2 TIME 271 (of 500) ]
[ time 1379 ] IO_START by JOB 0
IO DONE
[ time 1379 ] IDLE
[ time 1380 ] IDLE
[ time 1381 ] IDLE
[ time 1382 ] IDLE
[ time 1383 ] IDLE
[ time 1384 ] IO_DONE by JOB 0
[ time 1384 ] Run JOB 0 at PRIORITY 1 [ TICKS 9 ALLOT 2 TIME 270 (of 500) ]
[ time 1385 ] IO_START by JOB 0
IO DONE
[ time 1385 ] IDLE
[ time 1386 ] IDLE
[ time 1387 ] IDLE
[ time 1388 ] IDLE
[ time 1389 ] IDLE
[ time 1390 ] IO_DONE by JOB 0
[ time 1390 ] Run JOB 0 at PRIORITY 1 [ TICKS 9 ALLOT 2 TIME 269 (of 500) ]
[ time 1391 ] IO_START by JOB 0
IO DONE
[ time 1391 ] IDLE
[ time 1392 ] IDLE
[ time 1393 ] IDLE
[ time 1394 ] IDLE
[ time 1395 ] IDLE
[ time 1396 ] IO_DONE by JOB 0
[ time 1396 ] Run JOB 0 at PRIORITY 1 [ TICKS 9 ALLOT 2 TIME 268 (of 500) ]
[ time 1397 ] IO_START by JOB 0
IO DONE
[ time 1397 ] IDLE
[ time 1398 ] IDLE
[ time 1399 ] IDLE
[ time 1400 ] IDLE
[ time 1401 ] IDLE
[ time 1402 ] IO_DONE by JOB 0
[ time 1402 ] Run JOB 0 at PRIORITY 1 [ TICKS 9 ALLOT 2 TIME 267 (of 500) ]
[ time 1403 ] IO_START by JOB 0
IO DONE
[ time 1403 ] IDLE
[ time 1404 ] IDLE
[ time 1405 ] IDLE
[ time 1406 ] IDLE
[ time 1407 ] IDLE
[ time 1408 ] IO_DONE by JOB 0
[ time 1408 ] Run JOB 0 at PRIORITY 1 [ TICKS 9 ALLOT 2 TIME 266 (of 500) ]
[ time 1409 ] IO_START by JOB 0
IO DONE
[ time 1409 ] IDLE
[ time 1410 ] IDLE
[ time 1411 ] IDLE
[ time 1412 ] IDLE
[ time 1413 ] IDLE
[ time 1414 ] IO_DONE by JOB 0
[ time 1414 ] Run JOB 0 at PRIORITY 1 [ TICKS 9 ALLOT 2 TIME 265 (of 500) ]
[ time 1415 ] IO_START by JOB 0
IO DONE
[ time 1415 ] IDLE
[ time 1416 ] IDLE
[ time 1417 ] IDLE
[ time 1418 ] IDLE
[ time 1419 ] IDLE
[ time 1420 ] IO_DONE by JOB 0
[ time 1420 ] Run JOB 0 at PRIORITY 1 [ TICKS 9 ALLOT 2 TIME 264 (of 500) ]
[ time 1421 ] IO_START by JOB 0
IO DONE
[ time 1421 ] IDLE
[ time 1422 ] IDLE
[ time 1423 ] IDLE
[ time 1424 ] IDLE
[ time 1425 ] IDLE
[ time 1426 ] IO_DONE by JOB 0
[ time 1426 ] Run JOB 0 at PRIORITY 1 [ TICKS 9 ALLOT 2 TIME 263 (of 500) ]
[ time 1427 ] IO_START by JOB 0
IO DONE
[ time 1427 ] IDLE
[ time 1428 ] IDLE
[ time 1429 ] IDLE
[ time 1430 ] IDLE
[ time 1431 ] IDLE
[ time 1432 ] IO_DONE by JOB 0
[ time 1432 ] Run JOB 0 at PRIORITY 1 [ TICKS 9 ALLOT 2 TIME 262 (of 500) ]
[ time 1433 ] IO_START by JOB 0
IO DONE
[ time 1433 ] IDLE
[ time 1434 ] IDLE
[ time 1435 ] IDLE
[ time 1436 ] IDLE
[ time 1437 ] IDLE
[ time 1438 ] IO_DONE by JOB 0
[ time 1438 ] Run JOB 0 at PRIORITY 1 [ TICKS 9 ALLOT 2 TIME 261 (of 500) ]
[ time 1439 ] IO_START by JOB 0
IO DONE
[ time 1439 ] IDLE
[ time 1440 ] IDLE
[ time 1441 ] IDLE
[ time 1442 ] IDLE
[ time 1443 ] IDLE
[ time 1444 ] IO_DONE by JOB 0
[ time 1444 ] Run JOB 0 at PRIORITY 1 [ TICKS 9 ALLOT 2 TIME 260 (of 500) ]
[ time 1445 ] IO_START by JOB 0
IO DONE
[ time 1445 ] IDLE
[ time 1446 ] IDLE
[ time 1447 ] IDLE
[ time 1448 ] IDLE
[ time 1449 ] IDLE
[ time 1450 ] IO_DONE by JOB 0
[ time 1450 ] Run JOB 0 at PRIORITY 1 [ TICKS 9 ALLOT 2 TIME 259 (of 500) ]
[ time 1451 ] IO_START by JOB 0
IO DONE
[ time 1451 ] IDLE
[ time 1452 ] IDLE
[ time 1453 ] IDLE
[ time 1454 ] IDLE
[ time 1455 ] IDLE
[ time 1456 ] IO_DONE by JOB 0
[ time 1456 ] Run JOB 0 at PRIORITY 1 [ TICKS 9 ALLOT 2 TIME 258 (of 500) ]
[ time 1457 ] IO_START by JOB 0
IO DONE
[ time 1457 ] IDLE
[ time 1458 ] IDLE
[ time 1459 ] IDLE
[ time 1460 ] IDLE
[ time 1461 ] IDLE
[ time 1462 ] IO_DONE by JOB 0
[ time 1462 ] Run JOB 0 at PRIORITY 1 [ TICKS 9 ALLOT 2 TIME 257 (of 500) ]
[ time 1463 ] IO_START by JOB 0
IO DONE
[ time 1463 ] IDLE
[ time 1464 ] IDLE
[ time 1465 ] IDLE
[ time 1466 ] IDLE
[ time 1467 ] IDLE
[ time 1468 ] IO_DONE by JOB 0
[ time 1468 ] Run JOB 0 at PRIORITY 1 [ TICKS 9 ALLOT 2 TIME 256 (of 500) ]
[ time 1469 ] IO_START by JOB 0
IO DONE
[ time 1469 ] IDLE
[ time 1470 ] IDLE
[ time 1471 ] IDLE
[ time 1472 ] IDLE
[ time 1473 ] IDLE
[ time 1474 ] IO_DONE by JOB 0
[ time 1474 ] Run JOB 0 at PRIORITY 1 [ TICKS 9 ALLOT 2 TIME 255 (of 500) ]
[ time 1475 ] IO_START by JOB 0
IO DONE
[ time 1475 ] IDLE
[ time 1476 ] IDLE
[ time 1477 ] IDLE
[ time 1478 ] IDLE
[ time 1479 ] IDLE
[ time 1480 ] IO_DONE by JOB 0
[ time 1480 ] Run JOB 0 at PRIORITY 1 [ TICKS 9 ALLOT 2 TIME 254 (of 500) ]
[ time 1481 ] IO_START by JOB 0
IO DONE
[ time 1481 ] IDLE
[ time 1482 ] IDLE
[ time 1483 ] IDLE
[ time 1484 ] IDLE
[ time 1485 ] IDLE
[ time 1486 ] IO_DONE by JOB 0
[ time 1486 ] Run JOB 0 at PRIORITY 1 [ TICKS 9 ALLOT 2 TIME 253 (of 500) ]
[ time 1487 ] IO_START by JOB 0
IO DONE
[ time 1487 ] IDLE
[ time 1488 ] IDLE
[ time 1489 ] IDLE
[ time 1490 ] IDLE
[ time 1491 ] IDLE
[ time 1492 ] IO_DONE by JOB 0
[ time 1492 ] Run JOB 0 at PRIORITY 1 [ TICKS 9 ALLOT 2 TIME 252 (of 500) ]
[ time 1493 ] IO_START by JOB 0
IO DONE
[ time 1493 ] IDLE
[ time 1494 ] IDLE
[ time 1495 ] IDLE
[ time 1496 ] IDLE
[ time 1497 ] IDLE
[ time 1498 ] IO_DONE by JOB 0
[ time 1498 ] Run JOB 0 at PRIORITY 1 [ TICKS 9 ALLOT 2 TIME 251 (of 500) ]
[ time 1499 ] IO_START by JOB 0
IO DONE
[ time 1499 ] IDLE
[ time 1500 ] IDLE
[ time 1501 ] IDLE
[ time 1502 ] IDLE
[ time 1503 ] IDLE
[ time 1504 ] IO_DONE by JOB 0
[ time 1504 ] Run JOB 0 at PRIORITY 1 [ TICKS 9 ALLOT 2 TIME 250 (of 500) ]
[ time 1505 ] IO_START by JOB 0
IO DONE
[ time 1505 ] IDLE
[ time 1506 ] IDLE
[ time 1507 ] IDLE
[ time 1508 ] IDLE
[ time 1509 ] IDLE
[ time 1510 ] IO_DONE by JOB 0
[ time 1510 ] Run JOB 0 at PRIORITY 1 [ TICKS 9 ALLOT 2 TIME 249 (of 500) ]
[ time 1511 ] IO_START by JOB 0
IO DONE
[ time 1511 ] IDLE
[ time 1512 ] IDLE
[ time 1513 ] IDLE
[ time 1514 ] IDLE
[ time 1515 ] IDLE
[ time 1516 ] IO_DONE by JOB 0
[ time 1516 ] Run JOB 0 at PRIORITY 1 [ TICKS 9 ALLOT 2 TIME 248 (of 500) ]
[ time 1517 ] IO_START by JOB 0
IO DONE
[ time 1517 ] IDLE
[ time 1518 ] IDLE
[ time 1519 ] IDLE
[ time 1520 ] IDLE
[ time 1521 ] IDLE
[ time 1522 ] IO_DONE by JOB 0
[ time 1522 ] Run JOB 0 at PRIORITY 1 [ TICKS 9 ALLOT 2 TIME 247 (of 500) ]
[ time 1523 ] IO_START by JOB 0
IO DONE
[ time 1523 ] IDLE
[ time 1524 ] IDLE
[ time 1525 ] IDLE
[ time 1526 ] IDLE
[ time 1527 ] IDLE
[ time 1528 ] IO_DONE by JOB 0
[ time 1528 ] Run JOB 0 at PRIORITY 1 [ TICKS 9 ALLOT 2 TIME 246 (of 500) ]
[ time 1529 ] IO_START by JOB 0
IO DONE
[ time 1529 ] IDLE
[ time 1530 ] IDLE
[ time 1531 ] IDLE
[ time 1532 ] IDLE
[ time 1533 ] IDLE
[ time 1534 ] IO_DONE by JOB 0
[ time 1534 ] Run JOB 0 at PRIORITY 1 [ TICKS 9 ALLOT 2 TIME 245 (of 500) ]
[ time 1535 ] IO_START by JOB 0
IO DONE
[ time 1535 ] IDLE
[ time 1536 ] IDLE
[ time 1537 ] IDLE
[ time 1538 ] IDLE
[ time 1539 ] IDLE
[ time 1540 ] IO_DONE by JOB 0
[ time 1540 ] Run JOB 0 at PRIORITY 1 [ TICKS 9 ALLOT 2 TIME 244 (of 500) ]
[ time 1541 ] IO_START by JOB 0
IO DONE
[ time 1541 ] IDLE
[ time 1542 ] IDLE
[ time 1543 ] IDLE
[ time 1544 ] IDLE
[ time 1545 ] IDLE
[ time 1546 ] IO_DONE by JOB 0
[ time 1546 ] Run JOB 0 at PRIORITY 1 [ TICKS 9 ALLOT 2 TIME 243 (of 500) ]
[ time 1547 ] IO_START by JOB 0
IO DONE
[ time 1547 ] IDLE
[ time 1548 ] IDLE
[ time 1549 ] IDLE
[ time 1550 ] IDLE
[ time 1551 ] IDLE
[ time 1552 ] IO_DONE by JOB 0
[ time 1552 ] Run JOB 0 at PRIORITY 1 [ TICKS 9 ALLOT 2 TIME 242 (of 500) ]
[ time 1553 ] IO_START by JOB 0
IO DONE
[ time 1553 ] IDLE
[ time 1554 ] IDLE
[ time 1555 ] IDLE
[ time 1556 ] IDLE
[ time 1557 ] IDLE
[ time 1558 ] IO_DONE by JOB 0
[ time 1558 ] Run JOB 0 at PRIORITY 1 [ TICKS 9 ALLOT 2 TIME 241 (of 500) ]
[ time 1559 ] IO_START by JOB 0
IO DONE
[ time 1559 ] IDLE
[ time 1560 ] IDLE
[ time 1561 ] IDLE
[ time 1562 ] IDLE
[ time 1563 ] IDLE
[ time 1564 ] IO_DONE by JOB 0
[ time 1564 ] Run JOB 0 at PRIORITY 1 [ TICKS 9 ALLOT 2 TIME 240 (of 500) ]
[ time 1565 ] IO_START by JOB 0
IO DONE
[ time 1565 ] IDLE
[ time 1566 ] IDLE
[ time 1567 ] IDLE
[ time 1568 ] IDLE
[ time 1569 ] IDLE
[ time 1570 ] IO_DONE by JOB 0
[ time 1570 ] Run JOB 0 at PRIORITY 1 [ TICKS 9 ALLOT 2 TIME 239 (of 500) ]
[ time 1571 ] IO_START by JOB 0
IO DONE
[ time 1571 ] IDLE
[ time 1572 ] IDLE
[ time 1573 ] IDLE
[ time 1574 ] IDLE
[ time 1575 ] IDLE
[ time 1576 ] IO_DONE by JOB 0
[ time 1576 ] Run JOB 0 at PRIORITY 1 [ TICKS 9 ALLOT 2 TIME 238 (of 500) ]
[ time 1577 ] IO_START by JOB 0
IO DONE
[ time 1577 ] IDLE
[ time 1578 ] IDLE
[ time 1579 ] IDLE
[ time 1580 ] IDLE
[ time 1581 ] IDLE
[ time 1582 ] IO_DONE by JOB 0
[ time 1582 ] Run JOB 0 at PRIORITY 1 [ TICKS 9 ALLOT 2 TIME 237 (of 500) ]
[ time 1583 ] IO_START by JOB 0
IO DONE
[ time 1583 ] IDLE
[ time 1584 ] IDLE
[ time 1585 ] IDLE
[ time 1586 ] IDLE
[ time 1587 ] IDLE
[ time 1588 ] IO_DONE by JOB 0
[ time 1588 ] Run JOB 0 at PRIORITY 1 [ TICKS 9 ALLOT 2 TIME 236 (of 500) ]
[ time 1589 ] IO_START by JOB 0
IO DONE
[ time 1589 ] IDLE
[ time 1590 ] IDLE
[ time 1591 ] IDLE
[ time 1592 ] IDLE
[ time 1593 ] IDLE
[ time 1594 ] IO_DONE by JOB 0
[ time 1594 ] Run JOB 0 at PRIORITY 1 [ TICKS 9 ALLOT 2 TIME 235 (of 500) ]
[ time 1595 ] IO_START by JOB 0
IO DONE
[ time 1595 ] IDLE
[ time 1596 ] IDLE
[ time 1597 ] IDLE
[ time 1598 ] IDLE
[ time 1599 ] IDLE
[ time 1600 ] IO_DONE by JOB 0
[ time 1600 ] Run JOB 0 at PRIORITY 1 [ TICKS 9 ALLOT 2 TIME 234 (of 500) ]
[ time 1601 ] IO_START by JOB 0
IO DONE
[ time 1601 ] IDLE
[ time 1602 ] IDLE
[ time 1603 ] IDLE
[ time 1604 ] IDLE
[ time 1605 ] IDLE
[ time 1606 ] IO_DONE by JOB 0
[ time 1606 ] Run JOB 0 at PRIORITY 1 [ TICKS 9 ALLOT 2 TIME 233 (of 500) ]
[ time 1607 ] IO_START by JOB 0
IO DONE
[ time 1607 ] IDLE
[ time 1608 ] IDLE
[ time 1609 ] IDLE
[ time 1610 ] IDLE
[ time 1611 ] IDLE
[ time 1612 ] IO_DONE by JOB 0
[ time 1612 ] Run JOB 0 at PRIORITY 1 [ TICKS 9 ALLOT 2 TIME 232 (of 500) ]
[ time 1613 ] IO_START by JOB 0
IO DONE
[ time 1613 ] IDLE
[ time 1614 ] IDLE
[ time 1615 ] IDLE
[ time 1616 ] IDLE
[ time 1617 ] IDLE
[ time 1618 ] IO_DONE by JOB 0
[ time 1618 ] Run JOB 0 at PRIORITY 1 [ TICKS 9 ALLOT 2 TIME 231 (of 500) ]
[ time 1619 ] IO_START by JOB 0
IO DONE
[ time 1619 ] IDLE
[ time 1620 ] IDLE
[ time 1621 ] IDLE
[ time 1622 ] IDLE
[ time 1623 ] IDLE
[ time 1624 ] IO_DONE by JOB 0
[ time 1624 ] Run JOB 0 at PRIORITY 1 [ TICKS 9 ALLOT 2 TIME 230 (of 500) ]
[ time 1625 ] IO_START by JOB 0
IO DONE
[ time 1625 ] IDLE
[ time 1626 ] IDLE
[ time 1627 ] IDLE
[ time 1628 ] IDLE
[ time 1629 ] IDLE
[ time 1630 ] IO_DONE by JOB 0
[ time 1630 ] Run JOB 0 at PRIORITY 1 [ TICKS 9 ALLOT 2 TIME 229 (of 500) ]
[ time 1631 ] IO_START by JOB 0
IO DONE
[ time 1631 ] IDLE
[ time 1632 ] IDLE
[ time 1633 ] IDLE
[ time 1634 ] IDLE
[ time 1635 ] IDLE
[ time 1636 ] IO_DONE by JOB 0
[ time 1636 ] Run JOB 0 at PRIORITY 1 [ TICKS 9 ALLOT 2 TIME 228 (of 500) ]
[ time 1637 ] IO_START by JOB 0
IO DONE
[ time 1637 ] IDLE
[ time 1638 ] IDLE
[ time 1639 ] IDLE
[ time 1640 ] IDLE
[ time 1641 ] IDLE
[ time 1642 ] IO_DONE by JOB 0
[ time 1642 ] Run JOB 0 at PRIORITY 1 [ TICKS 9 ALLOT 2 TIME 227 (of 500) ]
[ time 1643 ] IO_START by JOB 0
IO DONE
[ time 1643 ] IDLE
[ time 1644 ] IDLE
[ time 1645 ] IDLE
[ time 1646 ] IDLE
[ time 1647 ] IDLE
[ time 1648 ] IO_DONE by JOB 0
[ time 1648 ] Run JOB 0 at PRIORITY 1 [ TICKS 9 ALLOT 2 TIME 226 (of 500) ]
[ time 1649 ] IO_START by JOB 0
IO DONE
[ time 1649 ] IDLE
[ time 1650 ] IDLE
[ time 1651 ] IDLE
[ time 1652 ] IDLE
[ time 1653 ] IDLE
[ time 1654 ] IO_DONE by JOB 0
[ time 1654 ] Run JOB 0 at PRIORITY 1 [ TICKS 9 ALLOT 2 TIME 225 (of 500) ]
[ time 1655 ] IO_START by JOB 0
IO DONE
[ time 1655 ] IDLE
[ time 1656 ] IDLE
[ time 1657 ] IDLE
[ time 1658 ] IDLE
[ time 1659 ] IDLE
[ time 1660 ] IO_DONE by JOB 0
[ time 1660 ] Run JOB 0 at PRIORITY 1 [ TICKS 9 ALLOT 2 TIME 224 (of 500) ]
[ time 1661 ] IO_START by JOB 0
IO DONE
[ time 1661 ] IDLE
[ time 1662 ] IDLE
[ time 1663 ] IDLE
[ time 1664 ] IDLE
[ time 1665 ] IDLE
[ time 1666 ] IO_DONE by JOB 0
[ time 1666 ] Run JOB 0 at PRIORITY 1 [ TICKS 9 ALLOT 2 TIME 223 (of 500) ]
[ time 1667 ] IO_START by JOB 0
IO DONE
[ time 1667 ] IDLE
[ time 1668 ] IDLE
[ time 1669 ] IDLE
[ time 1670 ] IDLE
[ time 1671 ] IDLE
[ time 1672 ] IO_DONE by JOB 0
[ time 1672 ] Run JOB 0 at PRIORITY 1 [ TICKS 9 ALLOT 2 TIME 222 (of 500) ]
[ time 1673 ] IO_START by JOB 0
IO DONE
[ time 1673 ] IDLE
[ time 1674 ] IDLE
[ time 1675 ] IDLE
[ time 1676 ] IDLE
[ time 1677 ] IDLE
[ time 1678 ] IO_DONE by JOB 0
[ time 1678 ] Run JOB 0 at PRIORITY 1 [ TICKS 9 ALLOT 2 TIME 221 (of 500) ]
[ time 1679 ] IO_START by JOB 0
IO DONE
[ time 1679 ] IDLE
[ time 1680 ] IDLE
[ time 1681 ] IDLE
[ time 1682 ] IDLE
[ time 1683 ] IDLE
[ time 1684 ] IO_DONE by JOB 0
[ time 1684 ] Run JOB 0 at PRIORITY 1 [ TICKS 9 ALLOT 2 TIME 220 (of 500) ]
[ time 1685 ] IO_START by JOB 0
IO DONE
[ time 1685 ] IDLE
[ time 1686 ] IDLE
[ time 1687 ] IDLE
[ time 1688 ] IDLE
[ time 1689 ] IDLE
[ time 1690 ] IO_DONE by JOB 0
[ time 1690 ] Run JOB 0 at PRIORITY 1 [ TICKS 9 ALLOT 2 TIME 219 (of 500) ]
[ time 1691 ] IO_START by JOB 0
IO DONE
[ time 1691 ] IDLE
[ time 1692 ] IDLE
[ time 1693 ] IDLE
[ time 1694 ] IDLE
[ time 1695 ] IDLE
[ time 1696 ] IO_DONE by JOB 0
[ time 1696 ] Run JOB 0 at PRIORITY 1 [ TICKS 9 ALLOT 2 TIME 218 (of 500) ]
[ time 1697 ] IO_START by JOB 0
IO DONE
[ time 1697 ] IDLE
[ time 1698 ] IDLE
[ time 1699 ] IDLE
[ time 1700 ] IDLE
[ time 1701 ] IDLE
[ time 1702 ] IO_DONE by JOB 0
[ time 1702 ] Run JOB 0 at PRIORITY 1 [ TICKS 9 ALLOT 2 TIME 217 (of 500) ]
[ time 1703 ] IO_START by JOB 0
IO DONE
[ time 1703 ] IDLE
[ time 1704 ] IDLE
[ time 1705 ] IDLE
[ time 1706 ] IDLE
[ time 1707 ] IDLE
[ time 1708 ] IO_DONE by JOB 0
[ time 1708 ] Run JOB 0 at PRIORITY 1 [ TICKS 9 ALLOT 2 TIME 216 (of 500) ]
[ time 1709 ] IO_START by JOB 0
IO DONE
[ time 1709 ] IDLE
[ time 1710 ] IDLE
[ time 1711 ] IDLE
[ time 1712 ] IDLE
[ time 1713 ] IDLE
[ time 1714 ] IO_DONE by JOB 0
[ time 1714 ] Run JOB 0 at PRIORITY 1 [ TICKS 9 ALLOT 2 TIME 215 (of 500) ]
[ time 1715 ] IO_START by JOB 0
IO DONE
[ time 1715 ] IDLE
[ time 1716 ] IDLE
[ time 1717 ] IDLE
[ time 1718 ] IDLE
[ time 1719 ] IDLE
[ time 1720 ] IO_DONE by JOB 0
[ time 1720 ] Run JOB 0 at PRIORITY 1 [ TICKS 9 ALLOT 2 TIME 214 (of 500) ]
[ time 1721 ] IO_START by JOB 0
IO DONE
[ time 1721 ] IDLE
[ time 1722 ] IDLE
[ time 1723 ] IDLE
[ time 1724 ] IDLE
[ time 1725 ] IDLE
[ time 1726 ] IO_DONE by JOB 0
[ time 1726 ] Run JOB 0 at PRIORITY 1 [ TICKS 9 ALLOT 2 TIME 213 (of 500) ]
[ time 1727 ] IO_START by JOB 0
IO DONE
[ time 1727 ] IDLE
[ time 1728 ] IDLE
[ time 1729 ] IDLE
[ time 1730 ] IDLE
[ time 1731 ] IDLE
[ time 1732 ] IO_DONE by JOB 0
[ time 1732 ] Run JOB 0 at PRIORITY 1 [ TICKS 9 ALLOT 2 TIME 212 (of 500) ]
[ time 1733 ] IO_START by JOB 0
IO DONE
[ time 1733 ] IDLE
[ time 1734 ] IDLE
[ time 1735 ] IDLE
[ time 1736 ] IDLE
[ time 1737 ] IDLE
[ time 1738 ] IO_DONE by JOB 0
[ time 1738 ] Run JOB 0 at PRIORITY 1 [ TICKS 9 ALLOT 2 TIME 211 (of 500) ]
[ time 1739 ] IO_START by JOB 0
IO DONE
[ time 1739 ] IDLE
[ time 1740 ] IDLE
[ time 1741 ] IDLE
[ time 1742 ] IDLE
[ time 1743 ] IDLE
[ time 1744 ] IO_DONE by JOB 0
[ time 1744 ] Run JOB 0 at PRIORITY 1 [ TICKS 9 ALLOT 2 TIME 210 (of 500) ]
[ time 1745 ] IO_START by JOB 0
IO DONE
[ time 1745 ] IDLE
[ time 1746 ] IDLE
[ time 1747 ] IDLE
[ time 1748 ] IDLE
[ time 1749 ] IDLE
[ time 1750 ] IO_DONE by JOB 0
[ time 1750 ] Run JOB 0 at PRIORITY 1 [ TICKS 9 ALLOT 2 TIME 209 (of 500) ]
[ time 1751 ] IO_START by JOB 0
IO DONE
[ time 1751 ] IDLE
[ time 1752 ] IDLE
[ time 1753 ] IDLE
[ time 1754 ] IDLE
[ time 1755 ] IDLE
[ time 1756 ] IO_DONE by JOB 0
[ time 1756 ] Run JOB 0 at PRIORITY 1 [ TICKS 9 ALLOT 2 TIME 208 (of 500) ]
[ time 1757 ] IO_START by JOB 0
IO DONE
[ time 1757 ] IDLE
[ time 1758 ] IDLE
[ time 1759 ] IDLE
[ time 1760 ] IDLE
[ time 1761 ] IDLE
[ time 1762 ] IO_DONE by JOB 0
[ time 1762 ] Run JOB 0 at PRIORITY 1 [ TICKS 9 ALLOT 2 TIME 207 (of 500) ]
[ time 1763 ] IO_START by JOB 0
IO DONE
[ time 1763 ] IDLE
[ time 1764 ] IDLE
[ time 1765 ] IDLE
[ time 1766 ] IDLE
[ time 1767 ] IDLE
[ time 1768 ] IO_DONE by JOB 0
[ time 1768 ] Run JOB 0 at PRIORITY 1 [ TICKS 9 ALLOT 2 TIME 206 (of 500) ]
[ time 1769 ] IO_START by JOB 0
IO DONE
[ time 1769 ] IDLE
[ time 1770 ] IDLE
[ time 1771 ] IDLE
[ time 1772 ] IDLE
[ time 1773 ] IDLE
[ time 1774 ] IO_DONE by JOB 0
[ time 1774 ] Run JOB 0 at PRIORITY 1 [ TICKS 9 ALLOT 2 TIME 205 (of 500) ]
[ time 1775 ] IO_START by JOB 0
IO DONE
[ time 1775 ] IDLE
[ time 1776 ] IDLE
[ time 1777 ] IDLE
[ time 1778 ] IDLE
[ time 1779 ] IDLE
[ time 1780 ] IO_DONE by JOB 0
[ time 1780 ] Run JOB 0 at PRIORITY 1 [ TICKS 9 ALLOT 2 TIME 204 (of 500) ]
[ time 1781 ] IO_START by JOB 0
IO DONE
[ time 1781 ] IDLE
[ time 1782 ] IDLE
[ time 1783 ] IDLE
[ time 1784 ] IDLE
[ time 1785 ] IDLE
[ time 1786 ] IO_DONE by JOB 0
[ time 1786 ] Run JOB 0 at PRIORITY 1 [ TICKS 9 ALLOT 2 TIME 203 (of 500) ]
[ time 1787 ] IO_START by JOB 0
IO DONE
[ time 1787 ] IDLE
[ time 1788 ] IDLE
