Here is the list of inputs:
OPTIONS jobs 3
OPTIONS queues 2
OPTIONS allotments for queue  1 is   2
OPTIONS quantum length for queue  1 is  10
OPTIONS allotments for queue  0 is   2
OPTIONS quantum length for queue  0 is  50
OPTIONS boost 20
OPTIONS ioTime 5
OPTIONS stayAfterIO False
OPTIONS iobump False


For each job, three defining characteristics are given:
  startTime : at what time does the job enter the system
  runTime   : the total CPU time needed by the job to finish
  ioFreq    : every ioFreq time units, the job issues an I/O
              (the I/O takes ioTime units to complete)

Job List:
  Job  0: startTime   0 - runTime 500 - ioFreq   0
  Job  1: startTime   0 - runTime  20 - ioFreq   0
  Job  2: startTime  20 - runTime 100 - ioFreq   0


Execution Trace:

[ time 0 ] JOB BEGINS by JOB 0
[ time 0 ] JOB BEGINS by JOB 1
[ time 0 ] Run JOB 0 at PRIORITY 1 [ TICKS 9 ALLOT 2 TIME 499 (of 500) ]
[ time 1 ] Run JOB 0 at PRIORITY 1 [ TICKS 8 ALLOT 2 TIME 498 (of 500) ]
[ time 2 ] Run JOB 0 at PRIORITY 1 [ TICKS 7 ALLOT 2 TIME 497 (of 500) ]
[ time 3 ] Run JOB 0 at PRIORITY 1 [ TICKS 6 ALLOT 2 TIME 496 (of 500) ]
[ time 4 ] Run JOB 0 at PRIORITY 1 [ TICKS 5 ALLOT 2 TIME 495 (of 500) ]
[ time 5 ] Run JOB 0 at PRIORITY 1 [ TICKS 4 ALLOT 2 TIME 494 (of 500) ]
[ time 6 ] Run JOB 0 at PRIORITY 1 [ TICKS 3 ALLOT 2 TIME 493 (of 500) ]
[ time 7 ] Run JOB 0 at PRIORITY 1 [ TICKS 2 ALLOT 2 TIME 492 (of 500) ]
[ time 8 ] Run JOB 0 at PRIORITY 1 [ TICKS 1 ALLOT 2 TIME 491 (of 500) ]
[ time 9 ] Run JOB 0 at PRIORITY 1 [ TICKS 0 ALLOT 2 TIME 490 (of 500) ]
[ time 10 ] Run JOB 1 at PRIORITY 1 [ TICKS 9 ALLOT 2 TIME 19 (of 20) ]
[ time 11 ] Run JOB 1 at PRIORITY 1 [ TICKS 8 ALLOT 2 TIME 18 (of 20) ]
[ time 12 ] Run JOB 1 at PRIORITY 1 [ TICKS 7 ALLOT 2 TIME 17 (of 20) ]
[ time 13 ] Run JOB 1 at PRIORITY 1 [ TICKS 6 ALLOT 2 TIME 16 (of 20) ]
[ time 14 ] Run JOB 1 at PRIORITY 1 [ TICKS 5 ALLOT 2 TIME 15 (of 20) ]
[ time 15 ] Run JOB 1 at PRIORITY 1 [ TICKS 4 ALLOT 2 TIME 14 (of 20) ]
[ time 16 ] Run JOB 1 at PRIORITY 1 [ TICKS 3 ALLOT 2 TIME 13 (of 20) ]
[ time 17 ] Run JOB 1 at PRIORITY 1 [ TICKS 2 ALLOT 2 TIME 12 (of 20) ]
[ time 18 ] Run JOB 1 at PRIORITY 1 [ TICKS 1 ALLOT 2 TIME 11 (of 20) ]
[ time 19 ] Run JOB 1 at PRIORITY 1 [ TICKS 0 ALLOT 2 TIME 10 (of 20) ]
[ time 20 ] BOOST ( every 20 )
[ time 20 ] JOB BEGINS by JOB 2
[ time 20 ] Run JOB 0 at PRIORITY 1 [ TICKS 9 ALLOT 2 TIME 489 (of 500) ]
[ time 21 ] Run JOB 0 at PRIORITY 1 [ TICKS 8 ALLOT 2 TIME 488 (of 500) ]
[ time 22 ] Run JOB 0 at PRIORITY 1 [ TICKS 7 ALLOT 2 TIME 487 (of 500) ]
[ time 23 ] Run JOB 0 at PRIORITY 1 [ TICKS 6 ALLOT 2 TIME 486 (of 500) ]
[ time 24 ] Run JOB 0 at PRIORITY 1 [ TICKS 5 ALLOT 2 TIME 485 (of 500) ]
[ time 25 ] Run JOB 0 at PRIORITY 1 [ TICKS 4 ALLOT 2 TIME 484 (of 500) ]
[ time 26 ] Run JOB 0 at PRIORITY 1 [ TICKS 3 ALLOT 2 TIME 483 (of 500) ]
[ time 27 ] Run JOB 0 at PRIORITY 1 [ TICKS 2 ALLOT 2 TIME 482 (of 500) ]
[ time 28 ] Run JOB 0 at PRIORITY 1 [ TICKS 1 ALLOT 2 TIME 481 (of 500) ]
[ time 29 ] Run JOB 0 at PRIORITY 1 [ TICKS 0 ALLOT 2 TIME 480 (of 500) ]
[ time 30 ] Run JOB 1 at PRIORITY 1 [ TICKS 9 ALLOT 2 TIME 9 (of 20) ]
[ time 31 ] Run JOB 1 at PRIORITY 1 [ TICKS 8 ALLOT 2 TIME 8 (of 20) ]
[ time 32 ] Run JOB 1 at PRIORITY 1 [ TICKS 7 ALLOT 2 TIME 7 (of 20) ]
[ time 33 ] Run JOB 1 at PRIORITY 1 [ TICKS 6 ALLOT 2 TIME 6 (of 20) ]
[ time 34 ] Run JOB 1 at PRIORITY 1 [ TICKS 5 ALLOT 2 TIME 5 (of 20) ]
[ time 35 ] Run JOB 1 at PRIORITY 1 [ TICKS 4 ALLOT 2 TIME 4 (of 20) ]
[ time 36 ] Run JOB 1 at PRIORITY 1 [ TICKS 3 ALLOT 2 TIME 3 (of 20) ]
[ time 37 ] Run JOB 1 at PRIORITY 1 [ TICKS 2 ALLOT 2 TIME 2 (of 20) ]
[ time 38 ] Run JOB 1 at PRIORITY 1 [ TICKS 1 ALLOT 2 TIME 1 (of 20) ]
[ time 39 ] Run JOB 1 at PRIORITY 1 [ TICKS 0 ALLOT 2 TIME 0 (of 20) ]
[ time 40 ] FINISHED JOB 1
[ time 40 ] BOOST ( every 20 )
[ time 40 ] Run JOB 2 at PRIORITY 1 [ TICKS 9 ALLOT 2 TIME 99 (of 100) ]
[ time 41 ] Run JOB 2 at PRIORITY 1 [ TICKS 8 ALLOT 2 TIME 98 (of 100) ]
[ time 42 ] Run JOB 2 at PRIORITY 1 [ TICKS 7 ALLOT 2 TIME 97 (of 100) ]
[ time 43 ] Run JOB 2 at PRIORITY 1 [ TICKS 6 ALLOT 2 TIME 96 (of 100) ]
[ time 44 ] Run JOB 2 at PRIORITY 1 [ TICKS 5 ALLOT 2 TIME 95 (of 100) ]
[ time 45 ] Run JOB 2 at PRIORITY 1 [ TICKS 4 ALLOT 2 TIME 94 (of 100) ]
[ time 46 ] Run JOB 2 at PRIORITY 1 [ TICKS 3 ALLOT 2 TIME 93 (of 100) ]
[ time 47 ] Run JOB 2 at PRIORITY 1 [ TICKS 2 ALLOT 2 TIME 92 (of 100) ]
[ time 48 ] Run JOB 2 at PRIORITY 1 [ TICKS 1 ALLOT 2 TIME 91 (of 100) ]
[ time 49 ] Run JOB 2 at PRIORITY 1 [ TICKS 0 ALLOT 2 TIME 90 (of 100) ]
[ time 50 ] Run JOB 0 at PRIORITY 1 [ TICKS 9 ALLOT 2 TIME 479 (of 500) ]
[ time 51 ] Run JOB 0 at PRIORITY 1 [ TICKS 8 ALLOT 2 TIME 478 (of 500) ]
[ time 52 ] Run JOB 0 at PRIORITY 1 [ TICKS 7 ALLOT 2 TIME 477 (of 500) ]
[ time 53 ] Run JOB 0 at PRIORITY 1 [ TICKS 6 ALLOT 2 TIME 476 (of 500) ]
[ time 54 ] Run JOB 0 at PRIORITY 1 [ TICKS 5 ALLOT 2 TIME 475 (of 500) ]
[ time 55 ] Run JOB 0 at PRIORITY 1 [ TICKS 4 ALLOT 2 TIME 474 (of 500) ]
[ time 56 ] Run JOB 0 at PRIORITY 1 [ TICKS 3 ALLOT 2 TIME 473 (of 500) ]
[ time 57 ] Run JOB 0 at PRIORITY 1 [ TICKS 2 ALLOT 2 TIME 472 (of 500) ]
[ time 58 ] Run JOB 0 at PRIORITY 1 [ TICKS 1 ALLOT 2 TIME 471 (of 500) ]
[ time 59 ] Run JOB 0 at PRIORITY 1 [ TICKS 0 ALLOT 2 TIME 470 (of 500) ]
[ time 60 ] BOOST ( every 20 )
[ time 60 ] Run JOB 2 at PRIORITY 1 [ TICKS 9 ALLOT 2 TIME 89 (of 100) ]
[ time 61 ] Run JOB 2 at PRIORITY 1 [ TICKS 8 ALLOT 2 TIME 88 (of 100) ]
[ time 62 ] Run JOB 2 at PRIORITY 1 [ TICKS 7 ALLOT 2 TIME 87 (of 100) ]
[ time 63 ] Run JOB 2 at PRIORITY 1 [ TICKS 6 ALLOT 2 TIME 86 (of 100) ]
[ time 64 ] Run JOB 2 at PRIORITY 1 [ TICKS 5 ALLOT 2 TIME 85 (of 100) ]
[ time 65 ] Run JOB 2 at PRIORITY 1 [ TICKS 4 ALLOT 2 TIME 84 (of 100) ]
[ time 66 ] Run JOB 2 at PRIORITY 1 [ TICKS 3 ALLOT 2 TIME 83 (of 100) ]
[ time 67 ] Run JOB 2 at PRIORITY 1 [ TICKS 2 ALLOT 2 TIME 82 (of 100) ]
[ time 68 ] Run JOB 2 at PRIORITY 1 [ TICKS 1 ALLOT 2 TIME 81 (of 100) ]
[ time 69 ] Run JOB 2 at PRIORITY 1 [ TICKS 0 ALLOT 2 TIME 80 (of 100) ]
[ time 70 ] Run JOB 0 at PRIORITY 1 [ TICKS 9 ALLOT 2 TIME 469 (of 500) ]
[ time 71 ] Run JOB 0 at PRIORITY 1 [ TICKS 8 ALLOT 2 TIME 468 (of 500) ]
[ time 72 ] Run JOB 0 at PRIORITY 1 [ TICKS 7 ALLOT 2 TIME 467 (of 500) ]
[ time 73 ] Run JOB 0 at PRIORITY 1 [ TICKS 6 ALLOT 2 TIME 466 (of 500) ]
[ time 74 ] Run JOB 0 at PRIORITY 1 [ TICKS 5 ALLOT 2 TIME 465 (of 500) ]
[ time 75 ] Run JOB 0 at PRIORITY 1 [ TICKS 4 ALLOT 2 TIME 464 (of 500) ]
[ time 76 ] Run JOB 0 at PRIORITY 1 [ TICKS 3 ALLOT 2 TIME 463 (of 500) ]
[ time 77 ] Run JOB 0 at PRIORITY 1 [ TICKS 2 ALLOT 2 TIME 462 (of 500) ]
[ time 78 ] Run JOB 0 at PRIORITY 1 [ TICKS 1 ALLOT 2 TIME 461 (of 500) ]
[ time 79 ] Run JOB 0 at PRIORITY 1 [ TICKS 0 ALLOT 2 TIME 460 (of 500) ]
[ time 80 ] BOOST ( every 20 )
[ time 80 ] Run JOB 2 at PRIORITY 1 [ TICKS 9 ALLOT 2 TIME 79 (of 100) ]
[ time 81 ] Run JOB 2 at PRIORITY 1 [ TICKS 8 ALLOT 2 TIME 78 (of 100) ]
[ time 82 ] Run JOB 2 at PRIORITY 1 [ TICKS 7 ALLOT 2 TIME 77 (of 100) ]
[ time 83 ] Run JOB 2 at PRIORITY 1 [ TICKS 6 ALLOT 2 TIME 76 (of 100) ]
[ time 84 ] Run JOB 2 at PRIORITY 1 [ TICKS 5 ALLOT 2 TIME 75 (of 100) ]
[ time 85 ] Run JOB 2 at PRIORITY 1 [ TICKS 4 ALLOT 2 TIME 74 (of 100) ]
[ time 86 ] Run JOB 2 at PRIORITY 1 [ TICKS 3 ALLOT 2 TIME 73 (of 100) ]
[ time 87 ] Run JOB 2 at PRIORITY 1 [ TICKS 2 ALLOT 2 TIME 72 (of 100) ]
[ time 88 ] Run JOB 2 at PRIORITY 1 [ TICKS 1 ALLOT 2 TIME 71 (of 100) ]
[ time 89 ] Run JOB 2 at PRIORITY 1 [ TICKS 0 ALLOT 2 TIME 70 (of 100) ]
[ time 90 ] Run JOB 0 at PRIORITY 1 [ TICKS 9 ALLOT 2 TIME 459 (of 500) ]
[ time 91 ] Run JOB 0 at PRIORITY 1 [ TICKS 8 ALLOT 2 TIME 458 (of 500) ]
[ time 92 ] Run JOB 0 at PRIORITY 1 [ TICKS 7 ALLOT 2 TIME 457 (of 500) ]
[ time 93 ] Run JOB 0 at PRIORITY 1 [ TICKS 6 ALLOT 2 TIME 456 (of 500) ]
[ time 94 ] Run JOB 0 at PRIORITY 1 [ TICKS 5 ALLOT 2 TIME 455 (of 500) ]
[ time 95 ] Run JOB 0 at PRIORITY 1 [ TICKS 4 ALLOT 2 TIME 454 (of 500) ]
[ time 96 ] Run JOB 0 at PRIORITY 1 [ TICKS 3 ALLOT 2 TIME 453 (of 500) ]
[ time 97 ] Run JOB 0 at PRIORITY 1 [ TICKS 2 ALLOT 2 TIME 452 (of 500) ]
[ time 98 ] Run JOB 0 at PRIORITY 1 [ TICKS 1 ALLOT 2 TIME 451 (of 500) ]
[ time 99 ] Run JOB 0 at PRIORITY 1 [ TICKS 0 ALLOT 2 TIME 450 (of 500) ]
[ time 100 ] BOOST ( every 20 )
[ time 100 ] Run JOB 2 at PRIORITY 1 [ TICKS 9 ALLOT 2 TIME 69 (of 100) ]
[ time 101 ] Run JOB 2 at PRIORITY 1 [ TICKS 8 ALLOT 2 TIME 68 (of 100) ]
[ time 102 ] Run JOB 2 at PRIORITY 1 [ TICKS 7 ALLOT 2 TIME 67 (of 100) ]
[ time 103 ] Run JOB 2 at PRIORITY 1 [ TICKS 6 ALLOT 2 TIME 66 (of 100) ]
[ time 104 ] Run JOB 2 at PRIORITY 1 [ TICKS 5 ALLOT 2 TIME 65 (of 100) ]
[ time 105 ] Run JOB 2 at PRIORITY 1 [ TICKS 4 ALLOT 2 TIME 64 (of 100) ]
[ time 106 ] Run JOB 2 at PRIORITY 1 [ TICKS 3 ALLOT 2 TIME 63 (of 100) ]
[ time 107 ] Run JOB 2 at PRIORITY 1 [ TICKS 2 ALLOT 2 TIME 62 (of 100) ]
[ time 108 ] Run JOB 2 at PRIORITY 1 [ TICKS 1 ALLOT 2 TIME 61 (of 100) ]
[ time 109 ] Run JOB 2 at PRIORITY 1 [ TICKS 0 ALLOT 2 TIME 60 (of 100) ]
[ time 110 ] Run JOB 0 at PRIORITY 1 [ TICKS 9 ALLOT 2 TIME 449 (of 500) ]
[ time 111 ] Run JOB 0 at PRIORITY 1 [ TICKS 8 ALLOT 2 TIME 448 (of 500) ]
[ time 112 ] Run JOB 0 at PRIORITY 1 [ TICKS 7 ALLOT 2 TIME 447 (of 500) ]
[ time 113 ] Run JOB 0 at PRIORITY 1 [ TICKS 6 ALLOT 2 TIME 446 (of 500) ]
[ time 114 ] Run JOB 0 at PRIORITY 1 [ TICKS 5 ALLOT 2 TIME 445 (of 500) ]
[ time 115 ] Run JOB 0 at PRIORITY 1 [ TICKS 4 ALLOT 2 TIME 444 (of 500) ]
[ time 116 ] Run JOB 0 at PRIORITY 1 [ TICKS 3 ALLOT 2 TIME 443 (of 500) ]
[ time 117 ] Run JOB 0 at PRIORITY 1 [ TICKS 2 ALLOT 2 TIME 442 (of 500) ]
[ time 118 ] Run JOB 0 at PRIORITY 1 [ TICKS 1 ALLOT 2 TIME 441 (of 500) ]
[ time 119 ] Run JOB 0 at PRIORITY 1 [ TICKS 0 ALLOT 2 TIME 440 (of 500) ]
[ time 120 ] BOOST ( every 20 )
[ time 120 ] Run JOB 2 at PRIORITY 1 [ TICKS 9 ALLOT 2 TIME 59 (of 100) ]
[ time 121 ] Run JOB 2 at PRIORITY 1 [ TICKS 8 ALLOT 2 TIME 58 (of 100) ]
[ time 122 ] Run JOB 2 at PRIORITY 1 [ TICKS 7 ALLOT 2 TIME 57 (of 100) ]
[ time 123 ] Run JOB 2 at PRIORITY 1 [ TICKS 6 ALLOT 2 TIME 56 (of 100) ]
[ time 124 ] Run JOB 2 at PRIORITY 1 [ TICKS 5 ALLOT 2 TIME 55 (of 100) ]
[ time 125 ] Run JOB 2 at PRIORITY 1 [ TICKS 4 ALLOT 2 TIME 54 (of 100) ]
[ time 126 ] Run JOB 2 at PRIORITY 1 [ TICKS 3 ALLOT 2 TIME 53 (of 100) ]
[ time 127 ] Run JOB 2 at PRIORITY 1 [ TICKS 2 ALLOT 2 TIME 52 (of 100) ]
[ time 128 ] Run JOB 2 at PRIORITY 1 [ TICKS 1 ALLOT 2 TIME 51 (of 100) ]
[ time 129 ] Run JOB 2 at PRIORITY 1 [ TICKS 0 ALLOT 2 TIME 50 (of 100) ]
[ time 130 ] Run JOB 0 at PRIORITY 1 [ TICKS 9 ALLOT 2 TIME 439 (of 500) ]
[ time 131 ] Run JOB 0 at PRIORITY 1 [ TICKS 8 ALLOT 2 TIME 438 (of 500) ]
[ time 132 ] Run JOB 0 at PRIORITY 1 [ TICKS 7 ALLOT 2 TIME 437 (of 500) ]
[ time 133 ] Run JOB 0 at PRIORITY 1 [ TICKS 6 ALLOT 2 TIME 436 (of 500) ]
[ time 134 ] Run JOB 0 at PRIORITY 1 [ TICKS 5 ALLOT 2 TIME 435 (of 500) ]
[ time 135 ] Run JOB 0 at PRIORITY 1 [ TICKS 4 ALLOT 2 TIME 434 (of 500) ]
[ time 136 ] Run JOB 0 at PRIORITY 1 [ TICKS 3 ALLOT 2 TIME 433 (of 500) ]
[ time 137 ] Run JOB 0 at PRIORITY 1 [ TICKS 2 ALLOT 2 TIME 432 (of 500) ]
[ time 138 ] Run JOB 0 at PRIORITY 1 [ TICKS 1 ALLOT 2 TIME 431 (of 500) ]
[ time 139 ] Run JOB 0 at PRIORITY 1 [ TICKS 0 ALLOT 2 TIME 430 (of 500) ]
[ time 140 ] BOOST ( every 20 )
[ time 140 ] Run JOB 2 at PRIORITY 1 [ TICKS 9 ALLOT 2 TIME 49 (of 100) ]
[ time 141 ] Run JOB 2 at PRIORITY 1 [ TICKS 8 ALLOT 2 TIME 48 (of 100) ]
[ time 142 ] Run JOB 2 at PRIORITY 1 [ TICKS 7 ALLOT 2 TIME 47 (of 100) ]
[ time 143 ] Run JOB 2 at PRIORITY 1 [ TICKS 6 ALLOT 2 TIME 46 (of 100) ]
[ time 144 ] Run JOB 2 at PRIORITY 1 [ TICKS 5 ALLOT 2 TIME 45 (of 100) ]
[ time 145 ] Run JOB 2 at PRIORITY 1 [ TICKS 4 ALLOT 2 TIME 44 (of 100) ]
[ time 146 ] Run JOB 2 at PRIORITY 1 [ TICKS 3 ALLOT 2 TIME 43 (of 100) ]
[ time 147 ] Run JOB 2 at PRIORITY 1 [ TICKS 2 ALLOT 2 TIME 42 (of 100) ]
[ time 148 ] Run JOB 2 at PRIORITY 1 [ TICKS 1 ALLOT 2 TIME 41 (of 100) ]
[ time 149 ] Run JOB 2 at PRIORITY 1 [ TICKS 0 ALLOT 2 TIME 40 (of 100) ]
[ time 150 ] Run JOB 0 at PRIORITY 1 [ TICKS 9 ALLOT 2 TIME 429 (of 500) ]
[ time 151 ] Run JOB 0 at PRIORITY 1 [ TICKS 8 ALLOT 2 TIME 428 (of 500) ]
[ time 152 ] Run JOB 0 at PRIORITY 1 [ TICKS 7 ALLOT 2 TIME 427 (of 500) ]
[ time 153 ] Run JOB 0 at PRIORITY 1 [ TICKS 6 ALLOT 2 TIME 426 (of 500) ]
[ time 154 ] Run JOB 0 at PRIORITY 1 [ TICKS 5 ALLOT 2 TIME 425 (of 500) ]
[ time 155 ] Run JOB 0 at PRIORITY 1 [ TICKS 4 ALLOT 2 TIME 424 (of 500) ]
[ time 156 ] Run JOB 0 at PRIORITY 1 [ TICKS 3 ALLOT 2 TIME 423 (of 500) ]
[ time 157 ] Run JOB 0 at PRIORITY 1 [ TICKS 2 ALLOT 2 TIME 422 (of 500) ]
[ time 158 ] Run JOB 0 at PRIORITY 1 [ TICKS 1 ALLOT 2 TIME 421 (of 500) ]
[ time 159 ] Run JOB 0 at PRIORITY 1 [ TICKS 0 ALLOT 2 TIME 420 (of 500) ]
[ time 160 ] BOOST ( every 20 )
[ time 160 ] Run JOB 2 at PRIORITY 1 [ TICKS 9 ALLOT 2 TIME 39 (of 100) ]
[ time 161 ] Run JOB 2 at PRIORITY 1 [ TICKS 8 ALLOT 2 TIME 38 (of 100) ]
[ time 162 ] Run JOB 2 at PRIORITY 1 [ TICKS 7 ALLOT 2 TIME 37 (of 100) ]
[ time 163 ] Run JOB 2 at PRIORITY 1 [ TICKS 6 ALLOT 2 TIME 36 (of 100) ]
[ time 164 ] Run JOB 2 at PRIORITY 1 [ TICKS 5 ALLOT 2 TIME 35 (of 100) ]
[ time 165 ] Run JOB 2 at PRIORITY 1 [ TICKS 4 ALLOT 2 TIME 34 (of 100) ]
[ time 166 ] Run JOB 2 at PRIORITY 1 [ TICKS 3 ALLOT 2 TIME 33 (of 100) ]
[ time 167 ] Run JOB 2 at PRIORITY 1 [ TICKS 2 ALLOT 2 TIME 32 (of 100) ]
[ time 168 ] Run JOB 2 at PRIORITY 1 [ TICKS 1 ALLOT 2 TIME 31 (of 100) ]
[ time 169 ] Run JOB 2 at PRIORITY 1 [ TICKS 0 ALLOT 2 TIME 30 (of 100) ]
[ time 170 ] Run JOB 0 at PRIORITY 1 [ TICKS 9 ALLOT 2 TIME 419 (of 500) ]
[ time 171 ] Run JOB 0 at PRIORITY 1 [ TICKS 8 ALLOT 2 TIME 418 (of 500) ]
[ time 172 ] Run JOB 0 at PRIORITY 1 [ TICKS 7 ALLOT 2 TIME 417 (of 500) ]
[ time 173 ] Run JOB 0 at PRIORITY 1 [ TICKS 6 ALLOT 2 TIME 416 (of 500) ]
[ time 174 ] Run JOB 0 at PRIORITY 1 [ TICKS 5 ALLOT 2 TIME 415 (of 500) ]
[ time 175 ] Run JOB 0 at PRIORITY 1 [ TICKS 4 ALLOT 2 TIME 414 (of 500) ]
[ time 176 ] Run JOB 0 at PRIORITY 1 [ TICKS 3 ALLOT 2 TIME 413 (of 500) ]
[ time 177 ] Run JOB 0 at PRIORITY 1 [ TICKS 2 ALLOT 2 TIME 412 (of 500) ]
[ time 178 ] Run JOB 0 at PRIORITY 1 [ TICKS 1 ALLOT 2 TIME 411 (of 500) ]
[ time 179 ] Run JOB 0 at PRIORITY 1 [ TICKS 0 ALLOT 2 TIME 410 (of 500) ]
[ time 180 ] BOOST ( every 20 )
[ time 180 ] Run JOB 2 at PRIORITY 1 [ TICKS 9 ALLOT 2 TIME 29 (of 100) ]
[ time 181 ] Run JOB 2 at PRIORITY 1 [ TICKS 8 ALLOT 2 TIME 28 (of 100) ]
[ time 182 ] Run JOB 2 at PRIORITY 1 [ TICKS 7 ALLOT 2 TIME 27 (of 100) ]
[ time 183 ] Run JOB 2 at PRIORITY 1 [ TICKS 6 ALLOT 2 TIME 26 (of 100) ]
[ time 184 ] Run JOB 2 at PRIORITY 1 [ TICKS 5 ALLOT 2 TIME 25 (of 100) ]
[ time 185 ] Run JOB 2 at PRIORITY 1 [ TICKS 4 ALLOT 2 TIME 24 (of 100) ]
[ time 186 ] Run JOB 2 at PRIORITY 1 [ TICKS 3 ALLOT 2 TIME 23 (of 100) ]
[ time 187 ] Run JOB 2 at PRIORITY 1 [ TICKS 2 ALLOT 2 TIME 22 (of 100) ]
[ time 188 ] Run JOB 2 at PRIORITY 1 [ TICKS 1 ALLOT 2 TIME 21 (of 100) ]
[ time 189 ] Run JOB 2 at PRIORITY 1 [ TICKS 0 ALLOT 2 TIME 20 (of 100) ]
[ time 190 ] Run JOB 0 at PRIORITY 1 [ TICKS 9 ALLOT 2 TIME 409 (of 500) ]
[ time 191 ] Run JOB 0 at PRIORITY 1 [ TICKS 8 ALLOT 2 TIME 408 (of 500) ]
[ time 192 ] Run JOB 0 at PRIORITY 1 [ TICKS 7 ALLOT 2 TIME 407 (of 500) ]
[ time 193 ] Run JOB 0 at PRIORITY 1 [ TICKS 6 ALLOT 2 TIME 406 (of 500) ]
[ time 194 ] Run JOB 0 at PRIORITY 1 [ TICKS 5 ALLOT 2 TIME 405 (of 500) ]
[ time 195 ] Run JOB 0 at PRIORITY 1 [ TICKS 4 ALLOT 2 TIME 404 (of 500) ]
[ time 196 ] Run JOB 0 at PRIORITY 1 [ TICKS 3 ALLOT 2 TIME 403 (of 500) ]
[ time 197 ] Run JOB 0 at PRIORITY 1 [ TICKS 2 ALLOT 2 TIME 402 (of 500) ]
[ time 198 ] Run JOB 0 at PRIORITY 1 [ TICKS 1 ALLOT 2 TIME 401 (of 500) ]
[ time 199 ] Run JOB 0 at PRIORITY 1 [ TICKS 0 ALLOT 2 TIME 400 (of 500) ]
[ time 200 ] BOOST ( every 20 )
[ time 200 ] Run JOB 2 at PRIORITY 1 [ TICKS 9 ALLOT 2 TIME 19 (of 100) ]
[ time 201 ] Run JOB 2 at PRIORITY 1 [ TICKS 8 ALLOT 2 TIME 18 (of 100) ]
[ time 202 ] Run JOB 2 at PRIORITY 1 [ TICKS 7 ALLOT 2 TIME 17 (of 100) ]
[ time 203 ] Run JOB 2 at PRIORITY 1 [ TICKS 6 ALLOT 2 TIME 16 (of 100) ]
[ time 204 ] Run JOB 2 at PRIORITY 1 [ TICKS 5 ALLOT 2 TIME 15 (of 100) ]
[ time 205 ] Run JOB 2 at PRIORITY 1 [ TICKS 4 ALLOT 2 TIME 14 (of 100) ]
[ time 206 ] Run JOB 2 at PRIORITY 1 [ TICKS 3 ALLOT 2 TIME 13 (of 100) ]
[ time 207 ] Run JOB 2 at PRIORITY 1 [ TICKS 2 ALLOT 2 TIME 12 (of 100) ]
[ time 208 ] Run JOB 2 at PRIORITY 1 [ TICKS 1 ALLOT 2 TIME 11 (of 100) ]
[ time 209 ] Run JOB 2 at PRIORITY 1 [ TICKS 0 ALLOT 2 TIME 10 (of 100) ]
[ time 210 ] Run JOB 0 at PRIORITY 1 [ TICKS 9 ALLOT 2 TIME 399 (of 500) ]
[ time 211 ] Run JOB 0 at PRIORITY 1 [ TICKS 8 ALLOT 2 TIME 398 (of 500) ]
[ time 212 ] Run JOB 0 at PRIORITY 1 [ TICKS 7 ALLOT 2 TIME 397 (of 500) ]
[ time 213 ] Run JOB 0 at PRIORITY 1 [ TICKS 6 ALLOT 2 TIME 396 (of 500) ]
[ time 214 ] Run JOB 0 at PRIORITY 1 [ TICKS 5 ALLOT 2 TIME 395 (of 500) ]
[ time 215 ] Run JOB 0 at PRIORITY 1 [ TICKS 4 ALLOT 2 TIME 394 (of 500) ]
[ time 216 ] Run JOB 0 at PRIORITY 1 [ TICKS 3 ALLOT 2 TIME 393 (of 500) ]
[ time 217 ] Run JOB 0 at PRIORITY 1 [ TICKS 2 ALLOT 2 TIME 392 (of 500) ]
[ time 218 ] Run JOB 0 at PRIORITY 1 [ TICKS 1 ALLOT 2 TIME 391 (of 500) ]
[ time 219 ] Run JOB 0 at PRIORITY 1 [ TICKS 0 ALLOT 2 TIME 390 (of 500) ]
[ time 220 ] BOOST ( every 20 )
[ time 220 ] Run JOB 2 at PRIORITY 1 [ TICKS 9 ALLOT 2 TIME 9 (of 100) ]
[ time 221 ] Run JOB 2 at PRIORITY 1 [ TICKS 8 ALLOT 2 TIME 8 (of 100) ]
[ time 222 ] Run JOB 2 at PRIORITY 1 [ TICKS 7 ALLOT 2 TIME 7 (of 100) ]
[ time 223 ] Run JOB 2 at PRIORITY 1 [ TICKS 6 ALLOT 2 TIME 6 (of 100) ]
[ time 224 ] Run JOB 2 at PRIORITY 1 [ TICKS 5 ALLOT 2 TIME 5 (of 100) ]
[ time 225 ] Run JOB 2 at PRIORITY 1 [ TICKS 4 ALLOT 2 TIME 4 (of 100) ]
[ time 226 ] Run JOB 2 at PRIORITY 1 [ TICKS 3 ALLOT 2 TIME 3 (of 100) ]
[ time 227 ] Run JOB 2 at PRIORITY 1 [ TICKS 2 ALLOT 2 TIME 2 (of 100) ]
[ time 228 ] Run JOB 2 at PRIORITY 1 [ TICKS 1 ALLOT 2 TIME 1 (of 100) ]
[ time 229 ] Run JOB 2 at PRIORITY 1 [ TICKS 0 ALLOT 2 TIME 0 (of 100) ]
[ time 230 ] FINISHED JOB 2
[ time 230 ] Run JOB 0 at PRIORITY 1 [ TICKS 9 ALLOT 2 TIME 389 (of 500) ]
[ time 231 ] Run JOB 0 at PRIORITY 1 [ TICKS 8 ALLOT 2 TIME 388 (of 500) ]
[ time 232 ] Run JOB 0 at PRIORITY 1 [ TICKS 7 ALLOT 2 TIME 387 (of 500) ]
[ time 233 ] Run JOB 0 at PRIORITY 1 [ TICKS 6 ALLOT 2 TIME 386 (of 500) ]
[ time 234 ] Run JOB 0 at PRIORITY 1 [ TICKS 5 ALLOT 2 TIME 385 (of 500) ]
[ time 235 ] Run JOB 0 at PRIORITY 1 [ TICKS 4 ALLOT 2 TIME 384 (of 500) ]
[ time 236 ] Run JOB 0 at PRIORITY 1 [ TICKS 3 ALLOT 2 TIME 383 (of 500) ]
[ time 237 ] Run JOB 0 at PRIORITY 1 [ TICKS 2 ALLOT 2 TIME 382 (of 500) ]
[ time 238 ] Run JOB 0 at PRIORITY 1 [ TICKS 1 ALLOT 2 TIME 381 (of 500) ]
[ time 239 ] Run JOB 0 at PRIORITY 1 [ TICKS 0 ALLOT 2 TIME 380 (of 500) ]
[ time 240 ] BOOST ( every 20 )
[ time 240 ] Run JOB 0 at PRIORITY 1 [ TICKS 9 ALLOT 2 TIME 379 (of 500) ]
[ time 241 ] Run JOB 0 at PRIORITY 1 [ TICKS 8 ALLOT 2 TIME 378 (of 500) ]
[ time 242 ] Run JOB 0 at PRIORITY 1 [ TICKS 7 ALLOT 2 TIME 377 (of 500) ]
[ time 243 ] Run JOB 0 at PRIORITY 1 [ TICKS 6 ALLOT 2 TIME 376 (of 500) ]
[ time 244 ] Run JOB 0 at PRIORITY 1 [ TICKS 5 ALLOT 2 TIME 375 (of 500) ]
[ time 245 ] Run JOB 0 at PRIORITY 1 [ TICKS 4 ALLOT 2 TIME 374 (of 500) ]
[ time 246 ] Run JOB 0 at PRIORITY 1 [ TICKS 3 ALLOT 2 TIME 373 (of 500) ]
[ time 247 ] Run JOB 0 at PRIORITY 1 [ TICKS 2 ALLOT 2 TIME 372 (of 500) ]
[ time 248 ] Run JOB 0 at PRIORITY 1 [ TICKS 1 ALLOT 2 TIME 371 (of 500) ]
[ time 249 ] Run JOB 0 at PRIORITY 1 [ TICKS 0 ALLOT 2 TIME 370 (of 500) ]
[ time 250 ] Run JOB 0 at PRIORITY 1 [ TICKS 9 ALLOT 1 TIME 369 (of 500) ]
[ time 251 ] Run JOB 0 at PRIORITY 1 [ TICKS 8 ALLOT 1 TIME 368 (of 500) ]
[ time 252 ] Run JOB 0 at PRIORITY 1 [ TICKS 7 ALLOT 1 TIME 367 (of 500) ]
[ time 253 ] Run JOB 0 at PRIORITY 1 [ TICKS 6 ALLOT 1 TIME 366 (of 500) ]
[ time 254 ] Run JOB 0 at PRIORITY 1 [ TICKS 5 ALLOT 1 TIME 365 (of 500) ]
[ time 255 ] Run JOB 0 at PRIORITY 1 [ TICKS 4 ALLOT 1 TIME 364 (of 500) ]
[ time 256 ] Run JOB 0 at PRIORITY 1 [ TICKS 3 ALLOT 1 TIME 363 (of 500) ]
[ time 257 ] Run JOB 0 at PRIORITY 1 [ TICKS 2 ALLOT 1 TIME 362 (of 500) ]
[ time 258 ] Run JOB 0 at PRIORITY 1 [ TICKS 1 ALLOT 1 TIME 361 (of 500) ]
[ time 259 ] Run JOB 0 at PRIORITY 1 [ TICKS 0 ALLOT 1 TIME 360 (of 500) ]
[ time 260 ] BOOST ( every 20 )
[ time 260 ] Run JOB 0 at PRIORITY 1 [ TICKS 9 ALLOT 2 TIME 359 (of 500) ]
[ time 261 ] Run JOB 0 at PRIORITY 1 [ TICKS 8 ALLOT 2 TIME 358 (of 500) ]
[ time 262 ] Run JOB 0 at PRIORITY 1 [ TICKS 7 ALLOT 2 TIME 357 (of 500) ]
[ time 263 ] Run JOB 0 at PRIORITY 1 [ TICKS 6 ALLOT 2 TIME 356 (of 500) ]
[ time 264 ] Run JOB 0 at PRIORITY 1 [ TICKS 5 ALLOT 2 TIME 355 (of 500) ]
[ time 265 ] Run JOB 0 at PRIORITY 1 [ TICKS 4 ALLOT 2 TIME 354 (of 500) ]
[ time 266 ] Run JOB 0 at PRIORITY 1 [ TICKS 3 ALLOT 2 TIME 353 (of 500) ]
[ time 267 ] Run JOB 0 at PRIORITY 1 [ TICKS 2 ALLOT 2 TIME 352 (of 500) ]
[ time 268 ] Run JOB 0 at PRIORITY 1 [ TICKS 1 ALLOT 2 TIME 351 (of 500) ]
[ time 269 ] Run JOB 0 at PRIORITY 1 [ TICKS 0 ALLOT 2 TIME 350 (of 500) ]
[ time 270 ] Run JOB 0 at PRIORITY 1 [ TICKS 9 ALLOT 1 TIME 349 (of 500) ]
[ time 271 ] Run JOB 0 at PRIORITY 1 [ TICKS 8 ALLOT 1 TIME 348 (of 500) ]
[ time 272 ] Run JOB 0 at PRIORITY 1 [ TICKS 7 ALLOT 1 TIME 347 (of 500) ]
[ time 273 ] Run JOB 0 at PRIORITY 1 [ TICKS 6 ALLOT 1 TIME 346 (of 500) ]
[ time 274 ] Run JOB 0 at PRIORITY 1 [ TICKS 5 ALLOT 1 TIME 345 (of 500) ]
[ time 275 ] Run JOB 0 at PRIORITY 1 [ TICKS 4 ALLOT 1 TIME 344 (of 500) ]
[ time 276 ] Run JOB 0 at PRIORITY 1 [ TICKS 3 ALLOT 1 TIME 343 (of 500) ]
[ time 277 ] Run JOB 0 at PRIORITY 1 [ TICKS 2 ALLOT 1 TIME 342 (of 500) ]
[ time 278 ] Run JOB 0 at PRIORITY 1 [ TICKS 1 ALLOT 1 TIME 341 (of 500) ]
[ time 279 ] Run JOB 0 at PRIORITY 1 [ TICKS 0 ALLOT 1 TIME 340 (of 500) ]
[ time 280 ] BOOST ( every 20 )
[ time 280 ] Run JOB 0 at PRIORITY 1 [ TICKS 9 ALLOT 2 TIME 339 (of 500) ]
[ time 281 ] Run JOB 0 at PRIORITY 1 [ TICKS 8 ALLOT 2 TIME 338 (of 500) ]
[ time 282 ] Run JOB 0 at PRIORITY 1 [ TICKS 7 ALLOT 2 TIME 337 (of 500) ]
[ time 283 ] Run JOB 0 at PRIORITY 1 [ TICKS 6 ALLOT 2 TIME 336 (of 500) ]
[ time 284 ] Run JOB 0 at PRIORITY 1 [ TICKS 5 ALLOT 2 TIME 335 (of 500) ]
[ time 285 ] Run JOB 0 at PRIORITY 1 [ TICKS 4 ALLOT 2 TIME 334 (of 500) ]
[ time 286 ] Run JOB 0 at PRIORITY 1 [ TICKS 3 ALLOT 2 TIME 333 (of 500) ]
[ time 287 ] Run JOB 0 at PRIORITY 1 [ TICKS 2 ALLOT 2 TIME 332 (of 500) ]
[ time 288 ] Run JOB 0 at PRIORITY 1 [ TICKS 1 ALLOT 2 TIME 331 (of 500) ]
[ time 289 ] Run JOB 0 at PRIORITY 1 [ TICKS 0 ALLOT 2 TIME 330 (of 500) ]
[ time 290 ] Run JOB 0 at PRIORITY 1 [ TICKS 9 ALLOT 1 TIME 329 (of 500) ]
[ time 291 ] Run JOB 0 at PRIORITY 1 [ TICKS 8 ALLOT 1 TIME 328 (of 500) ]
[ time 292 ] Run JOB 0 at PRIORITY 1 [ TICKS 7 ALLOT 1 TIME 327 (of 500) ]
[ time 293 ] Run JOB 0 at PRIORITY 1 [ TICKS 6 ALLOT 1 TIME 326 (of 500) ]
[ time 294 ] Run JOB 0 at PRIORITY 1 [ TICKS 5 ALLOT 1 TIME 325 (of 500) ]
[ time 295 ] Run JOB 0 at PRIORITY 1 [ TICKS 4 ALLOT 1 TIME 324 (of 500) ]
[ time 296 ] Run JOB 0 at PRIORITY 1 [ TICKS 3 ALLOT 1 TIME 323 (of 500) ]
[ time 297 ] Run JOB 0 at PRIORITY 1 [ TICKS 2 ALLOT 1 TIME 322 (of 500) ]
[ time 298 ] Run JOB 0 at PRIORITY 1 [ TICKS 1 ALLOT 1 TIME 321 (of 500) ]
[ time 299 ] Run JOB 0 at PRIORITY 1 [ TICKS 0 ALLOT 1 TIME 320 (of 500) ]
[ time 300 ] BOOST ( every 20 )
[ time 300 ] Run JOB 0 at PRIORITY 1 [ TICKS 9 ALLOT 2 TIME 319 (of 500) ]
[ time 301 ] Run JOB 0 at PRIORITY 1 [ TICKS 8 ALLOT 2 TIME 318 (of 500) ]
[ time 302 ] Run JOB 0 at PRIORITY 1 [ TICKS 7 ALLOT 2 TIME 317 (of 500) ]
[ time 303 ] Run JOB 0 at PRIORITY 1 [ TICKS 6 ALLOT 2 TIME 316 (of 500) ]
[ time 304 ] Run JOB 0 at PRIORITY 1 [ TICKS 5 ALLOT 2 TIME 315 (of 500) ]
[ time 305 ] Run JOB 0 at PRIORITY 1 [ TICKS 4 ALLOT 2 TIME 314 (of 500) ]
[ time 306 ] Run JOB 0 at PRIORITY 1 [ TICKS 3 ALLOT 2 TIME 313 (of 500) ]
[ time 307 ] Run JOB 0 at PRIORITY 1 [ TICKS 2 ALLOT 2 TIME 312 (of 500) ]
[ time 308 ] Run JOB 0 at PRIORITY 1 [ TICKS 1 ALLOT 2 TIME 311 (of 500) ]
[ time 309 ] Run JOB 0 at PRIORITY 1 [ TICKS 0 ALLOT 2 TIME 310 (of 500) ]
[ time 310 ] Run JOB 0 at PRIORITY 1 [ TICKS 9 ALLOT 1 TIME 309 (of 500) ]
[ time 311 ] Run JOB 0 at PRIORITY 1 [ TICKS 8 ALLOT 1 TIME 308 (of 500) ]
[ time 312 ] Run JOB 0 at PRIORITY 1 [ TICKS 7 ALLOT 1 TIME 307 (of 500) ]
[ time 313 ] Run JOB 0 at PRIORITY 1 [ TICKS 6 ALLOT 1 TIME 306 (of 500) ]
[ time 314 ] Run JOB 0 at PRIORITY 1 [ TICKS 5 ALLOT 1 TIME 305 (of 500) ]
[ time 315 ] Run JOB 0 at PRIORITY 1 [ TICKS 4 ALLOT 1 TIME 304 (of 500) ]
[ time 316 ] Run JOB 0 at PRIORITY 1 [ TICKS 3 ALLOT 1 TIME 303 (of 500) ]
[ time 317 ] Run JOB 0 at PRIORITY 1 [ TICKS 2 ALLOT 1 TIME 302 (of 500) ]
[ time 318 ] Run JOB 0 at PRIORITY 1 [ TICKS 1 ALLOT 1 TIME 301 (of 500) ]
[ time 319 ] Run JOB 0 at PRIORITY 1 [ TICKS 0 ALLOT 1 TIME 300 (of 500) ]
[ time 320 ] BOOST ( every 20 )
[ time 320 ] Run JOB 0 at PRIORITY 1 [ TICKS 9 ALLOT 2 TIME 299 (of 500) ]
[ time 321 ] Run JOB 0 at PRIORITY 1 [ TICKS 8 ALLOT 2 TIME 298 (of 500) ]
[ time 322 ] Run JOB 0 at PRIORITY 1 [ TICKS 7 ALLOT 2 TIME 297 (of 500) ]
[ time 323 ] Run JOB 0 at PRIORITY 1 [ TICKS 6 ALLOT 2 TIME 296 (of 500) ]
[ time 324 ] Run JOB 0 at PRIORITY 1 [ TICKS 5 ALLOT 2 TIME 295 (of 500) ]
[ time 325 ] Run JOB 0 at PRIORITY 1 [ TICKS 4 ALLOT 2 TIME 294 (of 500) ]
[ time 326 ] Run JOB 0 at PRIORITY 1 [ TICKS 3 ALLOT 2 TIME 293 (of 500) ]
[ time 327 ] Run JOB 0 at PRIORITY 1 [ TICKS 2 ALLOT 2 TIME 292 (of 500) ]
[ time 328 ] Run JOB 0 at PRIORITY 1 [ TICKS 1 ALLOT 2 TIME 291 (of 500) ]
[ time 329 ] Run JOB 0 at PRIORITY 1 [ TICKS 0 ALLOT 2 TIME 290 (of 500) ]
[ time 330 ] Run JOB 0 at PRIORITY 1 [ TICKS 9 ALLOT 1 TIME 289 (of 500) ]
[ time 331 ] Run JOB 0 at PRIORITY 1 [ TICKS 8 ALLOT 1 TIME 288 (of 500) ]
[ time 332 ] Run JOB 0 at PRIORITY 1 [ TICKS 7 ALLOT 1 TIME 287 (of 500) ]
[ time 333 ] Run JOB 0 at PRIORITY 1 [ TICKS 6 ALLOT 1 TIME 286 (of 500) ]
[ time 334 ] Run JOB 0 at PRIORITY 1 [ TICKS 5 ALLOT 1 TIME 285 (of 500) ]
[ time 335 ] Run JOB 0 at PRIORITY 1 [ TICKS 4 ALLOT 1 TIME 284 (of 500) ]
[ time 336 ] Run JOB 0 at PRIORITY 1 [ TICKS 3 ALLOT 1 TIME 283 (of 500) ]
[ time 337 ] Run JOB 0 at PRIORITY 1 [ TICKS 2 ALLOT 1 TIME 282 (of 500) ]
[ time 338 ] Run JOB 0 at PRIORITY 1 [ TICKS 1 ALLOT 1 TIME 281 (of 500) ]
[ time 339 ] Run JOB 0 at PRIORITY 1 [ TICKS 0 ALLOT 1 TIME 280 (of 500) ]
[ time 340 ] BOOST ( every 20 )
[ time 340 ] Run JOB 0 at PRIORITY 1 [ TICKS 9 ALLOT 2 TIME 279 (of 500) ]
[ time 341 ] Run JOB 0 at PRIORITY 1 [ TICKS 8 ALLOT 2 TIME 278 (of 500) ]
[ time 342 ] Run JOB 0 at PRIORITY 1 [ TICKS 7 ALLOT 2 TIME 277 (of 500) ]
[ time 343 ] Run JOB 0 at PRIORITY 1 [ TICKS 6 ALLOT 2 TIME 276 (of 500) ]
[ time 344 ] Run JOB 0 at PRIORITY 1 [ TICKS 5 ALLOT 2 TIME 275 (of 500) ]
[ time 345 ] Run JOB 0 at PRIORITY 1 [ TICKS 4 ALLOT 2 TIME 274 (of 500) ]
[ time 346 ] Run JOB 0 at PRIORITY 1 [ TICKS 3 ALLOT 2 TIME 273 (of 500) ]
[ time 347 ] Run JOB 0 at PRIORITY 1 [ TICKS 2 ALLOT 2 TIME 272 (of 500) ]
[ time 348 ] Run JOB 0 at PRIORITY 1 [ TICKS 1 ALLOT 2 TIME 271 (of 500) ]
[ time 349 ] Run JOB 0 at PRIORITY 1 [ TICKS 0 ALLOT 2 TIME 270 (of 500) ]
[ time 350 ] Run JOB 0 at PRIORITY 1 [ TICKS 9 ALLOT 1 TIME 269 (of 500) ]
[ time 351 ] Run JOB 0 at PRIORITY 1 [ TICKS 8 ALLOT 1 TIME 268 (of 500) ]
[ time 352 ] Run JOB 0 at PRIORITY 1 [ TICKS 7 ALLOT 1 TIME 267 (of 500) ]
[ time 353 ] Run JOB 0 at PRIORITY 1 [ TICKS 6 ALLOT 1 TIME 266 (of 500) ]
[ time 354 ] Run JOB 0 at PRIORITY 1 [ TICKS 5 ALLOT 1 TIME 265 (of 500) ]
[ time 355 ] Run JOB 0 at PRIORITY 1 [ TICKS 4 ALLOT 1 TIME 264 (of 500) ]
[ time 356 ] Run JOB 0 at PRIORITY 1 [ TICKS 3 ALLOT 1 TIME 263 (of 500) ]
[ time 357 ] Run JOB 0 at PRIORITY 1 [ TICKS 2 ALLOT 1 TIME 262 (of 500) ]
[ time 358 ] Run JOB 0 at PRIORITY 1 [ TICKS 1 ALLOT 1 TIME 261 (of 500) ]
[ time 359 ] Run JOB 0 at PRIORITY 1 [ TICKS 0 ALLOT 1 TIME 260 (of 500) ]
[ time 360 ] BOOST ( every 20 )
[ time 360 ] Run JOB 0 at PRIORITY 1 [ TICKS 9 ALLOT 2 TIME 259 (of 500) ]
[ time 361 ] Run JOB 0 at PRIORITY 1 [ TICKS 8 ALLOT 2 TIME 258 (of 500) ]
[ time 362 ] Run JOB 0 at PRIORITY 1 [ TICKS 7 ALLOT 2 TIME 257 (of 500) ]
[ time 363 ] Run JOB 0 at PRIORITY 1 [ TICKS 6 ALLOT 2 TIME 256 (of 500) ]
[ time 364 ] Run JOB 0 at PRIORITY 1 [ TICKS 5 ALLOT 2 TIME 255 (of 500) ]
[ time 365 ] Run JOB 0 at PRIORITY 1 [ TICKS 4 ALLOT 2 TIME 254 (of 500) ]
[ time 366 ] Run JOB 0 at PRIORITY 1 [ TICKS 3 ALLOT 2 TIME 253 (of 500) ]
[ time 367 ] Run JOB 0 at PRIORITY 1 [ TICKS 2 ALLOT 2 TIME 252 (of 500) ]
[ time 368 ] Run JOB 0 at PRIORITY 1 [ TICKS 1 ALLOT 2 TIME 251 (of 500) ]
[ time 369 ] Run JOB 0 at PRIORITY 1 [ TICKS 0 ALLOT 2 TIME 250 (of 500) ]
[ time 370 ] Run JOB 0 at PRIORITY 1 [ TICKS 9 ALLOT 1 TIME 249 (of 500) ]
[ time 371 ] Run JOB 0 at PRIORITY 1 [ TICKS 8 ALLOT 1 TIME 248 (of 500) ]
[ time 372 ] Run JOB 0 at PRIORITY 1 [ TICKS 7 ALLOT 1 TIME 247 (of 500) ]
[ time 373 ] Run JOB 0 at PRIORITY 1 [ TICKS 6 ALLOT 1 TIME 246 (of 500) ]
[ time 374 ] Run JOB 0 at PRIORITY 1 [ TICKS 5 ALLOT 1 TIME 245 (of 500) ]
[ time 375 ] Run JOB 0 at PRIORITY 1 [ TICKS 4 ALLOT 1 TIME 244 (of 500) ]
[ time 376 ] Run JOB 0 at PRIORITY 1 [ TICKS 3 ALLOT 1 TIME 243 (of 500) ]
[ time 377 ] Run JOB 0 at PRIORITY 1 [ TICKS 2 ALLOT 1 TIME 242 (of 500) ]
[ time 378 ] Run JOB 0 at PRIORITY 1 [ TICKS 1 ALLOT 1 TIME 241 (of 500) ]
[ time 379 ] Run JOB 0 at PRIORITY 1 [ TICKS 0 ALLOT 1 TIME 240 (of 500) ]
[ time 380 ] BOOST ( every 20 )
[ time 380 ] Run JOB 0 at PRIORITY 1 [ TICKS 9 ALLOT 2 TIME 239 (of 500) ]
[ time 381 ] Run JOB 0 at PRIORITY 1 [ TICKS 8 ALLOT 2 TIME 238 (of 500) ]
[ time 382 ] Run JOB 0 at PRIORITY 1 [ TICKS 7 ALLOT 2 TIME 237 (of 500) ]
[ time 383 ] Run JOB 0 at PRIORITY 1 [ TICKS 6 ALLOT 2 TIME 236 (of 500) ]
[ time 384 ] Run JOB 0 at PRIORITY 1 [ TICKS 5 ALLOT 2 TIME 235 (of 500) ]
[ time 385 ] Run JOB 0 at PRIORITY 1 [ TICKS 4 ALLOT 2 TIME 234 (of 500) ]
[ time 386 ] Run JOB 0 at PRIORITY 1 [ TICKS 3 ALLOT 2 TIME 233 (of 500) ]
[ time 387 ] Run JOB 0 at PRIORITY 1 [ TICKS 2 ALLOT 2 TIME 232 (of 500) ]
[ time 388 ] Run JOB 0 at PRIORITY 1 [ TICKS 1 ALLOT 2 TIME 231 (of 500) ]
[ time 389 ] Run JOB 0 at PRIORITY 1 [ TICKS 0 ALLOT 2 TIME 230 (of 500) ]
[ time 390 ] Run JOB 0 at PRIORITY 1 [ TICKS 9 ALLOT 1 TIME 229 (of 500) ]
[ time 391 ] Run JOB 0 at PRIORITY 1 [ TICKS 8 ALLOT 1 TIME 228 (of 500) ]
[ time 392 ] Run JOB 0 at PRIORITY 1 [ TICKS 7 ALLOT 1 TIME 227 (of 500) ]
[ time 393 ] Run JOB 0 at PRIORITY 1 [ TICKS 6 ALLOT 1 TIME 226 (of 500) ]
[ time 394 ] Run JOB 0 at PRIORITY 1 [ TICKS 5 ALLOT 1 TIME 225 (of 500) ]
[ time 395 ] Run JOB 0 at PRIORITY 1 [ TICKS 4 ALLOT 1 TIME 224 (of 500) ]
[ time 396 ] Run JOB 0 at PRIORITY 1 [ TICKS 3 ALLOT 1 TIME 223 (of 500) ]
[ time 397 ] Run JOB 0 at PRIORITY 1 [ TICKS 2 ALLOT 1 TIME 222 (of 500) ]
[ time 398 ] Run JOB 0 at PRIORITY 1 [ TICKS 1 ALLOT 1 TIME 221 (of 500) ]
[ time 399 ] Run JOB 0 at PRIORITY 1 [ TICKS 0 ALLOT 1 TIME 220 (of 500) ]
[ time 400 ] BOOST ( every 20 )
[ time 400 ] Run JOB 0 at PRIORITY 1 [ TICKS 9 ALLOT 2 TIME 219 (of 500) ]
[ time 401 ] Run JOB 0 at PRIORITY 1 [ TICKS 8 ALLOT 2 TIME 218 (of 500) ]
[ time 402 ] Run JOB 0 at PRIORITY 1 [ TICKS 7 ALLOT 2 TIME 217 (of 500) ]
[ time 403 ] Run JOB 0 at PRIORITY 1 [ TICKS 6 ALLOT 2 TIME 216 (of 500) ]
[ time 404 ] Run JOB 0 at PRIORITY 1 [ TICKS 5 ALLOT 2 TIME 215 (of 500) ]
[ time 405 ] Run JOB 0 at PRIORITY 1 [ TICKS 4 ALLOT 2 TIME 214 (of 500) ]
[ time 406 ] Run JOB 0 at PRIORITY 1 [ TICKS 3 ALLOT 2 TIME 213 (of 500) ]
[ time 407 ] Run JOB 0 at PRIORITY 1 [ TICKS 2 ALLOT 2 TIME 212 (of 500) ]
[ time 408 ] Run JOB 0 at PRIORITY 1 [ TICKS 1 ALLOT 2 TIME 211 (of 500) ]
[ time 409 ] Run JOB 0 at PRIORITY 1 [ TICKS 0 ALLOT 2 TIME 210 (of 500) ]
[ time 410 ] Run JOB 0 at PRIORITY 1 [ TICKS 9 ALLOT 1 TIME 209 (of 500) ]
[ time 411 ] Run JOB 0 at PRIORITY 1 [ TICKS 8 ALLOT 1 TIME 208 (of 500) ]
[ time 412 ] Run JOB 0 at PRIORITY 1 [ TICKS 7 ALLOT 1 TIME 207 (of 500) ]
[ time 413 ] Run JOB 0 at PRIORITY 1 [ TICKS 6 ALLOT 1 TIME 206 (of 500) ]
[ time 414 ] Run JOB 0 at PRIORITY 1 [ TICKS 5 ALLOT 1 TIME 205 (of 500) ]
[ time 415 ] Run JOB 0 at PRIORITY 1 [ TICKS 4 ALLOT 1 TIME 204 (of 500) ]
[ time 416 ] Run JOB 0 at PRIORITY 1 [ TICKS 3 ALLOT 1 TIME 203 (of 500) ]
[ time 417 ] Run JOB 0 at PRIORITY 1 [ TICKS 2 ALLOT 1 TIME 202 (of 500) ]
[ time 418 ] Run JOB 0 at PRIORITY 1 [ TICKS 1 ALLOT 1 TIME 201 (of 500) ]
[ time 419 ] Run JOB 0 at PRIORITY 1 [ TICKS 0 ALLOT 1 TIME 200 (of 500) ]
[ time 420 ] BOOST ( every 20 )
[ time 420 ] Run JOB 0 at PRIORITY 1 [ TICKS 9 ALLOT 2 TIME 199 (of 500) ]
[ time 421 ] Run JOB 0 at PRIORITY 1 [ TICKS 8 ALLOT 2 TIME 198 (of 500) ]
[ time 422 ] Run JOB 0 at PRIORITY 1 [ TICKS 7 ALLOT 2 TIME 197 (of 500) ]
[ time 423 ] Run JOB 0 at PRIORITY 1 [ TICKS 6 ALLOT 2 TIME 196 (of 500) ]
[ time 424 ] Run JOB 0 at PRIORITY 1 [ TICKS 5 ALLOT 2 TIME 195 (of 500) ]
[ time 425 ] Run JOB 0 at PRIORITY 1 [ TICKS 4 ALLOT 2 TIME 194 (of 500) ]
[ time 426 ] Run JOB 0 at PRIORITY 1 [ TICKS 3 ALLOT 2 TIME 193 (of 500) ]
[ time 427 ] Run JOB 0 at PRIORITY 1 [ TICKS 2 ALLOT 2 TIME 192 (of 500) ]
[ time 428 ] Run JOB 0 at PRIORITY 1 [ TICKS 1 ALLOT 2 TIME 191 (of 500) ]
[ time 429 ] Run JOB 0 at PRIORITY 1 [ TICKS 0 ALLOT 2 TIME 190 (of 500) ]
[ time 430 ] Run JOB 0 at PRIORITY 1 [ TICKS 9 ALLOT 1 TIME 189 (of 500) ]
[ time 431 ] Run JOB 0 at PRIORITY 1 [ TICKS 8 ALLOT 1 TIME 188 (of 500) ]
[ time 432 ] Run JOB 0 at PRIORITY 1 [ TICKS 7 ALLOT 1 TIME 187 (of 500) ]
[ time 433 ] Run JOB 0 at PRIORITY 1 [ TICKS 6 ALLOT 1 TIME 186 (of 500) ]
[ time 434 ] Run JOB 0 at PRIORITY 1 [ TICKS 5 ALLOT 1 TIME 185 (of 500) ]
[ time 435 ] Run JOB 0 at PRIORITY 1 [ TICKS 4 ALLOT 1 TIME 184 (of 500) ]
[ time 436 ] Run JOB 0 at PRIORITY 1 [ TICKS 3 ALLOT 1 TIME 183 (of 500) ]
[ time 437 ] Run JOB 0 at PRIORITY 1 [ TICKS 2 ALLOT 1 TIME 182 (of 500) ]
[ time 438 ] Run JOB 0 at PRIORITY 1 [ TICKS 1 ALLOT 1 TIME 181 (of 500) ]
[ time 439 ] Run JOB 0 at PRIORITY 1 [ TICKS 0 ALLOT 1 TIME 180 (of 500) ]
[ time 440 ] BOOST ( every 20 )
[ time 440 ] Run JOB 0 at PRIORITY 1 [ TICKS 9 ALLOT 2 TIME 179 (of 500) ]
[ time 441 ] Run JOB 0 at PRIORITY 1 [ TICKS 8 ALLOT 2 TIME 178 (of 500) ]
[ time 442 ] Run JOB 0 at PRIORITY 1 [ TICKS 7 ALLOT 2 TIME 177 (of 500) ]
[ time 443 ] Run JOB 0 at PRIORITY 1 [ TICKS 6 ALLOT 2 TIME 176 (of 500) ]
[ time 444 ] Run JOB 0 at PRIORITY 1 [ TICKS 5 ALLOT 2 TIME 175 (of 500) ]
[ time 445 ] Run JOB 0 at PRIORITY 1 [ TICKS 4 ALLOT 2 TIME 174 (of 500) ]
[ time 446 ] Run JOB 0 at PRIORITY 1 [ TICKS 3 ALLOT 2 TIME 173 (of 500) ]
[ time 447 ] Run JOB 0 at PRIORITY 1 [ TICKS 2 ALLOT 2 TIME 172 (of 500) ]
[ time 448 ] Run JOB 0 at PRIORITY 1 [ TICKS 1 ALLOT 2 TIME 171 (of 500) ]
[ time 449 ] Run JOB 0 at PRIORITY 1 [ TICKS 0 ALLOT 2 TIME 170 (of 500) ]
[ time 450 ] Run JOB 0 at PRIORITY 1 [ TICKS 9 ALLOT 1 TIME 169 (of 500) ]
[ time 451 ] Run JOB 0 at PRIORITY 1 [ TICKS 8 ALLOT 1 TIME 168 (of 500) ]
[ time 452 ] Run JOB 0 at PRIORITY 1 [ TICKS 7 ALLOT 1 TIME 167 (of 500) ]
[ time 453 ] Run JOB 0 at PRIORITY 1 [ TICKS 6 ALLOT 1 TIME 166 (of 500) ]
[ time 454 ] Run JOB 0 at PRIORITY 1 [ TICKS 5 ALLOT 1 TIME 165 (of 500) ]
[ time 455 ] Run JOB 0 at PRIORITY 1 [ TICKS 4 ALLOT 1 TIME 164 (of 500) ]
[ time 456 ] Run JOB 0 at PRIORITY 1 [ TICKS 3 ALLOT 1 TIME 163 (of 500) ]
[ time 457 ] Run JOB 0 at PRIORITY 1 [ TICKS 2 ALLOT 1 TIME 162 (of 500) ]
[ time 458 ] Run JOB 0 at PRIORITY 1 [ TICKS 1 ALLOT 1 TIME 161 (of 500) ]
[ time 459 ] Run JOB 0 at PRIORITY 1 [ TICKS 0 ALLOT 1 TIME 160 (of 500) ]
[ time 460 ] BOOST ( every 20 )
[ time 460 ] Run JOB 0 at PRIORITY 1 [ TICKS 9 ALLOT 2 TIME 159 (of 500) ]
[ time 461 ] Run JOB 0 at PRIORITY 1 [ TICKS 8 ALLOT 2 TIME 158 (of 500) ]
[ time 462 ] Run JOB 0 at PRIORITY 1 [ TICKS 7 ALLOT 2 TIME 157 (of 500) ]
[ time 463 ] Run JOB 0 at PRIORITY 1 [ TICKS 6 ALLOT 2 TIME 156 (of 500) ]
[ time 464 ] Run JOB 0 at PRIORITY 1 [ TICKS 5 ALLOT 2 TIME 155 (of 500) ]
[ time 465 ] Run JOB 0 at PRIORITY 1 [ TICKS 4 ALLOT 2 TIME 154 (of 500) ]
[ time 466 ] Run JOB 0 at PRIORITY 1 [ TICKS 3 ALLOT 2 TIME 153 (of 500) ]
[ time 467 ] Run JOB 0 at PRIORITY 1 [ TICKS 2 ALLOT 2 TIME 152 (of 500) ]
[ time 468 ] Run JOB 0 at PRIORITY 1 [ TICKS 1 ALLOT 2 TIME 151 (of 500) ]
[ time 469 ] Run JOB 0 at PRIORITY 1 [ TICKS 0 ALLOT 2 TIME 150 (of 500) ]
[ time 470 ] Run JOB 0 at PRIORITY 1 [ TICKS 9 ALLOT 1 TIME 149 (of 500) ]
[ time 471 ] Run JOB 0 at PRIORITY 1 [ TICKS 8 ALLOT 1 TIME 148 (of 500) ]
[ time 472 ] Run JOB 0 at PRIORITY 1 [ TICKS 7 ALLOT 1 TIME 147 (of 500) ]
[ time 473 ] Run JOB 0 at PRIORITY 1 [ TICKS 6 ALLOT 1 TIME 146 (of 500) ]
[ time 474 ] Run JOB 0 at PRIORITY 1 [ TICKS 5 ALLOT 1 TIME 145 (of 500) ]
[ time 475 ] Run JOB 0 at PRIORITY 1 [ TICKS 4 ALLOT 1 TIME 144 (of 500) ]
[ time 476 ] Run JOB 0 at PRIORITY 1 [ TICKS 3 ALLOT 1 TIME 143 (of 500) ]
[ time 477 ] Run JOB 0 at PRIORITY 1 [ TICKS 2 ALLOT 1 TIME 142 (of 500) ]
[ time 478 ] Run JOB 0 at PRIORITY 1 [ TICKS 1 ALLOT 1 TIME 141 (of 500) ]
[ time 479 ] Run JOB 0 at PRIORITY 1 [ TICKS 0 ALLOT 1 TIME 140 (of 500) ]
[ time 480 ] BOOST ( every 20 )
[ time 480 ] Run JOB 0 at PRIORITY 1 [ TICKS 9 ALLOT 2 TIME 139 (of 500) ]
[ time 481 ] Run JOB 0 at PRIORITY 1 [ TICKS 8 ALLOT 2 TIME 138 (of 500) ]
[ time 482 ] Run JOB 0 at PRIORITY 1 [ TICKS 7 ALLOT 2 TIME 137 (of 500) ]
[ time 483 ] Run JOB 0 at PRIORITY 1 [ TICKS 6 ALLOT 2 TIME 136 (of 500) ]
[ time 484 ] Run JOB 0 at PRIORITY 1 [ TICKS 5 ALLOT 2 TIME 135 (of 500) ]
[ time 485 ] Run JOB 0 at PRIORITY 1 [ TICKS 4 ALLOT 2 TIME 134 (of 500) ]
[ time 486 ] Run JOB 0 at PRIORITY 1 [ TICKS 3 ALLOT 2 TIME 133 (of 500) ]
[ time 487 ] Run JOB 0 at PRIORITY 1 [ TICKS 2 ALLOT 2 TIME 132 (of 500) ]
[ time 488 ] Run JOB 0 at PRIORITY 1 [ TICKS 1 ALLOT 2 TIME 131 (of 500) ]
[ time 489 ] Run JOB 0 at PRIORITY 1 [ TICKS 0 ALLOT 2 TIME 130 (of 500) ]
[ time 490 ] Run JOB 0 at PRIORITY 1 [ TICKS 9 ALLOT 1 TIME 129 (of 500) ]
[ time 491 ] Run JOB 0 at PRIORITY 1 [ TICKS 8 ALLOT 1 TIME 128 (of 500) ]
[ time 492 ] Run JOB 0 at PRIORITY 1 [ TICKS 7 ALLOT 1 TIME 127 (of 500) ]
[ time 493 ] Run JOB 0 at PRIORITY 1 [ TICKS 6 ALLOT 1 TIME 126 (of 500) ]
[ time 494 ] Run JOB 0 at PRIORITY 1 [ TICKS 5 ALLOT 1 TIME 125 (of 500) ]
[ time 495 ] Run JOB 0 at PRIORITY 1 [ TICKS 4 ALLOT 1 TIME 124 (of 500) ]
[ time 496 ] Run JOB 0 at PRIORITY 1 [ TICKS 3 ALLOT 1 TIME 123 (of 500) ]
[ time 497 ] Run JOB 0 at PRIORITY 1 [ TICKS 2 ALLOT 1 TIME 122 (of 500) ]
[ time 498 ] Run JOB 0 at PRIORITY 1 [ TICKS 1 ALLOT 1 TIME 121 (of 500) ]
[ time 499 ] Run JOB 0 at PRIORITY 1 [ TICKS 0 ALLOT 1 TIME 120 (of 500) ]
[ time 500 ] BOOST ( every 20 )
[ time 500 ] Run JOB 0 at PRIORITY 1 [ TICKS 9 ALLOT 2 TIME 119 (of 500) ]
[ time 501 ] Run JOB 0 at PRIORITY 1 [ TICKS 8 ALLOT 2 TIME 118 (of 500) ]
[ time 502 ] Run JOB 0 at PRIORITY 1 [ TICKS 7 ALLOT 2 TIME 117 (of 500) ]
[ time 503 ] Run JOB 0 at PRIORITY 1 [ TICKS 6 ALLOT 2 TIME 116 (of 500) ]
[ time 504 ] Run JOB 0 at PRIORITY 1 [ TICKS 5 ALLOT 2 TIME 115 (of 500) ]
[ time 505 ] Run JOB 0 at PRIORITY 1 [ TICKS 4 ALLOT 2 TIME 114 (of 500) ]
[ time 506 ] Run JOB 0 at PRIORITY 1 [ TICKS 3 ALLOT 2 TIME 113 (of 500) ]
[ time 507 ] Run JOB 0 at PRIORITY 1 [ TICKS 2 ALLOT 2 TIME 112 (of 500) ]
[ time 508 ] Run JOB 0 at PRIORITY 1 [ TICKS 1 ALLOT 2 TIME 111 (of 500) ]
[ time 509 ] Run JOB 0 at PRIORITY 1 [ TICKS 0 ALLOT 2 TIME 110 (of 500) ]
[ time 510 ] Run JOB 0 at PRIORITY 1 [ TICKS 9 ALLOT 1 TIME 109 (of 500) ]
[ time 511 ] Run JOB 0 at PRIORITY 1 [ TICKS 8 ALLOT 1 TIME 108 (of 500) ]
[ time 512 ] Run JOB 0 at PRIORITY 1 [ TICKS 7 ALLOT 1 TIME 107 (of 500) ]
[ time 513 ] Run JOB 0 at PRIORITY 1 [ TICKS 6 ALLOT 1 TIME 106 (of 500) ]
[ time 514 ] Run JOB 0 at PRIORITY 1 [ TICKS 5 ALLOT 1 TIME 105 (of 500) ]
[ time 515 ] Run JOB 0 at PRIORITY 1 [ TICKS 4 ALLOT 1 TIME 104 (of 500) ]
[ time 516 ] Run JOB 0 at PRIORITY 1 [ TICKS 3 ALLOT 1 TIME 103 (of 500) ]
[ time 517 ] Run JOB 0 at PRIORITY 1 [ TICKS 2 ALLOT 1 TIME 102 (of 500) ]
[ time 518 ] Run JOB 0 at PRIORITY 1 [ TICKS 1 ALLOT 1 TIME 101 (of 500) ]
[ time 519 ] Run JOB 0 at PRIORITY 1 [ TICKS 0 ALLOT 1 TIME 100 (of 500) ]
[ time 520 ] BOOST ( every 20 )
[ time 520 ] Run JOB 0 at PRIORITY 1 [ TICKS 9 ALLOT 2 TIME 99 (of 500) ]
[ time 521 ] Run JOB 0 at PRIORITY 1 [ TICKS 8 ALLOT 2 TIME 98 (of 500) ]
[ time 522 ] Run JOB 0 at PRIORITY 1 [ TICKS 7 ALLOT 2 TIME 97 (of 500) ]
[ time 523 ] Run JOB 0 at PRIORITY 1 [ TICKS 6 ALLOT 2 TIME 96 (of 500) ]
[ time 524 ] Run JOB 0 at PRIORITY 1 [ TICKS 5 ALLOT 2 TIME 95 (of 500) ]
[ time 525 ] Run JOB 0 at PRIORITY 1 [ TICKS 4 ALLOT 2 TIME 94 (of 500) ]
[ time 526 ] Run JOB 0 at PRIORITY 1 [ TICKS 3 ALLOT 2 TIME 93 (of 500) ]
[ time 527 ] Run JOB 0 at PRIORITY 1 [ TICKS 2 ALLOT 2 TIME 92 (of 500) ]
[ time 528 ] Run JOB 0 at PRIORITY 1 [ TICKS 1 ALLOT 2 TIME 91 (of 500) ]
[ time 529 ] Run JOB 0 at PRIORITY 1 [ TICKS 0 ALLOT 2 TIME 90 (of 500) ]
[ time 530 ] Run JOB 0 at PRIORITY 1 [ TICKS 9 ALLOT 1 TIME 89 (of 500) ]
[ time 531 ] Run JOB 0 at PRIORITY 1 [ TICKS 8 ALLOT 1 TIME 88 (of 500) ]
[ time 532 ] Run JOB 0 at PRIORITY 1 [ TICKS 7 ALLOT 1 TIME 87 (of 500) ]
[ time 533 ] Run JOB 0 at PRIORITY 1 [ TICKS 6 ALLOT 1 TIME 86 (of 500) ]
[ time 534 ] Run JOB 0 at PRIORITY 1 [ TICKS 5 ALLOT 1 TIME 85 (of 500) ]
[ time 535 ] Run JOB 0 at PRIORITY 1 [ TICKS 4 ALLOT 1 TIME 84 (of 500) ]
[ time 536 ] Run JOB 0 at PRIORITY 1 [ TICKS 3 ALLOT 1 TIME 83 (of 500) ]
[ time 537 ] Run JOB 0 at PRIORITY 1 [ TICKS 2 ALLOT 1 TIME 82 (of 500) ]
[ time 538 ] Run JOB 0 at PRIORITY 1 [ TICKS 1 ALLOT 1 TIME 81 (of 500) ]
[ time 539 ] Run JOB 0 at PRIORITY 1 [ TICKS 0 ALLOT 1 TIME 80 (of 500) ]
[ time 540 ] BOOST ( every 20 )
[ time 540 ] Run JOB 0 at PRIORITY 1 [ TICKS 9 ALLOT 2 TIME 79 (of 500) ]
[ time 541 ] Run JOB 0 at PRIORITY 1 [ TICKS 8 ALLOT 2 TIME 78 (of 500) ]
[ time 542 ] Run JOB 0 at PRIORITY 1 [ TICKS 7 ALLOT 2 TIME 77 (of 500) ]
[ time 543 ] Run JOB 0 at PRIORITY 1 [ TICKS 6 ALLOT 2 TIME 76 (of 500) ]
[ time 544 ] Run JOB 0 at PRIORITY 1 [ TICKS 5 ALLOT 2 TIME 75 (of 500) ]
[ time 545 ] Run JOB 0 at PRIORITY 1 [ TICKS 4 ALLOT 2 TIME 74 (of 500) ]
[ time 546 ] Run JOB 0 at PRIORITY 1 [ TICKS 3 ALLOT 2 TIME 73 (of 500) ]
[ time 547 ] Run JOB 0 at PRIORITY 1 [ TICKS 2 ALLOT 2 TIME 72 (of 500) ]
[ time 548 ] Run JOB 0 at PRIORITY 1 [ TICKS 1 ALLOT 2 TIME 71 (of 500) ]
[ time 549 ] Run JOB 0 at PRIORITY 1 [ TICKS 0 ALLOT 2 TIME 70 (of 500) ]
[ time 550 ] Run JOB 0 at PRIORITY 1 [ TICKS 9 ALLOT 1 TIME 69 (of 500) ]
[ time 551 ] Run JOB 0 at PRIORITY 1 [ TICKS 8 ALLOT 1 TIME 68 (of 500) ]
[ time 552 ] Run JOB 0 at PRIORITY 1 [ TICKS 7 ALLOT 1 TIME 67 (of 500) ]
[ time 553 ] Run JOB 0 at PRIORITY 1 [ TICKS 6 ALLOT 1 TIME 66 (of 500) ]
[ time 554 ] Run JOB 0 at PRIORITY 1 [ TICKS 5 ALLOT 1 TIME 65 (of 500) ]
[ time 555 ] Run JOB 0 at PRIORITY 1 [ TICKS 4 ALLOT 1 TIME 64 (of 500) ]
[ time 556 ] Run JOB 0 at PRIORITY 1 [ TICKS 3 ALLOT 1 TIME 63 (of 500) ]
[ time 557 ] Run JOB 0 at PRIORITY 1 [ TICKS 2 ALLOT 1 TIME 62 (of 500) ]
[ time 558 ] Run JOB 0 at PRIORITY 1 [ TICKS 1 ALLOT 1 TIME 61 (of 500) ]
[ time 559 ] Run JOB 0 at PRIORITY 1 [ TICKS 0 ALLOT 1 TIME 60 (of 500) ]
[ time 560 ] BOOST ( every 20 )
[ time 560 ] Run JOB 0 at PRIORITY 1 [ TICKS 9 ALLOT 2 TIME 59 (of 500) ]
[ time 561 ] Run JOB 0 at PRIORITY 1 [ TICKS 8 ALLOT 2 TIME 58 (of 500) ]
[ time 562 ] Run JOB 0 at PRIORITY 1 [ TICKS 7 ALLOT 2 TIME 57 (of 500) ]
[ time 563 ] Run JOB 0 at PRIORITY 1 [ TICKS 6 ALLOT 2 TIME 56 (of 500) ]
[ time 564 ] Run JOB 0 at PRIORITY 1 [ TICKS 5 ALLOT 2 TIME 55 (of 500) ]
[ time 565 ] Run JOB 0 at PRIORITY 1 [ TICKS 4 ALLOT 2 TIME 54 (of 500) ]
[ time 566 ] Run JOB 0 at PRIORITY 1 [ TICKS 3 ALLOT 2 TIME 53 (of 500) ]
[ time 567 ] Run JOB 0 at PRIORITY 1 [ TICKS 2 ALLOT 2 TIME 52 (of 500) ]
[ time 568 ] Run JOB 0 at PRIORITY 1 [ TICKS 1 ALLOT 2 TIME 51 (of 500) ]
[ time 569 ] Run JOB 0 at PRIORITY 1 [ TICKS 0 ALLOT 2 TIME 50 (of 500) ]
[ time 570 ] Run JOB 0 at PRIORITY 1 [ TICKS 9 ALLOT 1 TIME 49 (of 500) ]
[ time 571 ] Run JOB 0 at PRIORITY 1 [ TICKS 8 ALLOT 1 TIME 48 (of 500) ]
[ time 572 ] Run JOB 0 at PRIORITY 1 [ TICKS 7 ALLOT 1 TIME 47 (of 500) ]
[ time 573 ] Run JOB 0 at PRIORITY 1 [ TICKS 6 ALLOT 1 TIME 46 (of 500) ]
[ time 574 ] Run JOB 0 at PRIORITY 1 [ TICKS 5 ALLOT 1 TIME 45 (of 500) ]
[ time 575 ] Run JOB 0 at PRIORITY 1 [ TICKS 4 ALLOT 1 TIME 44 (of 500) ]
[ time 576 ] Run JOB 0 at PRIORITY 1 [ TICKS 3 ALLOT 1 TIME 43 (of 500) ]
[ time 577 ] Run JOB 0 at PRIORITY 1 [ TICKS 2 ALLOT 1 TIME 42 (of 500) ]
[ time 578 ] Run JOB 0 at PRIORITY 1 [ TICKS 1 ALLOT 1 TIME 41 (of 500) ]
[ time 579 ] Run JOB 0 at PRIORITY 1 [ TICKS 0 ALLOT 1 TIME 40 (of 500) ]
[ time 580 ] BOOST ( every 20 )
[ time 580 ] Run JOB 0 at PRIORITY 1 [ TICKS 9 ALLOT 2 TIME 39 (of 500) ]
[ time 581 ] Run JOB 0 at PRIORITY 1 [ TICKS 8 ALLOT 2 TIME 38 (of 500) ]
[ time 582 ] Run JOB 0 at PRIORITY 1 [ TICKS 7 ALLOT 2 TIME 37 (of 500) ]
[ time 583 ] Run JOB 0 at PRIORITY 1 [ TICKS 6 ALLOT 2 TIME 36 (of 500) ]
[ time 584 ] Run JOB 0 at PRIORITY 1 [ TICKS 5 ALLOT 2 TIME 35 (of 500) ]
[ time 585 ] Run JOB 0 at PRIORITY 1 [ TICKS 4 ALLOT 2 TIME 34 (of 500) ]
[ time 586 ] Run JOB 0 at PRIORITY 1 [ TICKS 3 ALLOT 2 TIME 33 (of 500) ]
[ time 587 ] Run JOB 0 at PRIORITY 1 [ TICKS 2 ALLOT 2 TIME 32 (of 500) ]
[ time 588 ] Run JOB 0 at PRIORITY 1 [ TICKS 1 ALLOT 2 TIME 31 (of 500) ]
[ time 589 ] Run JOB 0 at PRIORITY 1 [ TICKS 0 ALLOT 2 TIME 30 (of 500) ]
[ time 590 ] Run JOB 0 at PRIORITY 1 [ TICKS 9 ALLOT 1 TIME 29 (of 500) ]
[ time 591 ] Run JOB 0 at PRIORITY 1 [ TICKS 8 ALLOT 1 TIME 28 (of 500) ]
[ time 592 ] Run JOB 0 at PRIORITY 1 [ TICKS 7 ALLOT 1 TIME 27 (of 500) ]
[ time 593 ] Run JOB 0 at PRIORITY 1 [ TICKS 6 ALLOT 1 TIME 26 (of 500) ]
[ time 594 ] Run JOB 0 at PRIORITY 1 [ TICKS 5 ALLOT 1 TIME 25 (of 500) ]
[ time 595 ] Run JOB 0 at PRIORITY 1 [ TICKS 4 ALLOT 1 TIME 24 (of 500) ]
[ time 596 ] Run JOB 0 at PRIORITY 1 [ TICKS 3 ALLOT 1 TIME 23 (of 500) ]
[ time 597 ] Run JOB 0 at PRIORITY 1 [ TICKS 2 ALLOT 1 TIME 22 (of 500) ]
[ time 598 ] Run JOB 0 at PRIORITY 1 [ TICKS 1 ALLOT 1 TIME 21 (of 500) ]
[ time 599 ] Run JOB 0 at PRIORITY 1 [ TICKS 0 ALLOT 1 TIME 20 (of 500) ]
[ time 600 ] BOOST ( every 20 )
[ time 600 ] Run JOB 0 at PRIORITY 1 [ TICKS 9 ALLOT 2 TIME 19 (of 500) ]
[ time 601 ] Run JOB 0 at PRIORITY 1 [ TICKS 8 ALLOT 2 TIME 18 (of 500) ]
[ time 602 ] Run JOB 0 at PRIORITY 1 [ TICKS 7 ALLOT 2 TIME 17 (of 500) ]
[ time 603 ] Run JOB 0 at PRIORITY 1 [ TICKS 6 ALLOT 2 TIME 16 (of 500) ]
[ time 604 ] Run JOB 0 at PRIORITY 1 [ TICKS 5 ALLOT 2 TIME 15 (of 500) ]
[ time 605 ] Run JOB 0 at PRIORITY 1 [ TICKS 4 ALLOT 2 TIME 14 (of 500) ]
[ time 606 ] Run JOB 0 at PRIORITY 1 [ TICKS 3 ALLOT 2 TIME 13 (of 500) ]
[ time 607 ] Run JOB 0 at PRIORITY 1 [ TICKS 2 ALLOT 2 TIME 12 (of 500) ]
[ time 608 ] Run JOB 0 at PRIORITY 1 [ TICKS 1 ALLOT 2 TIME 11 (of 500) ]
[ time 609 ] Run JOB 0 at PRIORITY 1 [ TICKS 0 ALLOT 2 TIME 10 (of 500) ]
[ time 610 ] Run JOB 0 at PRIORITY 1 [ TICKS 9 ALLOT 1 TIME 9 (of 500) ]
[ time 611 ] Run JOB 0 at PRIORITY 1 [ TICKS 8 ALLOT 1 TIME 8 (of 500) ]
[ time 612 ] Run JOB 0 at PRIORITY 1 [ TICKS 7 ALLOT 1 TIME 7 (of 500) ]
[ time 613 ] Run JOB 0 at PRIORITY 1 [ TICKS 6 ALLOT 1 TIME 6 (of 500) ]
[ time 614 ] Run JOB 0 at PRIORITY 1 [ TICKS 5 ALLOT 1 TIME 5 (of 500) ]
[ time 615 ] Run JOB 0 at PRIORITY 1 [ TICKS 4 ALLOT 1 TIME 4 (of 500) ]
[ time 616 ] Run JOB 0 at PRIORITY 1 [ TICKS 3 ALLOT 1 TIME 3 (of 500) ]
[ time 617 ] Run JOB 0 at PRIORITY 1 [ TICKS 2 ALLOT 1 TIME 2 (of 500) ]
[ time 618 ] Run JOB 0 at PRIORITY 1 [ TICKS 1 ALLOT 1 TIME 1 (of 500) ]
[ time 619 ] Run JOB 0 at PRIORITY 1 [ TICKS 0 ALLOT 1 TIME 0 (of 500) ]
[ time 620 ] FINISHED JOB 0

Final statistics:
  Job  0: startTime   0 - response   0 - turnaround 620
  Job  1: startTime   0 - response  10 - turnaround  40
  Job  2: startTime  20 - response  20 - turnaround 210

  Avg  2: startTime n/a - response 10.00 - turnaround 290.00


